{"kind": "depth", "E": 1787088859697, "U": 11315947377549, "u": 11315947384786, "recv_ms": 1787088859646, "bids": [[14080.5, 1.232], [14180.5, 2.968], [51664.4, 0.0], [58122.4, 0.055], [61997.2, 0.0], [62643.2, 2.312], [63580.5, 0.0], [63644.4, 0.004], [63934.7, 6.581], [64063.9, 9.039], [64257.6, 6.664], [64385.7, 7.89], [64424.5, 4.309], [64441.4, 2.873], [64559.7, 0.008], [64560.3, 0.563], [64561.3, 0.004], [64563.4, 0.052], [64563.8, 0.693], [64564.0, 0.004], [64564.5, 0.939], [64565.4, 2.325], [64570.8, 1.243], [64572.3, 0.087], [64575.4, 0.001]], "asks": [[64580.7, 2.225], [64596.4, 0.547], [64596.8, 0.001], [64596.9, 0.003], [64597.7, 0.001], [64597.8, 1.381], [64600.7, 0.014], [64601.4, 0.58], [64602.0, 0.141], [64602.7, 0.118], [64621.4, 0.01], [64651.3, 44.426], [64653.5, 0.0], [64662.3, 0.0], [64720.3, 5.408], [64737.2, 10.676], [64776.0, 15.595], [64903.5, 4.616], [65166.4, 0.0], [65226.4, 3.214], [65324.0, 11.979], [65580.6, 0.0], [65788.3, 2.093]]}
{"kind": "depth", "E": 1787088859799, "U": 11315947384858, "u": 11315947392360, "recv_ms": 1787088859746, "bids": [[1000.0, 35.76], [14080.5, 1.582], [14180.5, 2.618], [51664.0, 0.0], [58122.4, 0.055], [61351.4, 0.0], [61997.2, 0.003], [62643.0, 2.312], [63631.2, 1.803], [63812.1, 7.473], [63934.7, 6.581], [64257.5, 0.002], [64574.5, 0.009], [64575.6, 0.061], [64576.7, 0.0], [64576.8, 0.074]], "asks": [[64580.6, 60.598], [64621.0, 0.013], [64621.4, 0.164], [64651.3, 0.004], [64662.3, 44.422], [64696.7, 0.2], [64903.6, 0.462], [65226.4, 3.214], [65324.0, 11.062]]}
{"kind": "depth", "E": 1787088859901, "U": 11315947392559, "u": 11315947398489, "recv_ms": 1787088859849, "bids": [[1000.0, 35.76], [14080.5, 1.946], [14180.5, 2.254], [58122.4, 0.055], [61351.5, 0.008], [61997.2, 0.0], [63288.9, 4.438], [63580.5, 0.02], [63721.8, 3.603], [63812.0, 5.523], [63934.7, 6.581], [64122.6, 0.001], [64441.4, 2.899], [64488.7, 29.106], [64493.1, 0.0], [64575.8, 0.09]], "asks": [[64580.6, 60.598], [64653.5, 44.396], [64662.3, 0.0], [64720.3, 5.408], [65161.8, 0.498], [65226.4, 3.214], [65323.9, 3.8], [65401.3, 2.268], [65505.4, 6.048], [65580.6, 0.02], [65614.0, 8.339]]}
{"kind": "depth", "E": 1787088860003, "U": 11315947398594, "u": 11315947404434, "recv_ms": 1787088859950, "bids": [[14080.5, 2.296], [14180.5, 1.904], [58122.4, 0.055], [61351.4, 0.0], [63838.2, 0.808], [63934.7, 6.583], [64257.6, 6.654], [64441.4, 2.464], [64488.7, 0.0], [64493.1, 29.106], [64522.3, 0.055], [64535.2, 0.105], [64546.9, 0.016], [64548.3, 0.0], [64554.1, 0.077], [64575.8, 0.006], [64580.5, 1.687]], "asks": [[64600.1, 0.788], [64638.8, 1.352], [64658.1, 0.32], [64720.3, 5.408], [65226.4, 3.214], [65298.1, 10.328]]}
{"kind": "depth", "E": 1787088860105, "U": 11315947404596, "u": 11315947410910, "recv_ms": 1787088860054, "bids": [[1000.0, 35.76], [14080.5, 2.646], [14180.5, 1.554], [51664.0, 0.0], [58122.4, 0.055], [61351.4, 0.0], [61997.2, 0.003], [63580.5, 0.0], [63708.7, 3.057], [63934.7, 6.581], [64488.1, 0.002], [64488.7, 0.0], [64488.8, 7.649], [64490.9, 29.53], [64493.1, 0.0], [64568.9, 0.0], [64575.5, 0.099], [64575.8, 0.004], [64576.5, 0.004], [64577.1, 0.115]], "asks": [[64580.6, 60.598], [64584.1, 0.318], [64597.0, 0.927], [64597.8, 0.454], [64608.4, 1.42], [64652.9, 7.091], [64720.2, 1.708], [64774.6, 7.056], [65226.4, 3.214], [65387.9, 5.006], [65465.9, 3.202], [65580.6, 0.0]]}
{"kind": "depth", "E": 1787088860207, "U": 11315947411072, "u": 11315947417786, "recv_ms": 1787088860153, "bids": [[1000.0, 35.76], [14080.5, 3.01], [14180.5, 1.19], [51664.0, 0.0], [58122.4, 0.055], [61997.2, 0.0], [63663.5, 2.137], [63824.9, 1.673], [63934.7, 6.581], [64122.4, 0.311], [64488.8, 0.003], [64490.9, 0.424], [64493.1, 29.106], [64502.0, 0.007], [64529.0, 0.001], [64532.0, 0.052], [64537.2, 0.003], [64550.1, 1.525], [64557.5, 0.093]], "asks": [[64580.6, 60.603], [64584.4, 0.006], [64621.4, 0.01], [65226.4, 3.214], [65284.5, 3.516], [65613.9, 2.131]]}
{"kind": "depth", "E": 1787088860309, "U": 11315947418022, "u": 11315947424771, "recv_ms": 1787088860262, "bids": [[14080.5, 3.36], [14180.5, 0.84], [51664.0, 0.0], [58122.4, 0.055], [61351.4, 0.001], [61997.2, 0.003], [63288.9, 4.441], [63580.5, 0.02], [63934.7, 6.581], [64257.5, 0.001], [64257.6, 6.654], [64385.7, 3.602], [64424.5, 2.349], [64441.4, 1.578], [64516.7, 0.014], [64563.7, 0.004], [64575.9, 0.795], [64580.5, 1.692]], "asks": [[64581.9, 2.617], [64584.4, 0.005], [64596.1, 0.003], [64608.2, 3.985], [64621.3, 0.0], [64643.4, 0.094], [65226.4, 3.214], [65324.0, 10.146], [65580.6, 0.02]]}
{"kind": "depth", "E": 1787088860411, "U": 11315947425021, "u": 11315947431850, "recv_ms": 1787088860359, "bids": [[1000.0, 35.76], [14080.5, 3.696], [14180.5, 0.49], [14480.5, 0.014], [58122.4, 0.055], [61351.4, 0.0], [61997.2, 0.0], [63812.1, 6.534], [63934.7, 6.581], [64385.7, 7.949], [64385.9, 1.255], [64424.5, 4.327], [64441.4, 2.629], [64467.7, 0.0], [64469.6, 0.0], [64470.4, 1.227], [64571.9, 0.275], [64573.2, 0.108], [64575.5, 0.015]], "asks": [[64691.7, 0.41], [64691.8, 0.0], [65226.4, 3.214], [65387.9, 5.234], [65517.1, 34.447], [65581.7, 22.532]]}
{"kind": "depth", "E": 1787088860513, "U": 11315947431888, "u": 11315947438031, "recv_ms": 1787088860462, "bids": [[14080.5, 3.724], [14180.5, 0.294], [14480.5, 0.182], [58122.4, 0.055], [61351.4, 0.0], [63580.5, 0.0], [63934.7, 6.583], [64431.9, 0.005], [64432.0, 1.503], [64536.5, 2.337], [64575.5, 0.015], [64580.5, 1.694]], "asks": [[64580.6, 60.603], [64581.9, 2.616], [64645.7, 0.031], [64646.0, 0.003], [64726.8, 0.226], [64729.4, 0.0], [64903.6, 0.463], [65226.4, 3.214], [65324.0, 9.229], [65478.8, 0.637], [65517.1, 33.38], [65580.6, 0.0], [65646.3, 4.727]]}
{"kind": "depth", "E": 1787088860717, "U": 11315947442969, "u": 11315947449531, "recv_ms": 1787088860665, "bids": [[1000.0, 35.76], [14080.5, 3.5], [14180.5, 0.056], [14480.5, 0.644], [51664.4, 0.0], [58122.4, 0.055], [61351.4, 0.0], [61997.2, 0.0], [63580.5, 0.02], [63637.7, 0.904], [63682.5, 2.353], [63934.7, 6.581], [64441.4, 2.455], [64553.0, 0.621], [64560.4, 0.003], [64572.1, 0.042], [64575.8, 0.007]], "asks": [[64580.6, 60.606], [64604.9, 0.168], [64612.3, 0.619], [64621.3, 0.0], [64621.7, 1.039], [64720.2, 6.441], [64720.3, 0.0], [65226.4, 3.216], [65580.6, 0.02]]}
{"kind": "depth", "E": 1787088860819, "U": 11315947449638, "u": 11315947455216, "recv_ms": 1787088860765, "bids": [[14080.5, 3.248], [14180.5, 0.0], [14480.5, 0.952], [58122.4, 0.055], [61997.2, 0.003], [63495.7, 1.571], [63695.8, 6.261], [63747.1, 6.264], [63934.7, 6.581], [64257.5, 0.0], [64553.0, 0.002], [64575.5, 0.099]], "asks": [[64581.9, 2.617], [64612.3, 0.0], [64903.6, 0.464], [65226.4, 3.214], [65323.9, 5.633], [65324.0, 8.312], [65355.6, 20.576], [65355.7, 50.99], [65465.4, 1.827], [65484.7, 14.587], [65517.0, 12.753], [65646.2, 2.13]]}
{"kind": "depth", "E": 1787088860921, "U": 11315947455387, "u": 11315947460113, "recv_ms": 1787088860877, "bids": [[14080.5, 2.898], [14480.5, 1.302], [58122.4, 0.055], [61351.4, 0.0], [63288.9, 4.438], [63580.5, 0.0], [63876.3, 3.91], [63934.7, 6.581], [64257.6, 6.664], [64385.7, 7.949], [64424.5, 4.328], [64441.4, 2.629], [64483.7, 1.089], [64515.5, 0.621], [64515.6, 3.577], [64536.5, 2.333], [64545.0, 0.291], [64575.4, 0.085], [64575.5, 0.015]], "asks": [[64580.6, 60.478], [64643.5, 2.566], [64720.2, 1.033], [64720.3, 4.749], [64737.2, 7.555], [64776.0, 13.473], [65226.4, 3.214], [65355.6, 21.034], [65401.3, 2.153], [65498.3, 35.828], [65580.6, 0.0]]}
{"kind": "depth", "E": 1787088861023, "U": 11315947460355, "u": 11315947465232, "recv_ms": 1787088860969, "bids": [[1000.0, 35.76], [14080.5, 2.534], [14480.5, 1.666], [58122.4, 0.055], [61351.4, 0.0], [61351.5, 0.008], [61997.2, 0.0], [63482.6, 12.105], [63637.6, 1.832], [63695.7, 1.879], [63934.7, 6.581], [64063.9, 9.35], [64064.0, 2.347], [64557.0, 0.021], [64558.2, 0.125], [64561.0, 0.02], [64563.4, 0.052], [64564.1, 0.0], [64576.7, 0.008], [64576.8, 0.066]], "asks": [[64580.6, 60.479], [64581.9, 2.558], [64582.1, 0.061], [64589.9, 0.033], [64591.3, 0.001], [64595.9, 0.003], [64597.2, 0.464], [64737.2, 10.676], [65226.4, 3.214], [65387.9, 5.349], [65388.0, 28.702], [65484.7, 16.873], [65614.0, 7.274], [65750.1, 1.522]]}
{"kind": "depth", "E": 1787088861125, "U": 11315947465368, "u": 11315947471769, "recv_ms": 1787088861075, "bids": [[14080.5, 2.184], [14480.5, 2.016], [51664.0, 0.0], [58122.4, 0.055], [61351.4, 0.0], [61997.2, 0.003], [63288.9, 4.441], [63580.5, 0.02], [63934.7, 6.581], [64488.7, 29.106], [64493.1, 0.0], [64495.4, 1.631], [64532.0, 0.05], [64534.3, 1.853], [64537.2, 0.001], [64548.2, 3.161], [64561.0, 0.012], [64561.4, 0.039], [64563.4, 0.06], [64568.9, 0.0], [64575.8, 0.091]], "asks": [[64580.6, 60.478], [64581.9, 2.617], [64582.1, 0.002], [64584.2, 0.001], [64589.9, 0.025], [64590.5, 0.122], [64595.9, 0.001], [64596.3, 0.941], [64596.4, 0.549], [64600.0, 1.263], [64619.4, 0.003], [64720.2, 1.61], [64765.5, 2.605], [65226.4, 3.214], [65323.9, 6.55], [65440.8, 1.528], [65497.6, 1.826], [65497.7, 2.28], [65580.6, 0.02]]}
{"kind": "depth", "E": 1787088861227, "U": 11315947471804, "u": 11315947477491, "recv_ms": 1787088861175, "bids": [[14080.5, 1.82], [14480.5, 2.38], [58122.4, 0.055], [61351.4, 0.0], [61351.5, 0.006], [61351.6, 2.449], [61997.2, 0.0], [63934.7, 6.581], [64257.6, 6.654], [64441.4, 2.196], [64488.7, 0.0], [64490.9, 29.324], [64502.0, 0.006], [64516.0, 1.561], [64529.0, 0.0], [64531.9, 0.002], [64535.2, 0.108], [64537.1, 0.003], [64545.0, 0.287]], "asks": [[64580.6, 60.479], [64638.8, 1.355], [64652.9, 0.618], [64653.5, 0.0], [64655.7, 46.797], [64659.8, 7.218], [64662.3, 0.0], [64720.2, 6.441], [64720.3, 0.0], [65226.4, 3.214], [65613.9, 3.196], [65743.1, 1.96]]}
{"kind": "depth", "E": 1787088861329, "U": 11315947477659, "u": 11315947483006, "recv_ms": 1787088861276, "bids": [[1000.0, 35.76], [14080.5, 1.47], [14480.5, 2.73], [58122.4, 0.055], [61997.2, 0.003], [63288.9, 4.438], [63418.1, 10.195], [63547.3, 2.64], [63580.5, 0.0], [63644.2, 32.252], [63663.5, 2.371], [63773.2, 6.824], [63934.7, 6.581], [64535.2, 0.105], [64536.5, 2.337], [64546.7, 0.283], [64547.1, 0.154], [64563.7, 0.004]], "asks": [[64596.1, 0.003], [64621.2, 0.208], [64621.7, 0.885], [64638.8, 1.352], [64659.8, 0.91], [64748.9, 16.184], [64749.2, 0.039], [65226.4, 3.214], [65517.1, 31.246], [65580.6, 0.0], [65614.0, 5.142], [65872.2, 0.003]]}
{"kind": "depth", "E": 1787088861431, "U": 11315947483020, "u": 11315947488119, "recv_ms": 1787088861380, "bids": [[14080.5, 1.106], [14480.5, 3.094], [58122.4, 0.055], [61351.4, 0.0], [63934.7, 6.581], [64424.5, 3.5], [64441.4, 2.196], [64557.0, 0.019], [64558.1, 0.495], [64575.8, 0.007], [64580.5, 1.699]], "asks": [[64580.6, 60.486], [64584.2, 0.0], [64590.5, 0.114], [64591.1, 0.008], [64596.4, 0.547], [64596.9, 0.005], [64621.2, 0.208], [64720.2, 6.441], [64737.2, 10.676], [64903.6, 0.463], [65226.4, 3.214], [65484.8, 48.681], [65517.0, 13.82], [65613.9, 4.262]]}
{"kind": "depth", "E": 1787088861533, "U": 11315947488300, "u": 11315947493442, "recv_ms": 1787088861482, "bids": [[14080.5, 0.742], [14480.5, 3.458], [58122.4, 0.055], [61351.4, 0.0], [61997.2, 0.0], [63418.1, 10.824], [63580.5, 0.02], [63934.7, 6.581], [64257.5, 0.001], [64257.6, 6.664], [64385.7, 3.581], [64424.5, 2.178], [64441.4, 1.322], [64490.9, 0.424], [64493.1, 28.9], [64515.6, 1.0], [64580.5, 1.698]], "asks": [[64580.6, 60.492], [64584.7, 0.029], [64586.1, 0.001], [64621.1, 0.155], [64621.2, 0.054], [64643.5, 0.0], [64653.5, 44.475], [64655.7, 2.322], [65226.4, 3.214], [65580.6, 0.02]]}
{"kind": "depth", "E": 1787088861635, "U": 11315947493474, "u": 11315947498785, "recv_ms": 1787088861584, "bids": [[1000.0, 35.76], [14080.5, 0.434], [14380.5, 0.042], [14480.5, 3.724], [51664.0, 0.0], [58122.4, 0.055], [61997.2, 0.003], [63580.5, 0.0], [63934.7, 6.581], [64385.7, 7.835], [64424.5, 4.293], [64441.4, 2.612], [64462.4, 0.002], [64462.8, 3.871], [64467.1, 0.0], [64467.2, 8.768], [64488.7, 28.9], [64493.1, 0.0], [64506.6, 3.878], [64507.0, 0.141], [64515.6, 3.588], [64572.0, 0.388], [64574.5, 0.017], [64575.0, 0.008], [64575.4, 0.001], [64576.7, 0.0], [64580.5, 1.699]], "asks": [[64580.6, 60.574], [64581.9, 2.558], [64591.0, 0.595], [64591.7, 1.105], [64621.1, 0.001], [64621.2, 0.208], [64643.5, 2.11], [64648.8, 0.022], [64649.1, 0.046], [64691.9, 2.319], [64692.0, 9.739], [64714.9, 0.023], [64715.2, 6.19], [65226.4, 3.214], [65580.6, 0.0]]}
{"kind": "depth", "E": 1787088861737, "U": 11315947498857, "u": 11315947504399, "recv_ms": 1787088861687, "bids": [[14080.5, 0.266], [14380.5, 0.224], [14480.5, 3.71], [51664.4, 0.0], [58122.4, 0.055], [61351.4, 0.0], [61351.5, 0.008], [61997.2, 0.0], [63547.2, 11.163], [63644.1, 14.868], [63934.7, 6.581], [64488.7, 28.9], [64490.9, 0.424], [64493.1, 0.0], [64547.1, 0.154], [64574.5, 0.009], [64575.6, 0.145], [64576.7, 0.008]], "asks": [[64582.3, 0.059], [64653.5, 0.0], [64655.7, 46.797], [64662.3, 0.0], [65226.4, 3.214], [65388.0, 28.474], [65491.7, 0.763], [65517.0, 14.887], [65613.9, 5.328]]}
{"kind": "depth", "E": 1787088861839, "U": 11315947504566, "u": 11315947510711, "recv_ms": 1787088861787, "bids": [[1000.0, 35.76], [14080.5, 0.154], [14380.5, 0.476], [14480.5, 3.57], [58122.4, 0.055], [61351.4, 0.001], [61997.2, 0.003], [63580.5, 0.02], [63934.7, 6.581], [64257.5, 0.002], [64257.6, 6.664], [64488.7, 0.0], [64490.9, 29.215], [64550.7, 0.635], [64558.1, 1.114], [64572.0, 0.304], [64576.0, 0.012], [64576.4, 0.119]], "asks": [[64580.6, 60.7], [64602.6, 0.0], [64610.0, 0.642], [64621.2, 0.054], [64653.5, 44.475], [64655.7, 2.322], [64903.6, 0.462], [65226.4, 3.214], [65452.4, 6.003], [65478.8, 0.028], [65491.9, 3.17], [65580.6, 0.02], [65872.2, 0.006], [71038.7, 0.002]]}
{"kind": "depth", "E": 1787088861941, "U": 11315947510769, "u": 11315947515861, "recv_ms": 1787088861892, "bids": [[1000.0, 35.76], [14080.5, 0.028], [14380.5, 0.7], [14480.5, 3.472], [58122.4, 0.055], [61351.4, 0.0], [64483.6, 2.345], [64490.9, 0.424], [64493.1, 28.791], [64522.5, 0.071], [64522.8, 0.2], [64523.1, 0.015], [64523.5, 0.314], [64523.8, 0.05], [64538.4, 3.363], [64538.7, 0.033], [64539.0, 0.033], [64539.3, 2.351], [64539.7, 0.019], [64540.0, 0.094], [64540.3, 0.0], [64540.6, 1.047], [64541.0, 0.696], [64554.6, 0.061], [64554.7, 1.639], [64554.8, 0.028], [64554.9, 1.484], [64555.0, 0.444], [64555.1, 1.085], [64555.2, 0.034], [64555.3, 0.002], [64555.4, 0.003], [64555.5, 1.31], [64556.0, 0.002], [64556.4, 0.001], [64570.9, 0.004], [64571.5, 0.141], [64571.8, 0.56], [64572.1, 0.142], [64572.7, 0.133], [64572.8, 0.914], [64572.9, 0.003], [64573.0, 0.033], [64573.1, 0.084], [64573.2, 0.006], [64573.3, 0.032], [64573.4, 0.23], [64573.5, 0.089], [64573.6, 0.039], [64574.0, 2.03], [64574.3, 0.001], [64574.4, 0.055], [64574.5, 0.009], [64574.6, 0.084], [64574.7, 0.543], [64574.8, 1.559], [64574.9, 0.027], [64575.3, 0.0], [64576.7, 0.008]], "asks": [[64586.6, 0.0], [64586.9, 0.054], [64587.2, 0.205], [64587.5, 1.21], [64587.9, 0.083], [64588.1, 0.01], [64588.3, 0.001], [64588.4, 0.263], [64588.5, 0.005], [64588.6, 0.001], [64588.7, 0.263], [64588.8, 0.009], [64588.9, 0.001], [64589.0, 1.518], [64589.1, 2.462], [64603.7, 0.001], [64604.0, 0.068], [64604.1, 0.05], [64604.4, 0.077], [64604.7, 0.067], [64605.0, 0.06], [64605.4, 0.0], [64605.8, 0.124], [64606.3, 0.646], [64606.5, 0.264], [64606.6, 0.375], [64606.7, 0.0], [64606.8, 0.117], [64606.9, 0.262], [64607.0, 2.351], [64607.1, 0.131], [64607.2, 0.259], [64607.3, 0.002], [64620.9, 0.042], [64621.0, 0.013], [64621.2, 0.054], [64621.4, 0.164], [64621.5, 0.074], [64621.8, 0.065], [64622.2, 0.058], [65226.4, 3.214], [65465.4, 2.436], [65581.7, 21.467]]}
{"kind": "depth", "E": 1787088862043, "U": 11315947515881, "u": 11315947521108, "recv_ms": 1787088861992, "bids": [[14080.5, 0.0], [14380.5, 1.036], [14480.5, 3.164], [58122.4, 0.055], [61351.4, 0.0], [61997.2, 0.0], [63934.7, 6.581], [64539.7, 0.051], [64547.1, 0.0], [64563.4, 0.052], [64563.5, 0.07], [64568.1, 0.103], [64568.2, 0.001], [64568.9, 0.005], [64570.9, 0.004], [64571.0, 0.001], [64571.6, 0.148], [64571.7, 0.004], [64572.3, 0.157], [64572.7, 0.133], [64572.8, 1.261], [64574.0, 2.062], [64574.1, 2.2], [64574.4, 0.048], [64574.5, 0.001], [64574.7, 0.001], [64574.8, 0.011], [64574.9, 0.027], [64575.0, 0.008], [64575.9, 0.773], [64576.7, 0.0]], "asks": [[64580.6, 60.7], [64585.4, 0.001], [64586.6, 0.054], [64588.1, 0.171], [64588.9, 0.155], [64603.7, 0.055], [64606.3, 0.807], [64607.1, 0.285], [64620.9, 0.096], [65226.4, 3.214], [65478.3, 4.0], [66525.8, 0.0]]}
{"kind": "depth", "E": 1787088862145, "U": 11315947521253, "u": 11315947550266, "recv_ms": 1787088862253, "bids": [[1000.0, 35.76], [14376.2, 0.126], [14377.6, 0.014], [14380.0, 0.042], [14380.5, 1.204], [14480.5, 2.814], [58118.5, 0.002], [58122.0, 0.0], [58122.4, 0.053], [59298.2, 0.0], [59460.6, 0.0], [59623.1, 0.0], [59785.6, 0.0], [59948.0, 0.001], [61351.4, 0.0], [61351.5, 0.006], [61351.6, 2.451], [61996.8, 0.006], [63286.1, 0.006], [63288.9, 4.432], [63482.7, 12.429], [63580.5, 0.0], [63930.4, 0.004], [63931.8, 0.105], [63933.5, 0.001], [63934.2, 0.0], [63934.3, 0.387], [63934.7, 6.581], [64063.5, 0.046], [64070.0, 1.123], [64081.1, 0.0], [64113.6, 0.001], [64127.9, 0.001], [64134.5, 0.016], [64146.1, 0.0], [64150.1, 1.447], [64178.6, 0.0], [64192.6, 0.029], [64199.2, 0.024], [64211.1, 0.02], [64243.6, 0.703], [64257.2, 0.001], [64257.6, 6.654], [64263.8, 0.0], [64321.8, 0.001], [64328.4, 0.0], [64376.5, 4.587], [64377.3, 0.966], [64378.6, 0.005], [64385.7, 0.0], [64385.9, 0.007], [64386.4, 0.005], [64388.2, 0.01], [64389.3, 0.003], [64391.1, 1.677], [64392.9, 0.0], [64395.4, 0.0], [64405.5, 0.014], [64410.0, 1.21], [64415.2, 4.833], [64416.0, 1.284], [64416.2, 3.266], [64424.5, 0.0], [64432.0, 2.804], [64432.2, 3.525], [64432.4, 0.002], [64438.1, 1.01], [64440.0, 0.683], [64441.4, 0.0], [64450.9, 0.001], [64453.0, 0.351], [64453.8, 0.04], [64455.2, 0.0], [64455.6, 0.0], [64455.7, 28.794], [64456.3, 1.036], [64456.4, 0.0], [64456.9, 0.003], [64457.5, 0.031], [64458.0, 1.676], [64460.1, 0.529], [64460.4, 0.274], [64461.3, 0.001], [64462.1, 26.081], [64467.4, 0.04], [64468.9, 0.022], [64469.1, 2.401], [64470.4, 2.214], [64471.4, 0.003], [64472.0, 1.243], [64474.3, 0.013], [64475.3, 0.006], [64478.1, 0.41], [64478.9, 0.003], [64479.0, 0.033], [64479.7, 0.017], [64479.8, 0.035], [64481.1, 0.014], [64484.8, 0.042], [64485.6, 1.031], [64485.7, 0.047], [64486.1, 0.003], [64486.2, 0.001], [64486.4, 0.005], [64487.2, 10.662], [64487.5, 0.003], [64489.3, 0.009], [64491.1, 0.0], [64493.1, 0.0], [64493.3, 0.121], [64493.6, 0.239], [64493.7, 5.569], [64493.9, 0.004], [64495.0, 0.382], [64495.4, 1.631], [64495.7, 0.001], [64496.3, 2.506], [64497.4, 0.028], [64497.6, 0.0], [64498.1, 0.048], [64498.7, 0.031], [64500.5, 0.441], [64500.9, 0.144], [64501.9, 0.016], [64503.8, 0.001], [64504.0, 0.019], [64504.5, 0.001], [64505.5, 3.648], [64507.2, 0.005], [64507.7, 0.0], [64508.5, 0.007], [64508.6, 3.973], [64509.0, 1.361], [64510.5, 0.77], [64511.5, 0.329], [64511.6, 0.0], [64512.4, 6.018], [64512.6, 0.001], [64514.2, 0.13], [64514.6, 1.533], [64514.7, 0.065], [64515.5, 0.625], [64515.6, 3.59], [64515.7, 0.21], [64515.9, 0.269], [64516.9, 0.004], [64517.0, 0.159], [64517.4, 0.001], [64517.5, 0.048], [64517.9, 0.04], [64518.8, 0.035], [64519.2, 1.311], [64520.3, 0.08], [64520.7, 0.101], [64521.2, 0.024], [64521.8, 0.024], [64521.9, 0.031], [64522.1, 4.266], [64522.3, 0.051], [64522.7, 0.041], [64523.2, 0.002], [64523.4, 0.019], [64523.6, 0.017], [64523.8, 0.054], [64523.9, 0.025], [64524.0, 1.485], [64524.5, 2.367], [64525.3, 0.179], [64525.7, 0.012], [64526.9, 0.442], [64527.4, 0.002], [64527.5, 0.328], [64527.8, 0.003], [64528.2, 0.078], [64528.3, 1.474], [64528.4, 0.002], [64528.7, 2.322], [64528.9, 0.031], [64529.1, 0.0], [64529.4, 2.469], [64529.5, 0.093], [64529.7, 0.025], [64529.8, 0.004], [64529.9, 0.223], [64530.2, 1.442], [64531.1, 0.159], [64531.2, 0.013], [64531.3, 0.0], [64531.4, 6.121], [64531.9, 0.003], [64532.1, 0.006], [64532.2, 0.049], [64532.3, 0.0], [64532.5, 0.0], [64532.6, 0.021], [64532.7, 0.019], [64533.2, 0.0], [64533.3, 0.01], [64533.6, 0.009], [64533.7, 4.48], [64533.9, 0.449], [64534.0, 0.016], [64534.1, 0.059], [64534.2, 0.443], [64534.3, 1.84], [64534.6, 0.0], [64534.7, 0.019], [64534.9, 0.1], [64535.0, 3.988], [64535.4, 0.191], [64535.7, 0.001], [64536.5, 2.352], [64536.6, 0.094], [64536.7, 0.0], [64536.8, 0.02], [64537.1, 0.068], [64537.4, 0.004], [64537.5, 0.019], [64537.6, 1.35], [64537.8, 3.9], [64538.1, 0.0], [64538.8, 0.671], [64539.1, 0.003], [64539.2, 1.865], [64539.4, 0.073], [64539.7, 0.069], [64539.9, 0.001], [64540.0, 0.088], [64540.3, 0.0], [64541.1, 1.626], [64541.3, 2.162], [64541.4, 0.0], [64541.9, 2.393], [64542.0, 0.002], [64542.1, 0.655], [64542.2, 0.0], [64542.6, 1.061], [64542.7, 0.18], [64543.0, 0.069], [64543.3, 0.001], [64543.5, 0.31], [64543.6, 0.002], [64543.7, 0.091], [64544.0, 0.018], [64544.3, 0.467], [64544.4, 0.001], [64544.8, 0.08], [64545.1, 0.315], [64545.3, 0.155], [64545.4, 0.007], [64545.5, 0.418], [64545.8, 0.003], [64545.9, 0.045], [64546.1, 0.007], [64546.2, 0.002], [64546.5, 0.002], [64546.7, 0.061], [64546.8, 0.007], [64546.9, 0.017], [64547.0, 0.049], [64547.1, 0.0], [64547.2, 0.006], [64547.4, 0.279], [64547.5, 0.314], [64547.6, 0.007], [64547.7, 1.279], [64547.8, 0.447], [64547.9, 0.117], [64548.1, 0.654], [64548.2, 3.155], [64548.3, 2.378], [64548.4, 0.039], [64548.5, 0.407], [64548.6, 0.464], [64548.7, 0.005], [64548.9, 2.161], [64549.0, 1.706], [64549.2, 0.0], [64549.4, 0.0], [64549.7, 1.501], [64549.8, 0.0], [64549.9, 0.002], [64550.1, 0.015], [64550.2, 0.154], [64550.3, 0.2], [64550.4, 0.02], [64550.7, 0.016], [64550.8, 0.009], [64551.3, 0.001], [64551.4, 2.422], [64551.6, 0.004], [64551.7, 0.003], [64551.8, 0.015], [64551.9, 0.493], [64552.1, 0.0], [64552.2, 0.003], [64552.5, 0.001], [64552.6, 0.008], [64552.7, 0.351], [64552.9, 0.074], [64553.1, 0.003], [64553.2, 0.003], [64553.5, 0.035], [64553.6, 0.462], [64553.7, 0.01], [64554.0, 0.216], [64554.1, 0.002], [64554.4, 0.001], [64554.5, 0.092], [64554.6, 0.052], [64554.7, 0.85], [64554.8, 0.0], [64554.9, 1.042], [64555.1, 0.015], [64555.4, 0.068], [64555.5, 0.31], [64555.6, 0.002], [64555.7, 2.309], [64555.8, 1.217], [64555.9, 0.001], [64556.0, 0.002], [64556.3, 0.053], [64556.6, 0.116], [64556.7, 0.004], [64556.8, 0.136], [64556.9, 0.003], [64557.2, 0.465], [64557.3, 0.055], [64557.4, 0.01], [64557.5, 2.319], [64557.6, 0.0], [64557.7, 0.018], [64557.8, 0.033], [64557.9, 0.0], [64558.0, 0.037], [64558.1, 0.226], [64558.2, 0.002], [64558.3, 0.566], [64558.4, 0.005], [64558.7, 0.024], [64559.0, 1.183], [64559.1, 0.008], [64559.6, 0.001], [64559.7, 0.228], [64559.9, 0.012], [64560.0, 0.206], [64560.1, 0.514], [64560.2, 2.321], [64560.3, 0.098], [64560.4, 0.011], [64560.6, 0.004], [64560.7, 0.002], [64560.8, 0.004], [64560.9, 0.343], [64561.0, 0.013], [64561.1, 0.003], [64561.2, 0.165], [64561.3, 0.217], [64561.4, 0.004], [64561.5, 0.0], [64561.7, 0.02], [64561.8, 0.0], [64562.0, 0.001], [64562.2, 0.154], [64562.4, 0.467], [64562.5, 0.428], [64562.6, 0.001], [64562.7, 0.0], [64562.8, 0.0], [64562.9, 2.577], [64563.0, 2.321], [64563.1, 2.209], [64563.2, 2.113], [64563.3, 0.005], [64563.4, 0.678], [64563.5, 0.604], [64563.7, 0.002], [64563.8, 0.0], [64563.9, 0.347], [64564.0, 0.004], [64564.4, 0.016], [64564.5, 0.062], [64564.6, 0.464], [64564.7, 0.129], [64564.8, 0.002], [64564.9, 0.577], [64565.0, 0.002], [64565.1, 0.002], [64565.2, 0.05], [64565.3, 0.004], [64565.4, 0.16], [64565.5, 0.008], [64565.6, 0.005], [64565.7, 0.212], [64565.8, 0.007], [64565.9, 0.101], [64566.0, 0.004], [64566.1, 0.015], [64566.2, 0.311], [64566.3, 0.003], [64566.4, 1.073], [64566.5, 2.32], [64566.6, 0.151], [64566.8, 0.02], [64567.0, 0.466], [64567.1, 0.099], [64567.2, 0.108], [64567.3, 0.001], [64567.4, 0.075], [64567.5, 0.007], [64567.6, 0.212], [64567.7, 0.005], [64567.9, 0.002], [64568.0, 0.354], [64568.1, 0.092], [64568.2, 1.9], [64568.4, 0.283], [64568.5, 1.985], [64568.6, 0.005], [64568.7, 0.001], [64568.8, 0.0], [64568.9, 0.084], [64569.0, 0.001], [64569.2, 0.019], [64569.3, 1.772], [64569.4, 0.014], [64569.5, 0.001], [64569.6, 0.009], [64569.7, 1.775], [64569.8, 0.231], [64569.9, 0.065], [64570.1, 0.085], [64570.2, 0.004], [64570.3, 0.003], [64570.4, 0.0], [64570.5, 0.185], [64570.6, 0.0], [64570.7, 0.014], [64570.8, 0.006], [64570.9, 0.086], [64571.1, 0.0], [64571.2, 0.167], [64571.3, 0.0], [64571.4, 0.0], [64571.6, 0.147], [64571.7, 0.071], [64571.8, 0.169], [64571.9, 0.001], [64572.0, 0.304], [64572.1, 0.048], [64572.2, 0.006], [64572.3, 0.002], [64572.6, 0.101], [64572.7, 0.015], [64572.8, 0.512], [64572.9, 0.003], [64573.0, 0.002], [64573.1, 0.0], [64573.2, 0.002], [64573.3, 0.006], [64573.4, 0.0], [64573.5, 0.001], [64573.6, 0.002], [64573.8, 0.001], [64574.0, 0.008], [64574.1, 0.007], [64574.2, 0.048], [64574.4, 0.008], [64574.5, 0.001], [64574.6, 0.0], [64574.7, 0.232], [64574.8, 0.087], [64574.9, 0.026], [64575.0, 0.01], [64575.1, 0.043], [64575.2, 0.0], [64575.3, 0.0], [64575.5, 0.003], [64575.6, 0.0], [64575.8, 0.003], [64575.9, 0.002], [64576.0, 0.002], [64576.1, 0.157], [64576.2, 3.894], [64576.3, 0.0], [64576.4, 0.0], [64576.5, 0.0], [64576.6, 0.0], [64576.8, 0.0], [64576.9, 0.0], [64577.0, 0.0], [64577.1, 0.0], [64577.3, 0.0], [64577.5, 0.0], [64577.6, 0.0], [64577.7, 0.0], [64577.8, 0.0], [64578.0, 0.0], [64578.1, 0.0], [64578.2, 0.0], [64578.3, 0.0], [64578.4, 0.0], [64578.5, 0.0], [64578.7, 0.0], [64578.8, 0.0], [64578.9, 0.0], [64579.0, 0.0], [64579.1, 0.0], [64579.2, 0.0], [64579.3, 0.0], [64579.4, 0.0], [64579.6, 0.0], [64579.9, 0.0], [64580.0, 0.0], [64580.1, 0.0], [64580.2, 0.0], [64580.3, 0.0], [64580.4, 0.0], [64580.5, 0.0]], "asks": [[64576.3, 25.867], [64576.4, 0.739], [64576.5, 0.189], [64576.6, 0.003], [64576.7, 0.084], [64576.9, 0.0], [64577.0, 0.0], [64577.1, 0.0], [64577.2, 0.0], [64577.3, 0.002], [64577.4, 0.02], [64577.5, 2.319], [64577.6, 0.884], [64577.7, 0.238], [64577.8, 0.001], [64577.9, 0.0], [64578.0, 0.001], [64578.1, 0.0], [64578.2, 0.0], [64578.3, 0.002], [64578.4, 0.31], [64578.5, 0.001], [64578.6, 0.0], [64578.7, 0.001], [64578.8, 0.0], [64578.9, 0.0], [64579.0, 0.002], [64579.1, 0.781], [64579.2, 0.002], [64579.3, 0.002], [64579.4, 0.002], [64579.5, 0.001], [64579.7, 0.002], [64579.8, 0.0], [64579.9, 0.016], [64580.0, 8.033], [64580.1, 5.514], [64580.2, 6.321], [64580.3, 0.001], [64580.4, 0.001], [64580.5, 4.649], [64580.6, 46.411], [64580.7, 2.078], [64580.8, 0.005], [64580.9, 0.312], [64581.0, 0.0], [64581.1, 0.016], [64581.2, 0.019], [64581.3, 0.054], [64581.6, 0.015], [64581.7, 0.017], [64581.8, 0.0], [64581.9, 2.561], [64582.0, 0.114], [64582.2, 0.238], [64582.4, 0.022], [64582.5, 0.002], [64582.6, 0.78], [64582.7, 0.002], [64582.8, 0.115], [64582.9, 0.056], [64583.1, 0.084], [64583.2, 0.157], [64583.3, 0.001], [64583.4, 0.018], [64583.5, 0.001], [64583.6, 0.025], [64583.7, 0.003], [64583.9, 0.501], [64584.0, 0.123], [64584.1, 0.313], [64584.2, 0.116], [64584.3, 0.007], [64584.4, 0.001], [64584.5, 0.003], [64584.6, 1.223], [64584.9, 0.0], [64585.0, 0.062], [64585.1, 0.314], [64585.2, 0.184], [64585.3, 0.348], [64585.5, 0.237], [64585.6, 1.586], [64585.9, 0.004], [64586.0, 0.002], [64586.1, 0.151], [64586.2, 0.052], [64586.3, 0.635], [64586.4, 0.227], [64586.5, 2.341], [64586.8, 0.059], [64586.9, 0.054], [64587.1, 0.261], [64587.2, 0.193], [64587.3, 0.022], [64587.4, 0.254], [64587.5, 1.21], [64587.6, 1.352], [64587.7, 0.001], [64587.9, 0.077], [64588.0, 0.001], [64588.1, 0.162], [64588.2, 0.31], [64588.5, 0.363], [64588.6, 0.014], [64588.7, 0.396], [64588.8, 0.021], [64588.9, 0.154], [64589.0, 3.173], [64589.1, 2.578], [64589.2, 0.005], [64589.3, 0.014], [64589.4, 0.0], [64589.5, 0.371], [64589.7, 0.001], [64589.8, 0.004], [64589.9, 0.025], [64590.0, 3.049], [64590.1, 0.038], [64590.2, 0.2], [64590.4, 0.005], [64590.5, 0.114], [64590.6, 0.003], [64590.7, 0.766], [64590.9, 10.0], [64591.0, 0.007], [64591.1, 0.0], [64591.2, 0.0], [64591.3, 0.037], [64591.4, 0.0], [64591.6, 0.004], [64591.7, 0.486], [64591.8, 1.272], [64592.0, 0.26], [64592.2, 0.31], [64592.4, 0.001], [64592.6, 0.002], [64592.7, 0.0], [64592.9, 0.0], [64593.1, 0.042], [64593.2, 0.003], [64593.3, 0.016], [64593.4, 0.789], [64593.5, 0.071], [64593.6, 0.011], [64593.7, 0.03], [64593.8, 1.205], [64594.0, 0.028], [64594.2, 0.09], [64594.3, 0.507], [64594.4, 0.0], [64594.6, 0.001], [64594.7, 0.059], [64594.9, 0.0], [64595.0, 0.003], [64595.1, 0.002], [64595.4, 0.927], [64595.6, 0.214], [64595.7, 0.648], [64595.9, 0.33], [64596.2, 0.0], [64596.3, 0.941], [64596.4, 0.004], [64596.5, 1.313], [64596.6, 0.465], [64596.7, 0.035], [64596.8, 0.021], [64596.9, 0.003], [64597.0, 0.001], [64597.4, 0.0], [64597.5, 0.154], [64597.6, 0.001], [64597.7, 0.0], [64597.8, 0.454], [64598.2, 0.352], [64598.4, 0.568], [64598.8, 0.037], [64598.9, 0.34], [64599.0, 0.107], [64599.1, 1.393], [64599.2, 0.027], [64599.6, 0.063], [64599.7, 0.119], [64599.8, 1.375], [64599.9, 0.66], [64600.0, 1.386], [64600.2, 0.225], [64600.3, 0.007], [64600.5, 0.055], [64600.6, 5.002], [64600.7, 0.021], [64600.8, 0.312], [64600.9, 1.21], [64601.1, 0.326], [64601.3, 2.32], [64601.4, 0.0], [64601.5, 0.018], [64601.6, 0.007], [64601.9, 0.053], [64602.2, 0.001], [64602.4, 0.022], [64602.5, 0.053], [64602.6, 0.05], [64602.7, 0.002], [64602.8, 0.95], [64603.2, 0.824], [64603.3, 0.974], [64603.4, 0.002], [64603.5, 0.477], [64603.6, 0.001], [64603.9, 0.154], [64604.1, 0.0], [64604.2, 2.32], [64604.4, 0.083], [64604.8, 0.008], [64604.9, 0.057], [64605.0, 0.059], [64605.2, 0.172], [64605.4, 0.009], [64605.5, 0.015], [64605.8, 0.122], [64605.9, 2.048], [64606.0, 6.045], [64606.1, 0.311], [64606.2, 0.124], [64606.3, 0.807], [64606.4, 0.008], [64606.6, 0.0], [64606.7, 0.329], [64606.8, 0.13], [64606.9, 0.395], [64607.0, 2.321], [64607.1, 0.156], [64607.5, 0.096], [64608.0, 0.01], [64608.1, 2.204], [64608.2, 5.297], [64608.3, 0.0], [64608.4, 0.0], [64608.5, 1.887], [64608.7, 1.237], [64608.8, 0.019], [64608.9, 0.001], [64609.1, 0.0], [64609.3, 0.003], [64609.4, 0.0], [64609.5, 0.003], [64609.6, 0.001], [64609.9, 0.09], [64610.0, 0.022], [64610.1, 0.002], [64610.2, 0.013], [64610.3, 0.154], [64610.8, 0.442], [64611.0, 0.0], [64611.4, 0.0], [64611.7, 0.001], [64611.9, 0.588], [64612.3, 0.002], [64612.4, 0.0], [64612.5, 0.002], [64612.6, 0.001], [64613.0, 2.32], [64613.2, 0.03], [64613.3, 0.115], [64613.4, 0.019], [64613.5, 0.014], [64613.9, 0.071], [64614.0, 0.019], [64614.1, 0.005], [64614.4, 0.024], [64614.6, 0.0], [64614.7, 0.001], [64615.0, 0.045], [64615.3, 0.003], [64615.4, 0.0], [64615.5, 0.001], [64615.6, 1.211], [64615.9, 0.0], [64616.2, 0.38], [64616.5, 0.05], [64616.9, 1.391], [64617.0, 0.311], [64617.3, 0.001], [64617.4, 0.001], [64618.1, 0.0], [64618.3, 0.001], [64619.2, 0.001], [64619.8, 0.083], [64621.4, 0.01], [64622.3, 0.157], [64622.5, 0.094], [64623.2, 0.0], [64623.4, 0.0], [64623.7, 0.001], [64624.5, 0.254], [64624.8, 0.165], [64624.9, 0.002], [64625.3, 0.015], [64625.5, 1.116], [64626.3, 0.003], [64627.1, 0.002], [64627.6, 2.091], [64627.8, 0.166], [64628.0, 0.001], [64628.6, 0.0], [64629.1, 0.044], [64629.3, 0.003], [64629.4, 0.0], [64630.3, 0.002], [64630.8, 1.354], [64631.6, 0.0], [64631.8, 0.015], [64632.2, 0.071], [64632.4, 0.004], [64632.8, 4.634], [64633.2, 0.274], [64634.2, 0.006], [64634.5, 1.473], [64635.6, 0.0], [64635.9, 0.0], [64636.5, 0.004], [64637.0, 0.037], [64638.1, 0.853], [64638.2, 0.006], [64638.5, 0.01], [64638.6, 1.472], [64638.7, 0.005], [64638.8, 1.355], [64639.1, 0.472], [64639.2, 0.003], [64639.3, 0.002], [64639.8, 0.032], [64640.4, 2.319], [64641.9, 0.074], [64642.3, 0.003], [64642.4, 0.001], [64642.7, 0.024], [64643.5, 2.329], [64645.2, 0.161], [64645.3, 0.001], [64645.5, 0.0], [64648.3, 0.008], [64648.4, 0.002], [64648.5, 0.527], [64648.6, 0.003], [64649.0, 0.03], [64649.7, 0.001], [64651.1, 0.008], [64651.8, 0.004], [64652.0, 0.015], [64652.3, 1.471], [64652.4, 0.001], [64652.8, 2.338], [64653.3, 0.0], [64653.5, 0.0], [64653.8, 0.004], [64654.2, 0.305], [64654.7, 0.001], [64654.9, 0.0], [64655.0, 0.001], [64655.3, 0.026], [64655.5, 0.013], [64656.1, 0.0], [64656.6, 0.0], [64656.7, 0.186], [64656.9, 3.767], [64657.0, 0.002], [64658.0, 0.006], [64658.1, 0.01], [64659.8, 0.911], [64660.0, 0.035], [64660.8, 0.0], [64661.6, 0.021], [64662.3, 0.0], [64663.3, 0.043], [64666.7, 0.0], [64667.1, 0.0], [64667.4, 0.001], [64668.0, 0.02], [64668.9, 0.001], [64670.2, 2.155], [64671.0, 0.014], [64671.1, 1.084], [64672.7, 0.0], [64673.2, 0.402], [64674.1, 0.0], [64675.4, 11.21], [64675.5, 0.0], [64676.0, 0.025], [64677.0, 2.619], [64677.7, 44.599], [64677.8, 2.154], [64679.8, 0.585], [64682.5, 0.155], [64684.0, 5.729], [64684.6, 2.324], [64685.4, 2.154], [64686.7, 0.0], [64693.4, 0.0], [64694.4, 0.014], [64696.7, 0.113], [64698.7, 2.32], [64705.5, 0.337], [64706.6, 0.003], [64707.6, 0.0], [64708.2, 0.0], [64709.4, 1.001], [64714.5, 1.214], [64715.9, 0.018], [64717.0, 0.001], [64720.1, 1.84], [64720.2, 5.408], [64722.3, 0.47], [64723.7, 0.029], [64733.0, 0.001], [64735.1, 0.027], [64737.2, 7.59], [64744.2, 0.332], [64746.6, 0.069], [64747.5, 0.557], [64748.0, 0.001], [64760.1, 0.024], [64761.4, 0.005], [64766.6, 0.187], [64767.9, 0.0], [64768.0, 16.214], [64768.4, 0.791], [64770.0, 0.042], [64771.2, 0.0], [64771.4, 0.008], [64772.7, 0.033], [64774.6, 6.895], [64776.0, 13.396], [64776.7, 0.027], [64776.8, 0.001], [64778.9, 0.012], [64784.1, 0.0], [64785.7, 0.016], [64786.2, 0.209], [64792.4, 0.0], [64798.8, 0.071], [64799.7, 0.076], [64836.0, 0.017], [64836.4, 0.0], [64838.4, 0.094], [64838.9, 0.0], [64843.4, 0.0], [64844.3, 0.2], [64874.5, 0.208], [64876.6, 0.526], [64882.1, 0.005], [64882.2, 0.017], [64883.0, 0.497], [64884.7, 0.0], [64886.0, 0.0], [64886.3, 1.392], [64887.4, 0.0], [64887.5, 0.011], [64887.7, 0.0], [64900.6, 0.002], [64908.0, 0.0], [64965.2, 0.001], [64972.6, 0.0], [65029.7, 0.012], [65037.2, 0.0], [65094.3, 0.001], [65101.8, 0.0], [65222.1, 3.052], [65223.5, 0.007], [65225.9, 0.161], [65226.0, 2.096], [65226.4, 3.214], [65580.6, 0.0], [65581.6, 6.503], [70020.5, 0.002]]}
{"kind": "depth", "E": 1787088862247, "U": 11315947550284, "u": 11315947560935, "recv_ms": 1787088862264, "bids": [[1000.0, 35.76], [14376.2, 0.49], [14480.5, 2.45], [58118.5, 0.002], [61347.3, 0.001], [61996.8, 0.003], [63284.7, 0.004], [63773.3, 22.14], [63930.4, 0.0], [64376.5, 0.091], [64376.6, 4.132], [64415.2, 0.002], [64415.3, 4.926], [64429.9, 0.027], [64432.2, 4.168], [64450.1, 1.9], [64452.6, 0.113], [64453.0, 0.238], [64453.2, 0.086], [64455.7, 0.003], [64460.1, 29.32], [64479.4, 2.783], [64482.5, 0.015], [64493.4, 2.35], [64494.4, 0.036], [64496.0, 0.021], [64496.3, 2.484], [64498.0, 0.594], [64498.7, 0.001], [64499.9, 0.185], [64502.1, 0.163], [64505.6, 0.28], [64506.3, 0.028], [64506.4, 0.009], [64506.9, 0.043], [64509.0, 1.341], [64511.6, 0.03], [64512.8, 0.028], [64512.9, 0.01], [64514.2, 0.13], [64514.5, 1.484], [64514.6, 0.06], [64514.9, 0.004], [64516.0, 1.53], [64516.7, 0.028], [64519.3, 0.027], [64519.9, 0.017], [64521.9, 0.002], [64523.5, 0.329], [64524.5, 2.39], [64526.1, 0.062], [64526.6, 0.005], [64527.0, 0.038], [64527.3, 0.971], [64527.8, 0.036], [64528.2, 1.491], [64528.3, 0.002], [64528.9, 0.032], [64529.2, 0.003], [64529.3, 0.023], [64529.8, 0.002], [64530.4, 0.001], [64530.7, 0.005], [64531.0, 0.371], [64531.7, 0.008], [64532.1, 0.0], [64532.2, 0.038], [64532.7, 0.0], [64533.8, 0.449], [64533.9, 0.0], [64534.1, 0.08], [64534.8, 0.018], [64535.4, 0.006], [64536.5, 2.333], [64537.5, 0.069], [64538.2, 0.006], [64539.1, 0.038], [64539.4, 0.003], [64539.8, 0.025], [64540.3, 0.019], [64540.7, 0.488], [64541.0, 0.697], [64541.8, 0.391], [64542.0, 0.657], [64542.1, 0.0], [64542.4, 0.087], [64543.0, 0.069], [64543.1, 0.0], [64544.0, 0.045], [64544.2, 0.566], [64544.3, 0.018], [64544.6, 0.122], [64545.1, 0.005], [64545.5, 0.416], [64545.9, 0.039], [64546.7, 0.061], [64547.0, 0.0], [64547.2, 0.038], [64547.9, 0.116], [64548.0, 0.421], [64548.2, 3.465], [64548.4, 0.109], [64550.1, 0.0], [64550.4, 0.057], [64550.8, 0.024], [64551.3, 0.001], [64551.4, 2.422], [64551.5, 0.329], [64551.6, 0.004], [64551.8, 0.015], [64551.9, 0.493], [64552.4, 0.037], [64552.5, 0.001], [64552.8, 0.072], [64552.9, 0.074], [64553.2, 0.003], [64553.3, 0.582], [64553.6, 0.464], [64554.2, 0.058], [64554.6, 0.501], [64554.7, 0.401], [64554.9, 1.035], [64555.7, 2.307], [64555.9, 0.001], [64556.4, 0.001], [64556.7, 0.005], [64557.6, 0.0], [64558.0, 0.042], [64558.2, 0.009], [64558.3, 0.559], [64558.7, 0.004], [64559.1, 0.001], [64559.9, 0.012], [64560.2, 2.341], [64560.3, 0.098], [64560.4, 0.003], [64560.5, 0.007], [64561.2, 0.012], [64561.3, 0.427], [64561.7, 0.019], [64562.3, 0.0], [64562.5, 0.56], [64562.9, 1.65], [64563.1, 0.946], [64563.2, 1.544], [64563.3, 0.006], [64563.5, 0.704], [64563.6, 1.928], [64563.7, 0.002], [64563.9, 0.347], [64564.0, 0.063], [64564.4, 0.014], [64564.5, 0.062], [64564.6, 0.465], [64565.0, 0.544], [64565.6, 0.315], [64565.7, 0.001], [64566.4, 1.133], [64566.6, 1.707], [64566.8, 0.09], [64566.9, 0.0], [64567.1, 0.215], [64567.2, 0.112], [64567.3, 0.101], [64567.5, 0.177], [64567.6, 0.128], [64567.9, 0.034], [64568.0, 0.357], [64568.1, 0.008], [64568.2, 0.033], [64568.4, 0.282], [64568.5, 0.034], [64568.6, 0.002], [64568.9, 0.116], [64569.2, 0.018], [64569.3, 0.833], [64569.4, 1.001], [64569.6, 0.009], [64569.7, 0.0], [64569.9, 0.007], [64570.0, 0.02], [64570.1, 0.713], [64570.3, 0.001], [64570.4, 0.0], [64570.9, 0.089], [64571.0, 0.001], [64571.1, 0.073], [64571.2, 0.167], [64571.3, 0.394], [64571.5, 0.001], [64571.6, 0.077], [64571.7, 0.155], [64571.8, 0.069], [64571.9, 0.001], [64572.0, 0.304], [64572.2, 0.006], [64572.3, 0.002], [64572.4, 0.0], [64572.5, 0.001], [64572.6, 0.101], [64572.7, 0.31], [64572.8, 0.769], [64573.1, 0.084], [64573.2, 0.005], [64573.4, 0.084], [64573.9, 0.268], [64574.4, 0.003], [64574.7, 0.0], [64574.9, 0.011], [64575.5, 0.003], [64576.1, 0.158], [64576.2, 9.053]], "asks": [[64576.3, 26.626], [64576.4, 0.312], [64576.5, 0.191], [64576.6, 0.001], [64577.2, 0.007], [64577.3, 0.001], [64577.4, 0.0], [64577.5, 0.0], [64577.7, 0.241], [64578.0, 0.021], [64578.2, 0.022], [64578.3, 0.007], [64578.5, 0.016], [64578.8, 0.0], [64578.9, 0.0], [64579.0, 0.002], [64579.1, 0.085], [64579.2, 0.007], [64579.5, 0.001], [64579.9, 0.25], [64580.1, 5.515], [64580.2, 6.323], [64580.3, 0.001], [64580.4, 2.32], [64580.5, 2.157], [64580.6, 45.559], [64580.7, 2.079], [64580.8, 0.003], [64580.9, 0.275], [64581.4, 0.088], [64582.0, 0.16], [64582.4, 0.027], [64582.6, 0.471], [64583.3, 0.31], [64585.6, 1.597], [64586.7, 0.006], [64586.9, 0.072], [64587.3, 0.015], [64587.4, 0.232], [64588.4, 0.53], [64588.5, 0.474], [64588.6, 0.254], [64588.8, 0.511], [64588.9, 0.154], [64589.0, 1.598], [64589.1, 2.711], [64589.6, 0.002], [64590.1, 0.035], [64590.2, 0.208], [64590.3, 0.02], [64590.5, 0.032], [64590.6, 0.003], [64590.7, 0.771], [64590.8, 0.001], [64590.9, 0.01], [64591.2, 0.211], [64591.5, 0.001], [64591.6, 0.004], [64591.7, 0.486], [64591.8, 1.238], [64592.1, 5.652], [64592.7, 0.002], [64592.9, 0.002], [64593.2, 0.003], [64593.3, 0.014], [64593.5, 0.0], [64593.6, 0.006], [64593.7, 0.649], [64593.8, 0.044], [64594.7, 0.0], [64594.8, 0.004], [64594.9, 0.0], [64595.0, 0.001], [64595.3, 0.464], [64595.4, 0.0], [64595.5, 0.001], [64595.6, 0.545], [64595.7, 0.648], [64595.8, 0.004], [64596.0, 1.047], [64596.2, 0.0], [64597.2, 0.468], [64597.9, 0.001], [64598.0, 0.022], [64598.4, 0.011], [64598.5, 0.0], [64598.6, 10.032], [64599.5, 0.561], [64599.6, 0.063], [64599.7, 0.003], [64600.0, 1.243], [64600.1, 0.628], [64600.2, 0.168], [64600.5, 0.003], [64600.6, 5.002], [64600.7, 0.041], [64600.9, 1.368], [64601.0, 0.017], [64602.1, 0.02], [64602.3, 0.038], [64602.4, 0.024], [64602.5, 0.053], [64604.2, 4.205], [64604.4, 0.077], [64604.9, 0.051], [64605.1, 0.311], [64605.2, 0.174], [64605.3, 0.026], [64605.6, 0.045], [64605.7, 0.01], [64605.9, 2.298], [64606.3, 1.081], [64607.3, 0.142], [64607.4, 0.879], [64607.6, 0.23], [64608.2, 5.299], [64608.3, 0.002], [64608.5, 0.002], [64609.1, 0.002], [64609.2, 0.002], [64610.2, 0.014], [64610.8, 0.472], [64611.2, 0.024], [64611.3, 0.003], [64613.5, 0.0], [64613.8, 0.023], [64615.0, 0.015], [64616.2, 0.17], [64616.5, 0.049], [64616.9, 1.237], [64617.1, 0.178], [64617.8, 0.061], [64619.1, 2.319], [64619.3, 0.023], [64619.5, 3.503], [64622.1, 0.466], [64622.3, 0.003], [64623.8, 1.865], [64624.4, 0.0], [64624.7, 0.162], [64624.8, 0.003], [64625.0, 0.01], [64625.1, 0.001], [64625.3, 0.0], [64627.5, 0.449], [64627.6, 1.642], [64629.5, 0.101], [64631.2, 0.21], [64631.5, 0.069], [64633.6, 0.671], [64633.8, 0.002], [64637.9, 0.028], [64638.0, 0.464], [64638.1, 0.404], [64638.5, 1.482], [64638.6, 0.0], [64639.2, 0.029], [64641.2, 0.466], [64642.5, 0.049], [64647.6, 0.039], [64648.4, 0.451], [64648.5, 0.078], [64652.2, 1.498], [64652.3, 0.0], [64657.9, 50.91], [64659.8, 0.905], [64661.7, 0.027], [64662.3, 0.0], [64662.8, 0.046], [64664.7, 0.003], [64669.0, 0.006], [64672.2, 0.003], [64673.3, 2.452], [64675.4, 0.0], [64677.3, 0.0], [64677.7, 0.018], [64691.3, 0.004], [64695.1, 0.1], [64700.6, 0.001], [64708.3, 0.024], [64710.1, 0.0], [64732.9, 10.43], [64737.2, 0.249], [64768.0, 16.137], [64776.0, 13.319], [64876.6, 0.0], [64883.0, 0.086], [64886.3, 1.469], [65222.1, 3.05], [65679.1, 2.537], [65867.8, 1.522]]}
{"kind": "depth", "E": 1787088862349, "U": 11315947561016, "u": 11315947567214, "recv_ms": 1787088862299, "bids": [[14376.2, 0.84], [14480.5, 2.1], [51661.0, 0.0], [51664.0, 0.0], [58118.5, 0.002], [61347.3, 0.001], [61531.5, 0.024], [61535.6, 0.101], [63576.2, 0.051], [63929.8, 0.387], [63930.4, 0.002], [63934.3, 0.0], [64460.1, 0.529], [64468.9, 0.022], [64475.5, 0.025], [64482.1, 28.794], [64512.0, 0.12], [64534.1, 0.196], [64536.6, 0.21], [64539.7, 0.051], [64542.6, 1.063], [64543.0, 0.223], [64544.2, 0.45], [64547.3, 0.057], [64547.4, 0.289], [64548.1, 0.644], [64548.3, 2.321], [64550.4, 0.058], [64552.6, 0.008], [64553.5, 0.0], [64553.6, 0.462], [64554.1, 0.004], [64555.7, 2.423], [64556.3, 0.013], [64556.8, 0.18], [64556.9, 0.562], [64557.6, 0.0], [64558.3, 0.001], [64558.4, 0.004], [64559.1, 0.009], [64559.2, 0.008], [64559.4, 0.021], [64559.8, 0.318], [64560.3, 0.159], [64560.5, 0.0], [64560.6, 0.004], [64560.7, 0.002], [64561.3, 0.428], [64561.5, 0.035], [64561.6, 0.001], [64561.8, 0.927], [64562.5, 0.444], [64562.7, 0.0], [64563.1, 0.019], [64563.5, 0.085], [64563.6, 0.012], [64563.7, 0.542], [64564.1, 0.0], [64564.5, 0.063], [64564.9, 0.617], [64565.0, 0.002], [64566.4, 0.571], [64566.6, 0.151], [64566.7, 0.072], [64566.8, 0.16], [64566.9, 0.07], [64567.0, 0.584], [64567.4, 0.175], [64568.9, 0.032], [64569.1, 0.04], [64569.2, 0.05], [64569.3, 1.207], [64569.4, 0.01], [64569.5, 2.32], [64569.6, 0.01], [64569.9, 0.008], [64570.0, 0.022], [64570.2, 0.004], [64570.3, 0.009], [64570.4, 1.548], [64570.5, 0.804], [64570.6, 1.982], [64570.9, 0.086], [64571.1, 0.008], [64571.3, 0.087], [64572.8, 0.979], [64573.4, 0.0], [64574.0, 0.008], [64574.4, 0.087], [64576.0, 0.003], [64576.2, 10.375]], "asks": [[64576.3, 27.265], [64577.2, 0.0], [64577.5, 0.007], [64577.7, 0.087], [64578.0, 0.044], [64578.3, 0.017], [64579.1, 0.084], [64579.4, 0.034], [64579.5, 0.001], [64579.7, 0.012], [64579.9, 0.25], [64580.0, 8.033], [64580.1, 0.096], [64580.2, 0.655], [64580.3, 0.001], [64580.6, 44.976], [64580.8, 0.004], [64580.9, 0.114], [64584.0, 0.007], [64585.2, 0.185], [64585.7, 0.028], [64586.5, 2.361], [64588.5, 2.178], [64589.0, 1.658], [64589.1, 2.595], [64590.1, 0.015], [64590.2, 0.168], [64590.4, 0.044], [64590.9, 0.01], [64591.5, 0.001], [64591.8, 1.24], [64592.0, 0.258], [64592.9, 0.002], [64593.2, 0.083], [64593.3, 0.556], [64594.4, 0.927], [64595.6, 0.004], [64595.7, 0.808], [64596.0, 0.12], [64596.1, 0.001], [64597.4, 0.04], [64597.9, 0.558], [64598.0, 0.022], [64598.5, 2.435], [64599.1, 1.45], [64599.5, 0.004], [64599.9, 0.628], [64600.9, 1.195], [64607.8, 0.181], [64608.0, 0.215], [64610.0, 0.138], [64616.6, 0.002], [64620.8, 0.005], [64622.0, 0.32], [64622.1, 0.31], [64631.0, 2.206], [64635.9, 0.116], [64637.8, 0.011], [64638.5, 1.472], [64657.9, 6.329], [64664.5, 44.585], [64834.6, 2.727], [64883.0, 0.163], [65222.1, 3.05], [65576.3, 0.024], [65867.8, 1.525], [66525.8, 2.177], [67601.6, 0.04], [67606.1, 0.0]]}
{"kind": "depth", "E": 1787088862451, "U": 11315947567220, "u": 11315947573277, "recv_ms": 1787088862400, "bids": [[1000.0, 35.76], [14376.2, 1.204], [14480.5, 1.736], [51664.0, 0.0], [58118.5, 0.002], [61347.3, 0.001], [61993.1, 0.003], [63478.5, 4.719], [63665.2, 0.863], [63708.8, 22.877], [63930.4, 0.0], [64257.6, 6.654], [64460.1, 0.529], [64468.9, 28.813], [64482.1, 0.003], [64486.5, 0.106], [64527.4, 0.0], [64536.5, 2.319], [64542.9, 1.252], [64543.0, 0.069], [64543.8, 0.012], [64546.7, 0.071], [64547.4, 0.279], [64547.6, 0.009], [64551.0, 0.036], [64557.9, 0.003], [64559.2, 0.0], [64559.9, 0.013], [64560.2, 2.321], [64560.3, 0.167], [64563.2, 1.548], [64563.3, 0.002], [64563.5, 0.0], [64563.6, 0.012], [64564.5, 0.06], [64565.8, 0.005], [64566.8, 0.23], [64566.9, 0.09], [64567.1, 0.213], [64567.6, 0.198], [64567.9, 0.035], [64569.5, 2.322], [64569.6, 1.558], [64569.7, 1.226], [64570.0, 0.02], [64570.2, 2.164], [64570.3, 0.001], [64570.4, 0.0], [64570.5, 0.185], [64570.6, 0.0], [64570.7, 0.076], [64571.5, 0.311], [64571.6, 0.077], [64572.3, 0.004], [64572.9, 0.004], [64573.3, 0.007], [64573.8, 0.0], [64574.2, 0.047], [64574.8, 0.087], [64576.2, 8.696]], "asks": [[64576.3, 27.552], [64576.4, 0.285], [64577.8, 0.022], [64578.0, 0.024], [64578.2, 0.0], [64578.3, 0.006], [64579.0, 0.001], [64579.4, 0.002], [64579.7, 0.002], [64580.4, 2.323], [64580.6, 44.976], [64581.7, 0.014], [64582.9, 0.031], [64583.2, 0.003], [64583.8, 0.003], [64583.9, 0.526], [64585.2, 0.184], [64586.3, 0.667], [64600.0, 0.995], [64609.9, 0.088], [64611.2, 0.022], [64612.5, 0.0], [64613.8, 0.021], [64614.9, 0.145], [64621.5, 0.23], [64621.7, 0.885], [64622.0, 0.164], [64631.2, 0.0], [64637.1, 0.01], [64637.8, 0.001], [64637.9, 0.238], [64647.4, 0.239], [64655.7, 46.903], [64664.5, 0.004], [64832.0, 0.131], [64982.2, 2.764], [65222.1, 3.05]]}
{"kind": "depth", "E": 1787088862553, "U": 11315947573379, "u": 11315947578556, "recv_ms": 1787088862501, "bids": [[1000.0, 35.76], [14376.2, 1.554], [14480.5, 1.386], [58118.5, 0.002], [61347.3, 0.001], [61993.1, 0.0], [63576.2, 0.031], [63579.6, 22.332], [63644.2, 31.154], [63704.5, 0.786], [63729.6, 0.784], [63773.3, 21.906], [63930.4, 0.0], [63931.6, 0.002], [64257.5, 0.001], [64441.1, 0.172], [64520.9, 0.032], [64521.2, 0.056], [64521.5, 0.045], [64521.9, 0.034], [64523.8, 0.05], [64540.8, 0.011], [64542.8, 0.008], [64542.9, 1.098], [64546.2, 0.012], [64546.7, 0.061], [64548.2, 3.535], [64548.4, 0.209], [64550.9, 0.004], [64551.9, 0.493], [64552.7, 0.353], [64554.1, 0.002], [64555.3, 0.0], [64556.8, 0.183], [64557.8, 0.041], [64558.0, 0.043], [64558.7, 0.066], [64559.1, 0.001], [64559.9, 0.012], [64560.0, 0.266], [64560.3, 0.106], [64563.5, 0.087], [64567.3, 0.171], [64567.9, 0.033], [64569.6, 2.134], [64569.7, 0.565], [64569.9, 0.005], [64570.2, 2.164], [64570.6, 0.003], [64571.3, 0.084], [64571.5, 0.001], [64571.6, 0.077], [64572.2, 0.316], [64572.7, 0.0], [64572.8, 0.723], [64574.4, 0.003], [64575.0, 0.011], [64576.2, 8.698]], "asks": [[64576.3, 27.775], [64577.2, 0.019], [64577.6, 0.907], [64579.0, 0.011], [64579.7, 0.012], [64579.8, 0.001], [64580.3, 0.009], [64580.6, 44.895], [64580.7, 2.077], [64584.4, 0.002], [64589.0, 1.66], [64590.9, 0.002], [64591.6, 0.006], [64592.9, 0.0], [64593.4, 0.787], [64601.6, 0.009], [64606.0, 6.043], [64615.6, 0.02], [64616.9, 1.237], [64617.1, 0.024], [64635.9, 0.119], [64636.6, 0.01], [64637.1, 0.0], [64638.8, 1.352], [64791.5, 0.0], [64860.9, 0.002], [64899.2, 0.001], [65222.1, 3.05], [65576.3, 0.004], [65665.6, 2.063], [71034.0, 0.0]]}
{"kind": "depth", "E": 1787088862655, "U": 11315947578601, "u": 11315947583831, "recv_ms": 1787088862608, "bids": [[14376.2, 1.918], [14480.5, 1.022], [51661.0, 0.0], [58118.5, 0.002], [61347.3, 0.001], [61993.1, 0.003], [63575.4, 1.101], [63639.9, 1.098], [63858.7, 0.955], [63930.4, 0.0], [64485.0, 0.188], [64486.1, 0.0], [64506.9, 0.07], [64522.2, 1.269], [64531.0, 0.921], [64535.3, 0.003], [64537.4, 0.204], [64541.7, 0.008], [64546.8, 0.317], [64547.9, 0.186], [64548.1, 0.712], [64548.2, 3.227], [64548.3, 2.421], [64548.5, 0.507], [64548.7, 0.075], [64549.6, 0.1], [64550.1, 0.1], [64550.4, 0.458], [64551.7, 0.003], [64551.9, 0.495], [64552.7, 0.351], [64554.1, 0.002], [64554.7, 0.002], [64556.9, 0.569], [64557.8, 0.041], [64558.2, 0.002], [64559.1, 0.009], [64560.3, 0.183], [64563.5, 0.002], [64563.9, 0.357], [64564.1, 0.31], [64564.9, 0.607], [64565.6, 0.005], [64569.0, 0.085], [64569.6, 1.558], [64569.7, 0.0], [64569.8, 0.78], [64569.9, 0.005], [64570.0, 0.023], [64570.2, 0.004], [64570.3, 0.001], [64570.4, 0.016], [64570.6, 0.004], [64571.5, 0.004], [64572.1, 0.048], [64572.2, 0.009], [64572.8, 1.042], [64573.1, 0.0], [64573.8, 0.001], [64574.4, 0.005], [64574.5, 0.001], [64574.8, 0.053], [64575.7, 0.001], [64576.1, 0.157], [64576.2, 7.488]], "asks": [[64576.3, 27.854], [64577.2, 0.0], [64577.5, 0.022], [64577.6, 0.884], [64577.7, 0.115], [64578.3, 0.019], [64579.0, 0.01], [64579.5, 0.104], [64579.9, 0.258], [64580.3, 0.001], [64580.5, 2.014], [64580.6, 44.813], [64580.7, 1.937], [64584.6, 0.073], [64587.7, 0.002], [64590.0, 3.051], [64590.9, 0.0], [64591.6, 0.006], [64592.1, 5.652], [64592.9, 0.0], [64594.3, 10.507], [64608.2, 5.299], [64653.5, 0.0], [64653.8, 0.002], [64655.7, 2.322], [64662.3, 44.581], [64775.7, 0.031], [64776.7, 0.024], [64883.0, 0.086], [64886.3, 1.392], [65097.3, 3.098], [65222.1, 3.05], [65498.3, 33.542]]}
{"kind": "depth", "E": 1787088862757, "U": 11315947583894, "u": 11315947588569, "recv_ms": 1787088862705, "bids": [[1000.0, 35.76], [14376.2, 2.268], [14480.5, 0.672], [51664.4, 0.0], [58118.5, 0.002], [61993.1, 0.0], [63576.2, 0.051], [63663.6, 1.873], [63930.4, 0.0], [64120.9, 0.0], [64253.3, 0.412], [64514.2, 0.13], [64545.8, 0.013], [64546.2, 0.002], [64547.9, 0.256], [64548.0, 0.491], [64548.2, 3.327], [64548.6, 0.564], [64549.1, 0.006], [64551.4, 2.423], [64551.9, 0.493], [64553.0, 0.002], [64554.5, 0.094], [64557.8, 0.033], [64559.1, 0.009], [64560.3, 0.098], [64561.6, 0.005], [64563.5, 0.002], [64565.4, 0.006], [64568.4, 0.436], [64569.6, 2.134], [64570.2, 0.097], [64571.0, 0.004], [64572.2, 0.319], [64572.5, 0.085], [64572.8, 1.07], [64572.9, 0.004], [64573.4, 0.084]], "asks": [[64576.3, 27.877], [64577.9, 0.007], [64578.3, 0.009], [64579.5, 0.001], [64579.7, 0.002], [64579.9, 0.25], [64580.1, 0.095], [64580.4, 2.323], [64580.6, 44.812], [64580.7, 1.935], [64591.0, 0.008], [64591.2, 0.219], [64591.6, 0.004], [64593.5, 0.002], [64598.6, 0.032], [64608.1, 2.204], [64636.2, 0.01], [64636.6, 0.0], [64653.8, 0.004], [64655.7, 46.903], [64658.4, 0.002], [64662.3, 0.0], [64662.9, 0.676], [64690.8, 0.021], [64695.3, 0.0], [64886.3, 1.469], [65222.1, 3.051], [65298.1, 9.641], [65387.9, 5.577], [65452.5, 15.421], [65517.1, 30.179], [65576.3, 0.024], [70182.9, 0.012]]}
{"kind": "depth", "E": 1787088862859, "U": 11315947588709, "u": 11315947593204, "recv_ms": 1787088862810, "bids": [[1000.0, 35.76], [14276.2, 0.07], [14376.2, 2.562], [14380.5, 1.134], [14480.5, 0.378], [51661.0, 0.0], [58118.5, 0.002], [61347.3, 0.001], [63708.8, 22.094], [63930.4, 0.0], [64257.5, 0.0], [64455.9, 0.013], [64460.2, 0.001], [64463.0, 0.024], [64467.3, 0.005], [64468.9, 0.022], [64470.0, 0.31], [64474.3, 0.0], [64477.1, 0.013], [64481.4, 0.204], [64484.1, 0.014], [64486.5, 28.897], [64488.4, 0.0], [64491.2, 0.013], [64495.5, 0.0], [64498.2, 0.79], [64502.5, 0.002], [64505.3, 0.014], [64509.6, 0.031], [64544.8, 0.058], [64548.0, 0.561], [64548.8, 0.071], [64559.1, 0.001], [64560.3, 0.106], [64569.6, 1.558], [64570.0, 0.02], [64570.2, 0.097], [64571.9, 0.004], [64576.2, 7.59]], "asks": [[64576.3, 27.889], [64594.3, 0.508], [64598.1, 10.126], [64608.2, 5.299], [64640.9, 0.004], [64653.2, 0.013], [64653.5, 44.931], [64653.8, 0.002], [64655.7, 2.322], [64659.8, 0.892], [64660.2, 0.016], [64662.3, 0.0], [64666.9, 0.0], [64667.3, 0.016], [64674.0, 0.0], [64674.4, 0.035], [64681.0, 0.001], [64681.4, 0.013], [64688.1, 1.237], [64688.5, 0.052], [64695.1, 0.087], [64695.5, 0.398], [64698.8, 0.008], [64702.2, 0.0], [64702.6, 0.013], [64705.8, 0.098], [64709.2, 11.717], [64713.9, 0.027], [64733.3, 0.007], [64790.9, 0.0], [65097.2, 7.821], [65147.2, 0.006], [65222.1, 3.051], [65349.2, 5.502], [65427.3, 11.448], [65484.8, 48.224], [65497.6, 2.054], [65867.8, 1.528]]}
{"kind": "depth", "E": 1787088862961, "U": 11315947593311, "u": 11315947597245, "recv_ms": 1787088862908, "bids": [[14276.2, 0.28], [14376.2, 2.702], [14380.5, 0.924], [14480.5, 0.238], [58118.5, 0.002], [61993.1, 0.003], [63576.2, 0.031], [63930.4, 0.0], [64222.3, 0.494], [64240.5, 0.0], [64542.4, 0.085], [64545.5, 0.426], [64545.8, 0.003], [64548.5, 0.577], [64551.5, 0.483], [64563.4, 0.67], [64569.6, 0.01], [64570.2, 0.097], [64570.3, 1.549], [64570.4, 0.0], [64571.7, 0.157], [64572.3, 0.004], [64572.4, 0.008], [64572.8, 0.725], [64572.9, 2.164], [64573.0, 0.018], [64574.8, 0.295]], "asks": [[64577.2, 0.143], [64579.2, 0.018], [64579.8, 0.352], [64582.5, 0.001], [64583.4, 0.007], [64607.8, 0.181], [64635.9, 0.129], [64636.2, 0.0], [64790.4, 0.393], [64899.2, 0.002], [65222.1, 3.051], [65280.2, 0.693], [65452.4, 6.383], [65480.4, 2.287], [65517.0, 15.954], [65517.1, 28.045], [65576.3, 0.004]]}
{"kind": "depth", "E": 1787088863063, "U": 11315947597453, "u": 11315947602008, "recv_ms": 1787088863021, "bids": [[1000.0, 35.76], [14276.2, 0.532], [14376.2, 2.814], [14380.5, 0.672], [14480.5, 0.126], [58118.5, 0.002], [61347.3, 0.001], [61351.5, 0.004], [61351.6, 2.453], [61993.1, 0.0], [63495.8, 0.788], [63704.4, 0.815], [63930.4, 0.0], [64243.6, 0.705], [64253.3, 0.402], [64257.6, 6.664], [64543.6, 0.0], [64545.2, 2.32], [64546.3, 0.199], [64551.5, 0.329], [64552.5, 0.001], [64553.2, 0.005], [64554.5, 0.092], [64559.1, 0.009], [64560.3, 0.106], [64563.2, 1.547], [64563.5, 0.087], [64564.6, 0.465], [64569.6, 2.71], [64569.8, 0.231], [64570.2, 0.569], [64570.3, 0.001], [64571.0, 0.001], [64571.1, 0.011], [64571.8, 0.223], [64571.9, 2.161], [64572.8, 0.725], [64572.9, 0.004], [64573.0, 0.002], [64573.4, 0.0], [64574.8, 0.053], [64575.1, 0.087], [64576.1, 0.003]], "asks": [[64576.3, 27.889], [64579.0, 0.02], [64579.6, 0.008], [64579.7, 0.554], [64580.2, 0.105], [64580.7, 1.996], [64585.0, 0.001], [64589.9, 0.033], [64591.2, 0.211], [64592.0, 0.26], [64593.5, 0.0], [64598.8, 0.037], [64606.1, 0.93], [64621.4, 0.012], [65222.1, 3.051], [65581.7, 20.401]]}
{"kind": "depth", "E": 1787088863165, "U": 11315947602107, "u": 11315947606773, "recv_ms": 1787088863121, "bids": [[1000.0, 35.76], [14276.2, 0.77], [14376.2, 2.94], [14380.5, 0.434], [14480.5, 0.0], [51664.0, 0.0], [58118.5, 0.002], [61993.1, 0.003], [63576.2, 0.051], [63930.4, 0.0], [64385.1, 0.723], [64419.1, 1.172], [64437.7, 0.001], [64438.2, 0.559], [64487.3, 7.088], [64494.8, 0.005], [64494.9, 0.007], [64499.3, 0.0], [64501.6, 0.0], [64501.8, 0.052], [64501.9, 0.015], [64509.0, 1.333], [64527.5, 0.329], [64528.7, 2.32], [64528.8, 1.245], [64528.9, 0.031], [64531.8, 0.009], [64531.9, 0.001], [64532.8, 0.001], [64536.9, 0.412], [64537.0, 0.021], [64537.1, 0.066], [64545.2, 2.33], [64545.5, 0.416], [64551.6, 0.158], [64551.7, 0.003], [64551.8, 0.03], [64559.1, 0.001], [64560.3, 0.106], [64561.8, 0.0], [64562.2, 0.0], [64562.7, 0.927], [64563.5, 0.002], [64563.6, 0.012], [64564.7, 0.144], [64565.5, 0.162], [64569.4, 0.012], [64569.5, 2.32], [64569.6, 1.566], [64569.7, 0.576], [64570.0, 0.02], [64570.2, 0.004], [64570.3, 0.558], [64570.4, 2.253], [64570.5, 0.188], [64571.9, 0.001], [64572.3, 0.004], [64572.8, 0.725], [64572.9, 0.004], [64573.4, 0.084], [64573.8, 0.003], [64574.8, 0.0], [64576.0, 0.235], [64576.1, 0.112]], "asks": [[64576.3, 28.187], [64578.6, 0.001], [64579.0, 0.01], [64579.6, 0.0], [64579.7, 0.544], [64580.3, 0.928], [64580.4, 2.331], [64580.5, 2.015], [64580.6, 44.558], [64582.0, 0.114], [64589.9, 0.025], [64591.6, 0.012], [64592.0, 0.258], [64593.3, 0.014], [64593.8, 0.046], [64594.3, 1.05], [64594.4, 0.0], [64595.2, 1.096], [64596.3, 2.208], [64597.9, 0.001], [64598.5, 2.319], [64598.8, 0.594], [64599.1, 1.393], [64599.9, 0.685], [64600.1, 0.744], [64608.1, 2.358], [64608.2, 5.299], [64615.6, 0.906], [64621.4, 0.168], [64621.5, 0.074], [64635.6, 0.01], [64635.9, 0.119], [64652.9, 7.151], [64732.8, 2.595], [64734.0, 0.001], [64752.8, 0.0], [64772.2, 1.433], [65135.4, 0.079], [65222.1, 3.051], [65349.1, 3.668], [65384.1, 0.757], [65388.6, 6.938], [65440.5, 3.075], [65480.4, 2.47], [65576.3, 0.024], [65595.2, 8.072], [65872.2, 0.003]]}
{"kind": "depth", "E": 1787088863267, "U": 11315947606798, "u": 11315947611304, "recv_ms": 1787088863215, "bids": [[14276.2, 1.12], [14380.5, 0.084], [51664.0, 0.0], [58118.5, 0.002], [61347.3, 0.001], [61351.5, 0.006], [61993.1, 0.0], [63366.5, 0.0], [63576.2, 0.031], [63930.4, 0.002], [64528.8, 1.244], [64532.8, 0.002], [64547.8, 0.449], [64551.5, 0.483], [64551.6, 0.004], [64551.7, 0.003], [64556.9, 0.011], [64558.0, 0.028], [64558.6, 0.558], [64561.2, 0.005], [64561.8, 0.0], [64562.7, 0.927], [64562.8, 0.007], [64563.5, 0.544], [64563.7, 0.0], [64564.1, 0.0], [64565.0, 0.002], [64566.6, 0.461], [64569.7, 1.152], [64570.4, 0.093], [64571.1, 0.008], [64571.9, 2.161], [64572.0, 0.307], [64572.8, 0.725], [64573.8, 0.002], [64575.9, 0.003], [64576.2, 8.17]], "asks": [[64576.3, 29.421], [64576.6, 0.006], [64579.5, 0.001], [64579.7, 0.003], [64579.9, 0.715], [64580.4, 2.408], [64580.5, 0.784], [64580.6, 44.43], [64583.3, 0.001], [64584.5, 0.312], [64593.3, 0.014], [64594.3, 0.508], [64594.4, 0.0], [64595.0, 0.543], [64595.1, 0.929], [64595.2, 0.169], [64598.4, 0.029], [64601.5, 0.0], [64606.1, 0.311], [64608.1, 2.358], [64695.6, 0.1], [65222.1, 3.051], [65517.0, 18.088], [65576.3, 0.004], [65581.6, 7.569], [70345.4, 0.004]]}
{"kind": "depth", "E": 1787088863369, "U": 11315947611372, "u": 11315947616401, "recv_ms": 1787088863316, "bids": [[1000.0, 35.76], [14276.2, 1.47], [14376.2, 2.73], [14377.6, 0.0], [14380.0, 0.0], [14380.5, 0.0], [58118.5, 0.002], [61347.3, 0.001], [63284.7, 0.007], [63708.8, 21.703], [63930.4, 0.0], [64059.6, 0.002], [64257.6, 6.664], [64468.9, 28.903], [64486.5, 0.106], [64487.3, 0.628], [64488.7, 0.0], [64497.5, 0.001], [64510.8, 0.03], [64524.6, 0.252], [64545.0, 0.297], [64545.2, 2.32], [64557.5, 2.877], [64558.6, 0.0], [64559.0, 1.029], [64559.4, 0.021], [64561.5, 0.035], [64562.5, 0.598], [64562.7, 0.927], [64563.6, 0.012], [64564.3, 0.002], [64566.9, 0.092], [64569.4, 0.012], [64569.6, 1.574], [64569.7, 0.0], [64569.9, 0.005], [64570.0, 0.02], [64570.2, 1.798], [64570.3, 0.063], [64570.4, 0.0], [64570.7, 0.014], [64571.2, 0.127], [64571.6, 0.077], [64571.9, 0.001], [64572.1, 0.048], [64572.3, 0.004], [64572.4, 0.008], [64572.8, 1.841], [64572.9, 0.004], [64576.2, 8.397]], "asks": [[64576.3, 29.432], [64576.6, 0.014], [64580.2, 0.097], [64580.4, 2.405], [64580.5, 0.792], [64580.6, 44.422], [64591.8, 1.24], [64593.3, 0.014], [64593.8, 0.588], [64593.9, 31.484], [64594.9, 0.927], [64595.0, 0.001], [64595.1, 0.002], [64608.1, 2.358], [64635.4, 0.01], [64635.6, 0.0], [65222.1, 3.053], [65581.6, 8.635]]}
{"kind": "depth", "E": 1787088863471, "U": 11315947616414, "u": 11315947620727, "recv_ms": 1787088863429, "bids": [[1000.0, 35.76], [14276.2, 1.834], [14376.2, 2.366], [58118.5, 0.002], [61993.1, 0.003], [63696.0, 0.001], [63773.3, 21.672], [63930.4, 0.0], [64208.5, 0.095], [64211.2, 0.448], [64305.0, 0.155], [64306.0, 0.488], [64375.8, 0.0], [64377.2, 0.634], [64468.9, 0.022], [64470.4, 0.0], [64478.9, 0.0], [64486.5, 28.987], [64488.7, 0.0], [64492.6, 0.005], [64530.9, 0.136], [64532.2, 0.038], [64534.8, 0.032], [64551.5, 0.483], [64559.1, 0.009], [64560.3, 0.106], [64561.6, 0.012], [64562.1, 0.931], [64562.7, 0.0], [64562.8, 0.0], [64563.2, 1.548], [64563.6, 0.097], [64565.3, 0.314], [64566.6, 0.151], [64569.4, 0.012], [64570.0, 0.02], [64570.2, 0.553], [64570.3, 0.063], [64570.5, 0.185], [64571.3, 0.087], [64572.0, 0.304], [64572.8, 1.0], [64573.4, 0.0]], "asks": [[64576.3, 29.47], [64579.3, 0.005], [64579.7, 0.019], [64580.1, 0.058], [64580.4, 2.397], [64580.5, 0.784], [64581.2, 0.012], [64589.9, 0.033], [64591.6, 0.004], [64595.7, 0.879], [64655.2, 0.018], [64774.6, 2.338], [64774.7, 4.509], [64845.2, 0.146], [64845.9, 0.024], [64941.5, 1.268], [64943.2, 0.0], [65222.1, 3.051], [65319.6, 2.727], [65323.9, 4.716], [65324.0, 7.403], [65384.1, 2.271], [65388.6, 5.424], [65646.3, 3.662]]}
{"kind": "depth", "E": 1787088863573, "U": 11315947620819, "u": 11315947626545, "recv_ms": 1787088863531, "bids": [[14276.2, 2.198], [14376.2, 2.002], [58118.5, 0.002], [61347.3, 0.001], [61993.1, 0.0], [63348.8, 0.315], [63547.3, 1.54], [63576.2, 0.051], [63644.2, 30.056], [63812.1, 5.595], [63930.4, 0.0], [63945.5, 0.003], [64092.9, 0.018], [64253.3, 0.403], [64544.1, 0.034], [64544.8, 0.068], [64545.0, 0.289], [64546.1, 0.064], [64547.3, 0.0], [64556.4, 0.559], [64557.5, 2.319], [64559.1, 0.009], [64560.3, 0.106], [64560.7, 0.929], [64561.5, 0.035], [64562.1, 0.004], [64562.6, 0.543], [64563.5, 0.087], [64563.6, 0.012], [64569.4, 0.012], [64569.7, 0.0], [64570.0, 0.02], [64570.3, 0.063], [64571.0, 0.003], [64571.2, 0.13], [64571.3, 0.084], [64572.1, 0.048], [64572.9, 0.002], [64573.8, 0.002], [64576.2, 8.171]], "asks": [[64576.3, 29.47], [64579.3, 0.002], [64579.7, 0.029], [64580.4, 2.397], [64580.6, 44.425], [64589.9, 0.033], [64591.6, 0.004], [64592.0, 0.258], [64593.0, 0.545], [64593.1, 0.969], [64593.8, 0.046], [64594.9, 0.0], [64596.7, 0.592], [64597.8, 0.511], [64598.0, 0.138], [64598.8, 0.037], [64599.9, 0.628], [64600.1, 0.628], [64635.2, 0.01], [64635.4, 0.0], [64774.6, 2.122], [64787.6, 0.216], [64899.2, 0.001], [65060.1, 0.055], [65209.7, 0.051], [65222.1, 3.051], [65319.6, 4.545], [65323.9, 3.8], [65324.0, 6.487], [65383.5, 0.228], [65484.8, 48.041], [65491.9, 2.286], [65576.3, 0.024]]}
{"kind": "depth", "E": 1787088863675, "U": 11315947626561, "u": 11315947631625, "recv_ms": 1787088863628, "bids": [[1000.0, 35.76], [14276.2, 2.548], [14376.2, 1.652], [51661.0, 0.0], [58118.5, 0.002], [58118.6, 0.002], [61347.3, 0.001], [61993.1, 0.003], [63183.6, 0.002], [63187.7, 0.0], [63704.4, 1.206], [63930.4, 0.0], [64012.6, 38.211], [64204.6, 43.897], [64253.3, 0.413], [64257.6, 6.654], [64301.1, 34.454], [64371.9, 27.418], [64486.5, 0.106], [64488.7, 28.881], [64540.3, 0.0], [64558.0, 0.036], [64559.1, 0.008], [64559.8, 0.311], [64560.3, 0.106], [64561.2, 0.159], [64562.5, 0.444], [64563.2, 1.547], [64563.5, 0.087], [64569.2, 0.052], [64569.4, 0.01], [64569.6, 0.01], [64570.3, 1.963], [64571.9, 0.001], [64572.1, 1.612], [64572.2, 0.009], [64572.5, 0.001], [64572.7, 0.001], [64572.8, 1.386], [64572.9, 0.002], [64573.1, 0.002], [64575.9, 0.002], [64576.2, 6.39]], "asks": [[64576.3, 29.477], [64577.3, 0.004], [64577.4, 0.0], [64577.5, 0.019], [64577.9, 0.01], [64579.0, 0.015], [64579.7, 0.021], [64580.2, 0.097], [64580.3, 0.936], [64589.9, 0.033], [64591.5, 0.001], [64605.1, 0.313], [64608.1, 2.206], [64608.2, 5.453], [64609.0, 0.019], [64609.3, 0.001], [64611.1, 0.002], [64612.3, 0.0], [64613.2, 0.028], [64615.3, 0.001], [64627.9, 0.002], [64695.1, 0.003], [64770.7, 28.615], [64841.9, 32.632], [64893.4, 0.002], [64939.2, 40.794], [65222.1, 3.051], [65355.7, 50.776], [65384.1, 3.785], [65388.6, 3.896]]}
{"kind": "depth", "E": 1787088863777, "U": 11315947631739, "u": 11315947639023, "recv_ms": 1787088863725, "bids": [[1000.0, 35.76], [14276.2, 2.912], [14376.2, 1.288], [51661.0, 0.0], [58118.5, 0.002], [58118.6, 0.0], [63576.2, 0.031], [63639.8, 1.098], [63678.6, 0.913], [63807.7, 2.035], [63930.4, 0.0], [63950.1, 0.0], [64204.3, 0.003], [64204.7, 6.701], [64302.7, 5.969], [64317.2, 0.002], [64356.6, 0.0], [64396.0, 0.068], [64435.4, 0.212], [64474.8, 0.024], [64514.2, 0.036], [64518.0, 0.254], [64520.0, 9.46], [64530.9, 0.133], [64544.6, 0.132], [64544.8, 0.058], [64558.0, 0.028], [64559.1, 0.008], [64560.3, 0.098], [64563.2, 1.548], [64563.5, 0.644], [64563.6, 0.028], [64567.5, 0.242], [64569.1, 0.042], [64569.2, 0.05], [64569.4, 0.01], [64569.6, 2.142], [64569.9, 0.005], [64570.2, 0.004], [64570.3, 0.001], [64570.4, 0.0], [64570.5, 0.247], [64570.6, 2.164], [64571.8, 0.168], [64572.1, 0.048], [64572.2, 0.009], [64572.3, 0.004], [64572.4, 0.008], [64572.8, 0.725], [64572.9, 0.002], [64573.3, 0.007]], "asks": [[64579.7, 0.021], [64580.3, 0.936], [64589.9, 0.033], [64590.6, 0.005], [64591.5, 0.001], [64632.8, 4.728], [64635.0, 0.112], [64635.2, 0.0], [64635.9, 0.119], [64655.2, 0.015], [64666.4, 0.023], [64705.8, 0.004], [64745.2, 0.002], [64768.4, 4.604], [64784.6, 0.0], [64824.0, 0.001], [64841.7, 5.083], [64863.4, 0.155], [64883.0, 0.593], [64938.5, 10.145], [65222.1, 3.05], [65319.6, 6.363], [65324.0, 4.654], [65384.1, 4.542], [65388.6, 3.132], [65401.4, 3.023], [65478.3, 4.884], [65530.5, 8.998], [65576.3, 0.004], [65646.2, 3.195]]}
{"kind": "depth", "E": 1787088863879, "U": 11315947639115, "u": 11315947645946, "recv_ms": 1787088863834, "bids": [[14276.2, 3.262], [14376.2, 0.938], [58118.5, 0.002], [61347.3, 0.001], [61993.1, 0.0], [62979.0, 0.042], [63284.7, 0.01], [63288.9, 4.429], [63543.0, 1.103], [63930.4, 0.0], [63998.2, 0.028], [64002.5, 0.0], [64089.0, 54.627], [64158.2, 0.012], [64162.5, 0.0], [64318.6, 0.004], [64322.9, 0.0], [64381.0, 3.298], [64409.4, 0.002], [64452.6, 0.0], [64453.2, 0.0], [64468.9, 0.022], [64479.4, 2.785], [64483.7, 1.087], [64488.7, 28.976], [64514.2, 0.036], [64539.2, 1.884], [64544.1, 0.015], [64544.5, 0.01], [64544.6, 0.122], [64551.5, 0.329], [64557.9, 0.003], [64559.1, 0.008], [64559.2, 0.0], [64560.3, 0.098], [64560.8, 0.004], [64561.6, 0.005], [64562.6, 0.001], [64563.0, 2.328], [64563.1, 0.561], [64563.5, 0.645], [64563.6, 0.012], [64564.1, 0.008], [64564.4, 0.168], [64565.5, 0.008], [64567.9, 0.041], [64568.3, 0.018], [64569.0, 0.001], [64569.1, 0.04], [64569.4, 1.224], [64569.5, 0.001], [64569.6, 0.01], [64569.9, 0.581], [64570.0, 0.02], [64570.2, 0.007], [64570.3, 0.001], [64570.5, 0.185], [64570.6, 0.004], [64570.7, 0.014], [64570.9, 0.087], [64571.0, 0.003], [64571.1, 0.015], [64571.2, 0.13], [64572.0, 0.614], [64572.1, 0.132], [64572.4, 0.0], [64572.5, 0.001], [64572.6, 0.101], [64572.7, 0.0], [64572.8, 0.56], [64572.9, 1.55], [64573.0, 2.162], [64573.1, 0.086], [64573.6, 0.002], [64574.0, 0.299], [64576.1, 0.003], [64576.2, 6.729]], "asks": [[64576.3, 29.616], [64578.3, 0.009], [64578.4, 0.313], [64579.0, 0.015], [64579.7, 0.013], [64580.2, 0.105], [64580.3, 0.936], [64580.5, 0.784], [64580.6, 44.419], [64589.9, 0.025], [64591.2, 0.211], [64591.5, 0.009], [64593.1, 0.042], [64593.8, 0.973], [64594.3, 10.508], [64595.7, 0.932], [64596.3, 0.941], [64596.7, 0.035], [64597.7, 0.557], [64598.0, 0.022], [64598.1, 0.128], [64599.0, 0.223], [64599.1, 1.393], [64599.3, 0.001], [64599.9, 0.635], [64600.7, 0.034], [64634.9, 0.013], [64635.0, 0.102], [64651.3, 0.004], [64652.9, 0.618], [64653.5, 45.283], [64662.3, 0.0], [64673.1, 0.002], [64677.4, 5.865], [64693.2, 0.085], [64768.3, 0.445], [64770.6, 0.217], [64787.6, 0.0], [64834.8, 0.006], [64839.1, 0.715], [64996.9, 0.011], [65001.2, 0.001], [65056.1, 52.67], [65159.4, 0.032], [65163.7, 0.0], [65222.1, 3.05], [65369.1, 27.009], [65601.8, 1.304], [70507.9, 0.002]]}
{"kind": "depth", "E": 1787088863981, "U": 11315947645984, "u": 11315947652147, "recv_ms": 1787088863931, "bids": [[1000.0, 35.76], [14276.2, 3.612], [14376.2, 0.588], [58118.5, 0.002], [61347.3, 0.001], [61351.6, 2.451], [61993.1, 0.003], [63488.7, 4.771], [63576.2, 0.051], [63769.0, 0.367], [63930.4, 0.0], [63995.0, 2.569], [64222.3, 0.001], [64227.6, 0.493], [64253.3, 0.404], [64257.6, 6.664], [64514.2, 0.036], [64551.5, 0.483], [64557.9, 0.003], [64559.1, 0.008], [64560.8, 0.546], [64561.4, 0.011], [64563.0, 2.321], [64563.1, 0.019], [64563.5, 0.002], [64563.6, 0.012], [64564.0, 0.063], [64564.1, 0.0], [64565.0, 1.55], [64567.7, 0.007], [64567.9, 2.057], [64568.1, 0.55], [64568.3, 0.016], [64568.5, 1.923], [64569.3, 1.123], [64569.4, 1.162], [64569.9, 1.157], [64570.0, 0.02], [64570.2, 1.221], [64570.9, 0.086], [64571.1, 0.008], [64572.0, 0.304], [64572.1, 2.292], [64572.8, 0.387], [64572.9, 0.312], [64573.0, 0.002], [64573.1, 0.086], [64573.2, 0.005], [64573.4, 0.084], [64573.8, 0.002], [64574.0, 0.117], [64574.4, 0.089], [64575.9, 0.003], [64576.2, 7.753]], "asks": [[64576.3, 29.608], [64579.0, 0.005], [64579.7, 0.003], [64589.9, 0.025], [64591.4, 0.008], [64591.5, 0.001], [64595.7, 1.003], [64651.3, 0.004], [64653.5, 45.283], [64660.1, 0.013], [64768.3, 0.001], [64775.6, 0.005], [64775.7, 0.028], [64899.2, 0.0], [65222.1, 3.05], [65319.6, 7.272], [65324.0, 3.745], [65351.2, 1.528], [65387.9, 6.341], [65576.3, 0.024]]}
{"kind": "depth", "E": 1787088864083, "U": 11315947652346, "u": 11315947658385, "recv_ms": 1787088864031, "bids": [[1000.0, 35.76], [14176.2, 0.112], [14276.2, 3.752], [14376.2, 0.336], [58118.5, 0.002], [61347.3, 0.001], [61993.1, 0.0], [63037.0, 0.679], [63288.9, 4.426], [63930.4, 0.0], [64468.9, 28.998], [64488.7, 0.0], [64514.2, 0.036], [64532.2, 0.038], [64544.4, 0.011], [64544.5, 0.0], [64545.6, 0.621], [64552.9, 0.693], [64558.0, 0.028], [64559.1, 0.016], [64560.3, 0.106], [64560.8, 0.004], [64563.5, 0.087], [64563.6, 0.554], [64563.7, 0.0], [64564.3, 0.002], [64564.6, 0.465], [64565.0, 0.002], [64567.7, 0.005], [64567.9, 1.581], [64568.1, 0.008], [64568.2, 0.033], [64568.5, 0.034], [64568.6, 0.002], [64569.2, 0.052], [64569.4, 1.162], [64569.8, 0.231], [64569.9, 0.005], [64570.2, 0.004], [64570.3, 0.001], [64570.4, 0.0], [64570.5, 0.185], [64570.6, 0.631], [64572.1, 0.126], [64572.2, 0.009], [64572.7, 0.084], [64572.8, 0.571], [64572.9, 0.002], [64573.1, 0.002], [64573.4, 0.0], [64574.0, 0.052], [64574.4, 0.005], [64575.1, 0.093]], "asks": [[64576.3, 29.608], [64576.7, 0.086], [64589.9, 0.033], [64590.4, 0.046], [64591.4, 0.0], [64597.8, 0.454], [64598.7, 0.063], [64599.2, 0.646], [64605.2, 0.172], [64605.3, 0.024], [64606.5, 0.883], [64608.2, 5.297], [64608.3, 0.0], [64609.1, 0.0], [64609.2, 0.0], [64611.2, 0.02], [64611.3, 0.001], [64634.8, 0.01], [64634.9, 0.003], [64651.3, 45.287], [64653.5, 0.0], [65222.1, 3.05], [65226.9, 1.013], [65311.6, 2.295]]}
{"kind": "depth", "E": 1787088864185, "U": 11315947658558, "u": 11315947665023, "recv_ms": 1787088864133, "bids": [[14176.2, 0.336], [14276.2, 3.654], [14376.2, 0.21], [51661.0, 0.0], [58118.5, 0.002], [61347.3, 0.001], [61993.1, 0.003], [63576.2, 0.031], [63708.8, 20.92], [63773.3, 21.407], [63930.4, 0.0], [64253.3, 0.404], [64257.6, 6.654], [64373.3, 4.556], [64408.6, 0.001], [64416.0, 1.794], [64468.9, 0.022], [64488.1, 2.621], [64488.7, 28.976], [64490.6, 0.001], [64494.9, 0.008], [64497.6, 0.001], [64504.7, 0.034], [64514.2, 0.036], [64524.6, 0.253], [64527.6, 0.005], [64528.7, 2.321], [64530.9, 0.136], [64532.8, 0.003], [64544.3, 0.028], [64544.4, 0.001], [64545.7, 0.696], [64560.3, 0.106], [64563.5, 0.079], [64567.8, 1.07], [64567.9, 1.581], [64568.1, 0.023], [64569.2, 0.052], [64569.3, 1.123], [64569.4, 1.162], [64569.5, 0.001], [64569.6, 0.01], [64570.2, 0.007], [64570.3, 0.001], [64570.4, 2.16], [64570.6, 0.624], [64572.8, 0.399], [64573.1, 0.086], [64576.1, 0.014], [64576.2, 7.769]], "asks": [[64576.3, 29.609], [64577.7, 0.12], [64582.0, 0.109], [64583.7, 0.004], [64594.3, 0.508], [64597.4, 10.04], [64599.0, 2.297], [64599.8, 0.004], [64608.0, 0.215], [64608.1, 2.36], [64634.7, 0.011], [64634.8, 0.0], [64651.3, 45.287], [64653.8, 0.005], [64659.8, 0.892], [64660.1, 0.013], [64726.8, 2.294], [64880.9, 0.18], [64925.9, 0.024], [65222.1, 3.052], [65388.0, 28.246], [65576.3, 0.004]]}
{"kind": "depth", "E": 1787088864287, "U": 11315947665043, "u": 11315947671871, "recv_ms": 1787088864235, "bids": [[1000.0, 35.76], [14176.2, 0.588], [14276.2, 3.514], [14376.2, 0.098], [51661.0, 0.0], [58118.5, 0.002], [61347.3, 0.001], [61351.6, 2.449], [63284.7, 0.013], [63704.4, 1.989], [63769.0, 0.601], [63930.4, 0.0], [64480.6, 0.67], [64494.9, 0.009], [64514.2, 0.036], [64544.2, 0.46], [64544.3, 0.018], [64545.6, 0.002], [64552.9, 0.074], [64559.1, 0.016], [64560.3, 0.106], [64561.4, 0.004], [64561.6, 0.012], [64562.7, 0.0], [64563.5, 0.087], [64563.7, 0.0], [64567.9, 0.033], [64568.1, 0.008], [64568.2, 0.033], [64568.3, 0.016], [64569.2, 0.05], [64569.4, 0.094], [64569.5, 0.003], [64569.6, 1.566], [64569.9, 0.005], [64570.2, 0.583], [64570.3, 0.558], [64570.4, 0.0], [64570.6, 0.004], [64570.7, 0.014], [64570.8, 0.068], [64571.1, 0.011], [64571.2, 0.127], [64572.0, 0.304], [64572.2, 0.009], [64572.3, 0.004], [64572.4, 0.008], [64572.5, 0.001], [64572.7, 0.0], [64572.8, 1.321], [64573.1, 0.002], [64574.0, 0.008], [64574.2, 0.053], [64575.1, 0.087], [64576.1, 0.133], [64576.2, 7.761]], "asks": [[64576.3, 29.619], [64576.9, 0.002], [64578.3, 0.019], [64579.7, 0.013], [64580.0, 8.036], [64580.6, 44.408], [64589.9, 0.033], [64591.6, 0.004], [64599.2, 0.027], [64606.5, 0.264], [64608.1, 2.206], [64608.2, 5.451], [64634.6, 0.01], [64634.7, 0.001], [64672.2, 0.097], [64964.6, 3.075], [65213.5, 1.022], [65222.1, 3.05], [65349.7, 0.0], [65388.0, 27.986]]}
{"kind": "depth", "E": 1787088864389, "U": 11315947672219, "u": 11315947676977, "recv_ms": 1787088864337, "bids": [[1000.0, 35.76], [14176.2, 0.84], [14276.2, 3.36], [14376.2, 0.0], [58118.5, 0.002], [61993.1, 0.0], [63576.2, 0.051], [63617.9, 2.355], [63659.3, 0.234], [63930.4, 0.0], [64452.3, 0.124], [64452.9, 0.092], [64492.6, 0.002], [64500.0, 21.932], [64504.1, 0.031], [64559.1, 0.008], [64559.4, 0.021], [64560.3, 0.106], [64560.7, 0.002], [64561.1, 0.93], [64562.1, 0.004], [64563.1, 0.561], [64563.5, 0.644], [64563.6, 0.012], [64563.7, 0.0], [64563.8, 0.0], [64567.9, 0.033], [64569.2, 0.05], [64569.3, 1.125], [64569.4, 2.413], [64569.5, 0.001], [64569.6, 0.01], [64569.9, 0.581], [64570.2, 0.007], [64570.3, 0.001], [64570.4, 0.0], [64570.6, 0.004], [64570.7, 0.014], [64572.4, 0.318], [64572.5, 0.085], [64572.8, 0.656], [64572.9, 2.178], [64573.0, 1.55], [64576.1, 0.339]], "asks": [[64580.0, 8.033], [64589.9, 0.025], [64591.6, 0.012], [64591.8, 1.24], [64591.9, 2.321], [64593.5, 0.927], [64593.8, 0.046], [64594.4, 0.0], [64608.2, 5.297], [65097.3, 2.178], [65222.1, 3.05], [65576.3, 0.024], [71034.0, 0.0]]}
{"kind": "depth", "E": 1787088864491, "U": 11315947677050, "u": 11315947682663, "recv_ms": 1787088864438, "bids": [[14176.2, 1.204], [14276.2, 2.996], [58118.5, 0.002], [61347.3, 0.001], [61993.1, 0.003], [63576.2, 0.031], [63930.4, 0.0], [63942.0, 66.582], [64116.0, 0.313], [64253.3, 0.403], [64468.9, 0.022], [64486.5, 29.082], [64488.7, 0.0], [64543.2, 0.021], [64546.8, 0.007], [64548.3, 2.731], [64549.1, 0.006], [64556.4, 0.001], [64556.9, 0.004], [64557.0, 0.577], [64558.1, 0.233], [64559.1, 0.016], [64559.2, 0.0], [64560.3, 0.106], [64563.5, 0.087], [64563.6, 0.012], [64564.5, 0.061], [64565.2, 0.36], [64565.3, 0.004], [64566.3, 0.002], [64566.5, 2.32], [64569.0, 0.085], [64569.3, 1.124], [64569.4, 3.565], [64569.5, 1.153], [64569.8, 0.231], [64569.9, 0.005], [64570.0, 0.02], [64570.1, 0.715], [64570.2, 1.552], [64570.3, 1.142], [64570.4, 0.0], [64570.6, 0.004], [64570.7, 0.014], [64572.0, 0.614], [64572.1, 2.202], [64572.2, 0.009], [64572.4, 0.008], [64572.5, 0.085], [64572.8, 0.656], [64572.9, 0.086], [64573.0, 0.002], [64573.3, 0.007], [64576.1, 0.133], [64576.2, 7.986]], "asks": [[64576.3, 28.725], [64576.4, 0.177], [64577.5, 0.0], [64577.6, 0.001], [64577.7, 0.098], [64577.8, 0.002], [64578.0, 0.044], [64578.3, 0.006], [64579.0, 0.01], [64579.2, 0.018], [64579.5, 0.004], [64579.7, 0.003], [64580.4, 2.397], [64583.2, 0.003], [64584.5, 0.312], [64585.2, 0.185], [64589.9, 0.025], [64590.7, 0.764], [64591.6, 0.012], [64591.7, 0.493], [64595.7, 1.127], [64597.2, 1.025], [64597.7, 0.0], [64598.5, 2.435], [64599.0, 2.181], [64608.1, 2.206], [64608.2, 5.451], [65204.8, 64.521], [65222.1, 3.05], [65331.8, 0.535], [65355.7, 50.318], [65576.3, 0.004], [70670.3, 0.002]]}
{"kind": "depth", "E": 1787088864593, "U": 11315947682792, "u": 11315947687219, "recv_ms": 1787088864541, "bids": [[1000.0, 35.76], [14176.2, 1.554], [14276.2, 2.646], [51661.0, 0.0], [58118.5, 0.002], [61993.1, 0.0], [63284.7, 0.016], [63805.6, 45.099], [63889.8, 0.007], [63930.4, 0.0], [64486.5, 0.106], [64488.7, 28.976], [64512.4, 0.018], [64514.2, 0.05], [64515.1, 1.169], [64535.0, 0.488], [64537.6, 0.01], [64539.2, 1.865], [64544.1, 0.025], [64544.2, 0.45], [64551.1, 0.002], [64563.2, 1.548], [64563.5, 0.087], [64569.3, 0.004], [64569.4, 2.413], [64569.5, 2.709], [64569.6, 2.515], [64570.1, 0.713], [64570.2, 0.066], [64570.3, 0.001], [64570.4, 0.0], [64570.8, 0.006], [64572.1, 0.042], [64572.2, 0.009], [64572.8, 0.656]], "asks": [[64576.3, 28.725], [64577.4, 0.002], [64579.0, 0.02], [64579.7, 0.013], [64580.7, 1.989], [64603.3, 0.017], [64608.2, 5.451], [64619.5, 0.003], [64634.5, 1.483], [64634.6, 0.0], [64640.3, 0.708], [64642.1, 0.018], [65092.9, 0.923], [65222.1, 3.05], [65349.2, 4.585]]}
{"kind": "depth", "E": 1787088864695, "U": 11315947687423, "u": 11315947692541, "recv_ms": 1787088864643, "bids": [[1000.0, 35.76], [14176.2, 1.918], [14276.2, 2.282], [51661.0, 0.0], [58118.5, 0.002], [61347.3, 0.001], [61993.1, 0.003], [62965.5, 2.3], [63930.4, 0.0], [64470.7, 0.012], [64479.3, 3.098], [64479.4, 1.475], [64505.3, 6.014], [64514.2, 0.036], [64527.9, 3.526], [64544.0, 1.037], [64555.1, 0.131], [64555.7, 2.307], [64556.4, 0.559], [64557.0, 0.019], [64560.3, 0.098], [64560.5, 0.0], [64560.6, 0.004], [64561.1, 0.003], [64561.2, 0.159], [64561.4, 0.931], [64561.6, 0.005], [64563.0, 2.328], [64563.1, 0.019], [64563.5, 0.544], [64567.8, 1.089], [64569.0, 0.001], [64569.3, 0.002], [64569.4, 2.329], [64569.5, 0.001], [64569.6, 3.659], [64570.0, 0.023], [64570.1, 0.715], [64570.2, 2.164], [64570.3, 0.732], [64571.3, 0.084], [64572.1, 0.019], [64572.8, 0.939], [64572.9, 2.246], [64573.0, 1.566], [64573.3, 0.091], [64573.5, 0.001], [64574.1, 0.007], [64574.2, 0.137]], "asks": [[64576.3, 28.732], [64579.5, 0.001], [64580.1, 0.058], [64591.7, 0.495], [64593.0, 0.003], [64593.3, 0.556], [64596.5, 1.313], [64597.2, 0.468], [64597.4, 10.597], [64598.2, 1.314], [64608.2, 5.451], [64614.4, 3.524], [64637.0, 6.037], [64676.8, 0.0], [64899.2, 0.001], [64958.4, 0.019], [65222.1, 3.05], [65480.4, 2.927]]}
{"kind": "depth", "E": 1787088864797, "U": 11315947692699, "u": 11315947697372, "recv_ms": 1787088864744, "bids": [[14176.2, 2.268], [14276.2, 1.932], [58118.5, 0.002], [63301.9, 1.893], [63478.5, 5.662], [63576.2, 0.051], [63872.3, 0.745], [63930.4, 0.0], [64253.3, 0.403], [64441.2, 0.095], [64527.7, 0.048], [64528.0, 1.751], [64563.6, 0.012], [64569.5, 0.001], [64569.6, 1.359], [64569.7, 0.0], [64570.1, 0.713], [64570.2, 0.004], [64570.3, 0.003], [64570.4, 1.548], [64570.5, 0.761], [64570.6, 0.701], [64572.1, 0.019], [64572.2, 0.032], [64572.8, 1.256], [64572.9, 0.086], [64573.0, 0.002], [64576.1, 0.161]], "asks": [[64576.3, 28.741], [64577.6, 0.003], [64579.0, 0.01], [64579.7, 0.003], [64580.6, 44.399], [64608.2, 5.297], [64693.2, 0.001], [64696.7, 0.0], [64711.6, 0.383], [65222.1, 3.05], [65344.8, 0.975], [65349.2, 3.668], [65351.2, 1.987], [65576.3, 0.024], [65679.1, 1.93]]}
{"kind": "depth", "E": 1787088864899, "U": 11315947697409, "u": 11315947702004, "recv_ms": 1787088864846, "bids": [[1000.0, 35.76], [14176.2, 2.632], [14276.2, 1.568], [58118.5, 0.002], [61993.1, 0.0], [63398.9, 0.001], [63801.3, 0.782], [63930.4, 0.0], [64470.7, 0.004], [64473.0, 10.017], [64473.1, 0.012], [64563.6, 0.105], [64569.5, 0.003], [64570.0, 0.023], [64570.3, 0.001], [64570.5, 2.345], [64570.6, 0.546], [64570.7, 0.099], [64572.2, 0.009], [64572.8, 0.656]], "asks": [[64579.9, 0.715], [64608.0, 0.369], [64669.3, 10.05], [65097.3, 1.871], [65222.1, 3.05], [65349.1, 4.585], [65426.9, 0.766], [65743.2, 2.768]]}
{"kind": "depth", "E": 1787088865001, "U": 11315947702125, "u": 11315947706784, "recv_ms": 1787088864946, "bids": [[1000.0, 35.76], [14176.2, 2.982], [14276.2, 1.218], [58118.5, 0.002], [61993.1, 0.003], [62960.6, 2.365], [63350.0, 33.822], [63576.2, 0.031], [63930.4, 0.0], [64227.6, 0.0], [64231.0, 0.5], [64253.3, 0.402], [64544.0, 1.047], [64544.1, 0.015], [64563.6, 0.105], [64569.5, 0.001], [64570.3, 0.003], [64570.5, 0.185], [64570.6, 0.004], [64570.7, 0.099], [64570.8, 0.548], [64572.8, 0.984], [64573.7, 0.086], [64574.2, 0.053]], "asks": [[64576.3, 28.741], [64593.2, 0.085], [64608.0, 0.215], [64899.2, 0.002], [65222.1, 3.05], [65319.6, 9.09], [65323.9, 2.883], [65324.0, 2.836], [65351.2, 2.201], [65384.1, 5.299], [65388.6, 2.368], [65576.3, 0.004], [65661.2, 0.617]]}
{"kind": "depth", "E": 1787088865103, "U": 11315947706946, "u": 11315947713205, "recv_ms": 1787088865051, "bids": [[14176.2, 3.346], [14276.2, 0.854], [58118.5, 0.002], [61347.3, 0.001], [61351.6, 2.447], [61993.1, 0.0], [63284.2, 0.32], [63672.1, 0.188], [63708.8, 20.294], [63801.3, 1.001], [63805.6, 44.88], [63837.8, 5.635], [63930.4, 0.0], [64253.3, 0.402], [64490.7, 0.002], [64498.7, 0.004], [64504.8, 0.003], [64518.0, 0.251], [64521.0, 0.382], [64530.9, 0.133], [64532.9, 0.004], [64560.3, 0.106], [64561.6, 0.012], [64563.0, 2.321], [64563.6, 0.012], [64563.7, 0.085], [64564.6, 0.465], [64569.5, 0.001], [64570.0, 0.023], [64570.3, 0.003], [64570.5, 0.192], [64570.6, 0.004], [64570.7, 0.572], [64570.8, 0.068], [64572.8, 0.918], [64573.3, 0.007], [64573.7, 0.002]], "asks": [[64578.0, 0.046], [64579.6, 0.003], [64608.1, 2.36], [64634.5, 1.486], [64635.9, 0.116], [64653.8, 0.002], [65092.9, 1.23], [65222.1, 3.05], [65480.4, 3.11]]}
{"kind": "depth", "E": 1787088865205, "U": 11315947713326, "u": 11315947719005, "recv_ms": 1787088865152, "bids": [[1000.0, 35.76], [14076.2, 0.014], [14176.2, 3.682], [14276.2, 0.504], [58118.5, 0.002], [61347.3, 0.001], [63381.5, 1.023], [63576.2, 0.051], [63769.0, 0.835], [63930.4, 0.0], [64377.2, 1.17], [64460.1, 29.505], [64470.3, 5.576], [64488.1, 0.002], [64488.7, 0.0], [64488.8, 7.544], [64497.6, 0.003], [64524.7, 0.022], [64527.7, 0.049], [64532.9, 0.005], [64545.5, 1.035], [64549.7, 2.129], [64551.5, 0.483], [64552.9, 0.693], [64563.6, 0.012], [64564.0, 0.067], [64567.2, 0.108], [64569.5, 0.001], [64569.7, 0.0], [64570.0, 0.022], [64570.3, 0.001], [64570.5, 0.727], [64570.6, 0.011], [64570.7, 0.014], [64570.8, 0.006], [64570.9, 0.086], [64571.0, 0.065], [64572.1, 0.019], [64572.2, 0.025], [64572.8, 1.157]], "asks": [[64576.3, 28.741], [64577.6, 0.027], [64580.6, 43.347], [64581.7, 0.015], [64581.9, 2.548], [64582.0, 0.098], [64583.7, 0.003], [64587.5, 0.181], [64593.0, 0.005], [64596.3, 2.161], [64596.5, 0.017], [64599.2, 0.646], [64600.1, 0.0], [64605.1, 0.311], [64605.8, 0.035], [64606.5, 0.883], [64608.1, 2.204], [64609.0, 0.017], [64611.1, 0.0], [64634.4, 0.014], [64634.5, 1.476], [64650.1, 7.84], [64668.8, 3.155], [65222.1, 4.865], [65319.6, 9.999], [65323.9, 1.966], [65349.2, 2.751], [65576.3, 0.024]]}
{"kind": "depth", "E": 1787088865307, "U": 11315947719052, "u": 11315947724010, "recv_ms": 1787088865256, "bids": [[1000.0, 35.76], [14076.2, 0.168], [14176.2, 3.724], [14276.2, 0.308], [51661.0, 0.0], [58118.5, 0.002], [61347.3, 0.001], [61351.6, 2.445], [61993.1, 0.003], [63288.9, 4.423], [63833.6, 0.939], [63930.4, 0.0], [64401.8, 0.097], [64460.1, 0.529], [64488.7, 29.159], [64488.8, 0.003], [64524.7, 0.023], [64545.5, 0.416], [64551.5, 0.483], [64552.9, 0.074], [64555.1, 0.015], [64555.8, 1.333], [64556.4, 0.001], [64557.1, 0.61], [64563.2, 1.548], [64563.6, 0.569], [64569.5, 0.579], [64569.7, 0.0], [64570.0, 0.02], [64570.4, 0.0], [64570.5, 0.185], [64570.6, 0.012], [64570.7, 0.014], [64570.8, 3.714], [64571.0, 0.068], [64571.1, 0.008], [64572.2, 0.009], [64572.8, 0.985], [64573.3, 0.091], [64573.7, 0.086], [64576.2, 7.987]], "asks": [[64576.3, 28.738], [64576.8, 0.007], [64577.9, 0.003], [64578.2, 0.002], [64579.7, 0.09], [64580.4, 2.32], [64583.2, 0.312], [64584.5, 0.003], [64591.7, 1.114], [64593.7, 0.03], [64599.2, 0.027], [64606.5, 0.264], [64608.0, 0.215], [64692.2, 0.087], [64692.8, 0.131], [64751.0, 0.094], [65222.1, 4.865], [65319.6, 11.817], [65323.9, 1.049], [65324.0, 1.919], [65351.2, 2.415], [65384.1, 6.813], [65388.6, 0.84], [65480.4, 3.293], [65497.7, 2.052]]}
{"kind": "depth", "E": 1787088865409, "U": 11315947724079, "u": 11315947728934, "recv_ms": 1787088865356, "bids": [[14076.2, 0.406], [14176.2, 3.612], [14276.2, 0.182], [51661.0, 0.0], [58118.5, 0.002], [61993.1, 0.0], [63576.2, 0.031], [63704.4, 2.615], [63930.4, 0.0], [64253.3, 0.412], [64559.4, 0.019], [64563.6, 0.012], [64569.5, 0.001], [64569.7, 0.0], [64570.0, 0.022], [64570.2, 0.004], [64570.3, 0.55], [64570.4, 0.0], [64570.8, 0.006], [64570.9, 0.086], [64571.0, 0.006], [64571.1, 0.008], [64571.2, 0.127], [64571.3, 1.702], [64572.8, 0.902], [64573.3, 0.007], [64573.7, 0.002], [64576.2, 7.761]], "asks": [[64579.0, 0.02], [64581.7, 0.014], [64591.8, 1.238], [64607.9, 0.0], [64608.0, 0.369], [65222.1, 4.865], [65355.7, 48.485], [65576.3, 0.004], [65867.8, 1.531]]}
{"kind": "depth", "E": 1787088865511, "U": 11315947728995, "u": 11315947733136, "recv_ms": 1787088865459, "bids": [[1000.0, 35.76], [14076.2, 0.644], [14176.2, 3.486], [14276.2, 0.07], [58118.5, 0.002], [61347.3, 0.001], [61993.1, 0.003], [63424.6, 3.172], [63482.7, 12.037], [63576.2, 0.051], [63930.4, 0.002], [64432.2, 0.014], [64433.3, 3.473], [64452.8, 0.116], [64452.9, 0.005], [64559.4, 0.021], [64563.2, 1.547], [64563.6, 0.569], [64569.5, 0.003], [64569.7, 1.548], [64570.0, 0.02], [64570.3, 0.001], [64570.4, 0.0], [64570.5, 0.185], [64570.6, 0.012], [64570.7, 0.014], [64571.3, 0.146], [64571.4, 0.0], [64572.8, 0.985], [64576.2, 7.987]], "asks": [[64576.3, 28.872], [64579.0, 0.01], [64579.7, 0.08], [64591.8, 1.24], [64593.7, 0.005], [64593.9, 31.51], [64602.3, 0.04], [64608.0, 0.369], [64713.6, 2.696], [64716.0, 5.408], [64720.1, 0.0], [64720.2, 0.0], [65222.1, 4.865], [65344.8, 1.892], [65355.7, 47.722], [65576.3, 0.024], [67809.6, 0.005]]}
{"kind": "depth", "E": 1787088865613, "U": 11315947733210, "u": 11315947737360, "recv_ms": 1787088865560, "bids": [[1000.0, 35.76], [14076.2, 0.924], [14176.2, 3.276], [14276.2, 0.0], [58118.5, 0.002], [61347.4, 0.002], [61993.1, 0.0], [62961.8, 0.519], [63471.3, 0.787], [63930.4, 0.0], [64533.2, 0.004], [64540.8, 0.007], [64560.3, 0.098], [64561.6, 0.005], [64562.7, 0.007], [64563.2, 1.548], [64563.6, 0.012], [64563.7, 0.0], [64565.2, 0.05], [64566.5, 2.63], [64569.7, 2.7], [64570.2, 1.721], [64570.3, 0.094], [64570.6, 0.004], [64571.0, 0.003], [64571.9, 0.004], [64572.1, 2.179], [64573.8, 0.086]], "asks": [[64576.8, 0.0], [64578.1, 0.007], [64578.7, 0.003], [64579.7, 0.003], [64580.4, 2.397], [64583.2, 0.003], [64584.5, 0.312], [64591.7, 0.495], [64593.8, 0.665], [64608.0, 0.215], [64608.1, 2.358], [65222.1, 4.865], [65319.6, 13.635], [65323.9, 0.132], [65324.0, 1.01], [65351.2, 4.248], [65512.7, 0.154]]}
{"kind": "depth", "E": 1787088865715, "U": 11315947737538, "u": 11315947742334, "recv_ms": 1787088865662, "bids": [[14076.2, 1.288], [14176.2, 2.912], [51661.0, 0.0], [58118.5, 0.002], [61347.3, 0.001], [63773.3, 21.056], [63930.4, 0.0], [64253.3, 0.403], [64468.9, 0.022], [64486.5, 29.265], [64488.7, 0.0], [64521.0, 0.354], [64560.3, 0.106], [64561.5, 0.042], [64562.7, 0.0], [64563.6, 0.097], [64565.2, 0.36], [64566.5, 2.32], [64569.5, 0.579], [64569.7, 0.008], [64569.8, 0.231], [64570.1, 0.713], [64570.2, 1.552], [64570.3, 0.558], [64570.4, 2.16], [64570.5, 0.247], [64571.0, 0.006], [64571.3, 0.084], [64571.5, 0.004], [64571.9, 0.001], [64572.1, 0.103], [64572.2, 0.009], [64572.3, 0.004], [64572.8, 1.0], [64572.9, 0.002], [64573.8, 0.002], [64576.1, 0.123], [64576.2, 7.763]], "asks": [[64576.3, 28.872], [64579.0, 0.02], [64579.7, 0.09], [64580.4, 2.32], [64580.7, 1.821], [64604.9, 0.0], [64608.0, 0.369], [64608.1, 2.204], [64651.2, 0.002], [64899.2, 0.001], [65222.1, 4.865], [65319.6, 14.544], [65324.0, 0.101], [65351.2, 5.011], [65588.1, 0.658], [66513.4, 0.003]]}
{"kind": "depth", "E": 1787088865817, "U": 11315947742382, "u": 11315947746840, "recv_ms": 1787088865764, "bids": [[1000.0, 35.76], [14076.2, 1.652], [14176.2, 2.548], [51661.0, 0.0], [58118.5, 0.002], [61993.1, 0.003], [63478.5, 6.054], [63576.2, 0.031], [63930.4, 0.0], [64486.5, 0.106], [64488.7, 29.159], [64569.5, 0.003], [64570.1, 0.713], [64570.4, 0.0], [64570.5, 0.185], [64570.6, 0.066], [64572.9, 0.086], [64573.0, 0.0], [64573.3, 0.091], [64576.2, 7.767]], "asks": [[64576.3, 29.283], [64577.2, 0.0], [64577.6, 0.07], [64579.8, 0.001], [64579.9, 1.579], [64580.2, 0.105], [64582.2, 0.666], [64588.0, 0.383], [64596.0, 0.692], [64596.5, 0.101], [64602.3, 0.473], [64608.0, 0.215], [64608.1, 2.204], [64608.2, 5.451], [65222.1, 3.05], [65298.0, 9.584], [65383.5, 0.487], [65384.1, 7.57], [65388.5, 0.0], [65576.3, 0.004], [65581.7, 19.335]]}
{"kind": "depth", "E": 1787088865919, "U": 11315947746874, "u": 11315947751290, "recv_ms": 1787088865866, "bids": [[14076.2, 2.002], [14176.2, 2.198], [58118.5, 0.002], [61993.1, 0.0], [63019.8, 0.68], [63488.7, 3.984], [63769.0, 1.1], [63773.3, 20.705], [63851.1, 4.066], [63930.4, 0.0], [64231.0, 0.007], [64233.0, 1.825], [64504.1, 0.028], [64515.4, 0.013], [64567.2, 0.218], [64571.6, 0.001], [64572.8, 0.656]], "asks": [[64579.7, 0.089], [64579.9, 0.715], [65222.1, 3.05], [65383.5, 0.715], [65384.1, 8.327], [65388.0, 27.643], [65388.6, 0.076], [65543.4, 5.405]]}
{"kind": "depth", "E": 1787088866021, "U": 11315947751451, "u": 11315947755951, "recv_ms": 1787088865968, "bids": [[14076.2, 2.366], [14176.2, 1.834], [58118.5, 0.002], [61347.3, 0.001], [61993.1, 0.003], [63288.9, 4.42], [63576.2, 0.051], [63779.4, 3.137], [63930.4, 0.0], [64253.3, 0.403], [64362.4, 0.165], [64433.3, 0.147], [64433.4, 2.866], [64435.1, 0.94], [64460.1, 29.725], [64488.7, 0.0], [64560.3, 0.098], [64563.2, 1.548], [64563.6, 0.012], [64569.5, 0.579], [64569.8, 0.147], [64570.0, 0.023], [64570.1, 0.713], [64570.2, 1.552], [64570.3, 1.71], [64570.4, 0.093], [64571.0, 0.003], [64571.9, 0.004], [64572.1, 2.263], [64572.8, 0.988], [64574.1, 0.091]], "asks": [[64576.3, 29.329], [64578.3, 0.007], [64579.0, 0.01], [64579.7, 0.002], [64580.4, 2.397], [64580.6, 43.303], [64580.7, 1.814], [64608.2, 5.297], [64608.3, 0.154], [64642.5, 0.051], [64689.0, 0.002], [64716.0, 5.408], [64735.6, 0.002], [64790.4, 0.487], [64899.2, 0.0], [65222.1, 3.05], [65576.3, 0.024]]}
{"kind": "depth", "E": 1787088866123, "U": 11315947756017, "u": 11315947760158, "recv_ms": 1787088866081, "bids": [[1000.0, 35.76], [14076.2, 2.716], [14176.2, 1.484], [51661.0, 0.0], [58118.5, 0.002], [61347.3, 0.001], [61993.1, 0.0], [63576.2, 0.031], [63833.6, 1.877], [63930.4, 0.0], [63967.3, 0.0], [64253.3, 0.404], [64460.1, 0.529], [64486.5, 29.302], [64487.3, 7.148], [64497.8, 0.001], [64504.8, 0.004], [64527.7, 0.05], [64533.0, 0.003], [64540.6, 1.867], [64556.9, 0.562], [64557.1, 0.052], [64557.8, 0.033], [64560.3, 0.098], [64561.0, 0.94], [64561.4, 0.004], [64563.1, 0.561], [64563.2, 1.547], [64563.5, 0.002], [64563.6, 0.012], [64564.6, 0.465], [64569.5, 0.003], [64569.7, 2.132], [64569.8, 0.209], [64570.0, 0.02], [64570.2, 0.292], [64570.3, 0.574], [64570.4, 0.077], [64570.6, 0.004], [64571.1, 0.011], [64571.9, 0.001], [64572.1, 1.183], [64572.2, 0.009], [64572.3, 0.004], [64572.6, 0.101], [64572.8, 0.656], [64572.9, 0.086], [64573.3, 0.007], [64573.7, 0.002], [64573.9, 0.352], [64574.1, 0.007], [64576.1, 0.123]], "asks": [[64576.3, 29.329], [64577.4, 0.0], [64579.1, 0.094], [64579.3, 0.004], [64579.8, 0.011], [64581.7, 0.015], [64593.5, 0.0], [64594.2, 1.017], [64594.4, 0.0], [64597.4, 10.04], [64598.0, 0.579], [64598.5, 2.319], [64598.9, 0.34], [64599.3, 0.124], [64599.9, 0.628], [64611.9, 1.03], [64656.8, 1.923], [64676.2, 3.505], [65222.1, 3.05], [65576.3, 0.004], [65577.2, 1.066]]}
{"kind": "depth", "E": 1787088866225, "U": 11315947760224, "u": 11315947765025, "recv_ms": 1787088866171, "bids": [[14076.2, 3.066], [14176.2, 1.134], [51661.0, 0.0], [58118.5, 0.002], [61347.3, 0.001], [63600.4, 0.787], [63708.8, 19.668], [63930.4, 0.0], [64524.8, 2.622], [64530.9, 0.136], [64545.5, 1.035], [64547.7, 1.242], [64552.9, 0.693], [64556.5, 0.037], [64560.3, 0.106], [64563.2, 1.548], [64563.5, 0.087], [64569.7, 2.132], [64569.8, 0.231], [64569.9, 0.067], [64570.2, 0.004], [64570.3, 0.558], [64570.4, 2.16], [64572.0, 0.304], [64572.1, 0.103], [64572.2, 0.009], [64572.8, 0.955], [64572.9, 0.002], [64573.9, 0.268], [64576.1, 0.014]], "asks": [[64576.3, 29.33], [64579.1, 0.084], [64579.8, 0.001], [64580.6, 43.302], [64580.7, 1.807], [64593.3, 1.483], [64594.2, 0.09], [64599.2, 0.646], [64600.2, 0.258], [64606.5, 0.883], [64607.5, 0.006], [64608.3, 0.154], [64653.8, 0.005], [65222.1, 3.05], [65222.7, 0.379], [65227.2, 0.025], [65525.6, 1.41], [65867.8, 1.534]]}
{"kind": "depth", "E": 1787088866327, "U": 11315947765238, "u": 11315947769642, "recv_ms": 1787088866273, "bids": [[14076.2, 3.43], [14176.2, 0.77], [51661.0, 0.0], [58118.5, 0.002], [61351.6, 2.443], [61993.1, 0.003], [63930.4, 0.0], [64253.3, 0.404], [64374.0, 0.06], [64498.7, 0.001], [64530.9, 0.136], [64555.6, 0.118], [64555.8, 1.217], [64569.5, 0.003], [64569.7, 0.008], [64569.9, 0.005], [64570.2, 0.004], [64570.4, 1.548], [64570.5, 0.185], [64570.6, 0.066], [64571.0, 0.006], [64571.1, 0.008], [64572.8, 0.94], [64572.9, 0.086]], "asks": [[64576.8, 0.007], [64578.1, 0.0], [64579.0, 0.02], [64579.8, 0.088], [64580.2, 0.105], [64580.4, 2.32], [64583.2, 0.312], [64584.5, 0.003], [64591.7, 1.114], [64593.8, 0.046], [64597.0, 0.558], [64598.0, 0.022], [64598.3, 1.353], [64599.3, 0.008], [64608.2, 5.451], [64608.3, 0.0], [64634.5, 1.476], [64653.8, 0.002], [64903.6, 0.308], [65222.1, 3.05]]}
{"kind": "depth", "E": 1787088866429, "U": 11315947769796, "u": 11315947774233, "recv_ms": 1787088866376, "bids": [[1000.0, 35.76], [14076.2, 3.71], [14176.2, 0.448], [14476.2, 0.042], [58118.5, 0.002], [61347.3, 0.001], [61993.1, 0.0], [63576.2, 0.051], [63930.4, 0.0], [64545.5, 0.416], [64552.9, 0.074], [64559.4, 0.019], [64563.2, 1.547], [64569.5, 0.003], [64570.5, 0.185], [64572.8, 0.94], [64573.8, 0.003], [64575.9, 0.002], [64576.2, 7.435]], "asks": [[64576.3, 29.337], [64579.0, 0.01], [64579.1, 0.094], [64581.7, 0.014], [64591.8, 1.238], [64593.2, 0.005], [64593.9, 31.59], [64601.8, 0.0], [64608.2, 5.297], [64608.3, 0.154], [64650.1, 1.537], [64651.3, 0.004], [64662.3, 45.825], [64899.2, 0.154], [65222.1, 3.05], [65576.3, 0.024]]}
{"kind": "depth", "E": 1787088866531, "U": 11315947774389, "u": 11315947778473, "recv_ms": 1787088866512, "bids": [[14076.2, 3.696], [14176.2, 0.28], [14476.2, 0.224], [58118.5, 0.002], [61347.3, 0.001], [61993.1, 0.003], [63644.1, 13.769], [63704.4, 3.241], [63930.4, 0.0], [64323.0, 0.107], [64486.5, 0.106], [64487.3, 0.628], [64488.7, 29.196], [64559.4, 0.021], [64569.5, 0.003], [64570.5, 0.185], [64572.8, 0.94]], "asks": [[64576.3, 29.336], [64591.8, 1.24], [64608.2, 5.451], [64608.3, 0.0], [64651.3, 45.829], [64662.3, 0.0], [64829.8, 0.109], [65222.1, 3.05]]}
{"kind": "depth", "E": 1787088866633, "U": 11315947778554, "u": 11315947782927, "recv_ms": 1787088866580, "bids": [[14076.2, 3.584], [14176.2, 0.154], [14476.2, 0.462], [58118.5, 0.002], [61347.3, 0.001], [63576.2, 0.031], [63930.4, 0.0], [64253.3, 0.414], [64433.4, 0.005], [64433.5, 3.413], [64556.7, 0.563], [64556.9, 0.004], [64560.3, 0.106], [64563.5, 0.087], [64567.8, 1.09], [64569.3, 0.001], [64569.5, 0.003], [64570.5, 0.185], [64572.7, 0.001], [64572.8, 0.94], [64573.6, 0.002], [64573.8, 0.002], [64576.2, 6.41]], "asks": [[64576.3, 29.336], [64578.3, 0.011], [64579.0, 0.006], [64580.6, 43.22], [64596.3, 0.941], [64597.4, 0.04], [64599.2, 0.027], [64606.5, 0.264], [64608.2, 5.451], [64716.0, 0.0], [64716.1, 5.408], [65222.1, 3.05], [65576.3, 0.004], [65738.7, 0.008]]}
{"kind": "depth", "E": 1787088866735, "U": 11315947782965, "u": 11315947786834, "recv_ms": 1787088866680, "bids": [[1000.0, 35.76], [14076.2, 3.458], [14176.2, 0.042], [14476.2, 0.7], [51661.0, 0.0], [58118.5, 0.002], [61993.1, 0.0], [63182.7, 0.002], [63183.6, 0.0], [63514.9, 1.102], [63644.1, 12.67], [63930.4, 0.0], [64253.3, 0.413], [64543.9, 0.011], [64544.0, 1.037], [64559.1, 0.008], [64560.3, 0.098], [64563.5, 0.095], [64563.6, 0.02], [64569.7, 0.0], [64570.2, 1.552], [64570.3, 0.566], [64570.4, 0.0], [64570.6, 0.066], [64572.1, 0.103], [64572.2, 0.009], [64572.8, 0.656], [64572.9, 0.002]], "asks": [[64576.3, 29.336], [64580.0, 8.035], [64580.2, 0.393], [64597.6, 10.001], [64608.2, 5.451], [64649.1, 45.871], [64651.3, 0.004], [64767.9, 0.661], [64899.2, 0.155], [65222.1, 3.05], [65376.2, 3.056]]}
{"kind": "depth", "E": 1787088866837, "U": 11315947786923, "u": 11315947791843, "recv_ms": 1787088866784, "bids": [[14076.2, 3.192], [14176.2, 0.0], [14476.2, 1.008], [58118.5, 0.002], [61347.3, 0.001], [61993.1, 0.003], [63288.9, 4.417], [63495.7, 0.628], [63576.2, 0.051], [63639.8, 2.197], [63876.3, 3.128], [63930.4, 0.0], [64433.5, 0.504], [64433.6, 3.556], [64558.2, 0.009], [64559.1, 0.009], [64560.3, 0.106], [64561.1, 0.003], [64561.5, 0.042], [64562.7, 0.0], [64563.1, 0.019], [64563.5, 0.629], [64563.6, 0.561], [64565.2, 0.36], [64566.4, 0.571], [64569.1, 0.124], [64569.3, 0.003], [64569.4, 2.413], [64569.5, 0.001], [64570.2, 0.004], [64570.3, 0.001], [64570.4, 0.0], [64570.5, 0.185], [64570.6, 0.004], [64570.9, 0.089], [64571.0, 1.881], [64571.1, 0.008], [64571.2, 0.189], [64571.9, 0.001], [64572.1, 0.103], [64572.2, 1.565], [64572.3, 0.004], [64572.4, 0.008], [64572.5, 0.085], [64572.8, 0.94], [64572.9, 0.01], [64576.2, 6.383]], "asks": [[64576.3, 29.337], [64576.8, 0.0], [64578.1, 0.007], [64579.1, 0.084], [64579.8, 0.001], [64580.2, 0.105], [64580.3, 1.013], [64583.2, 0.003], [64584.5, 0.312], [64591.6, 0.631], [64591.7, 0.495], [64592.0, 0.258], [64592.1, 5.654], [64593.2, 0.547], [64593.3, 0.014], [64593.8, 0.046], [64593.9, 32.517], [64608.2, 5.297], [64608.3, 0.154], [64610.7, 0.033], [64610.8, 0.442], [64649.1, 0.046], [64660.1, 45.838], [64716.1, 5.408], [65222.1, 3.05], [65576.3, 0.024]]}
{"kind": "depth", "E": 1787088866939, "U": 11315947791865, "u": 11315947796223, "recv_ms": 1787088866886, "bids": [[1000.0, 35.91], [14076.2, 2.842], [14476.2, 1.358], [58118.5, 0.002], [61351.5, 0.004], [61351.6, 2.445], [61993.1, 0.0], [63510.7, 1.101], [63639.8, 3.296], [63801.3, 1.22], [63930.4, 0.0], [64233.0, 1.332], [64234.3, 0.497], [64253.3, 0.403], [64257.6, 6.499], [64569.3, 0.001], [64570.0, 0.022], [64571.0, 0.003], [64571.1, 0.008], [64571.2, 0.127], [64571.3, 1.632], [64571.4, 0.0], [64572.1, 0.103], [64572.2, 0.017], [64572.3, 0.004], [64572.9, 0.072]], "asks": [[64577.6, 0.027], [64577.8, 0.044], [64579.0, 0.016], [64579.8, 0.011], [64651.3, 46.178], [64660.1, 0.013], [64903.5, 4.462], [65222.1, 3.05], [65493.3, 0.23]]}
{"kind": "depth", "E": 1787088867041, "U": 11315947796274, "u": 11315947803298, "recv_ms": 1787088866989, "bids": [[1000.0, 35.76], [14076.2, 2.464], [14476.2, 1.736], [58118.5, 0.002], [61347.3, 0.001], [61993.1, 0.003], [63284.7, 0.019], [63576.2, 0.031], [63786.5, 6.998], [63930.4, 0.0], [64551.4, 2.577], [64551.5, 0.329], [64554.8, 0.116], [64555.6, 0.002], [64555.9, 0.559], [64556.7, 0.005], [64559.1, 0.001], [64560.3, 0.098], [64560.5, 0.927], [64560.6, 0.012], [64561.0, 0.013], [64561.1, 0.003], [64563.5, 1.186], [64563.6, 0.012], [64563.7, 0.0], [64564.6, 0.47], [64569.1, 0.04], [64569.3, 0.003], [64569.7, 1.152], [64570.0, 0.023], [64570.2, 0.066], [64570.9, 0.086], [64571.3, 0.084], [64571.4, 0.0], [64571.9, 0.004], [64572.1, 0.103], [64572.2, 0.009], [64572.7, 0.311], [64572.8, 0.656], [64572.9, 3.71], [64573.0, 0.016], [64573.8, 0.086]], "asks": [[64576.3, 29.337], [64576.5, 0.089], [64579.0, 0.006], [64579.8, 0.001], [64580.1, 0.037], [64591.6, 0.012], [64591.7, 0.495], [64592.8, 0.003], [64592.9, 0.0], [64593.2, 0.005], [64593.3, 0.556], [64593.7, 0.932], [64593.8, 0.665], [64593.9, 31.59], [64599.3, 0.001], [64599.8, 0.011], [65222.1, 3.05], [65344.0, 0.883], [65576.3, 0.004]]}
{"kind": "depth", "E": 1787088867143, "U": 11315947803315, "u": 11315947808552, "recv_ms": 1787088867090, "bids": [[14076.2, 2.114], [14476.2, 2.086], [58118.5, 0.002], [63407.2, 0.675], [63930.4, 0.0], [64253.3, 0.402], [64435.1, 1.361], [64488.8, 7.576], [64497.8, 0.002], [64504.9, 1.356], [64518.0, 0.254], [64524.9, 0.008], [64527.8, 0.037], [64533.1, 0.002], [64536.7, 0.609], [64559.1, 0.009], [64560.6, 0.012], [64563.5, 0.544], [64563.6, 0.097], [64564.6, 0.465], [64569.3, 0.001], [64569.7, 0.0], [64570.0, 0.022], [64570.2, 1.568], [64570.3, 2.263], [64570.5, 0.247], [64571.1, 0.011], [64571.9, 0.001], [64572.5, 0.001], [64572.7, 0.001], [64572.8, 1.189], [64572.9, 0.002], [64573.0, 0.0], [64573.1, 0.002], [64573.4, 0.0], [64573.8, 0.002], [64574.0, 0.051]], "asks": [[64579.0, 0.025], [64581.5, 0.004], [64582.9, 0.012], [64592.1, 5.652], [64596.3, 2.191], [64634.3, 2.328], [64634.4, 0.004], [64650.1, 7.972], [64653.8, 0.005], [64720.9, 0.881], [64899.2, 0.31], [65222.1, 3.05], [65724.4, 2.632]]}
{"kind": "depth", "E": 1787088867245, "U": 11315947808606, "u": 11315947813504, "recv_ms": 1787088867191, "bids": [[1000.0, 35.76], [14076.2, 1.764], [14476.2, 2.436], [58118.5, 0.002], [61347.3, 0.001], [61993.1, 0.0], [63286.1, 0.003], [63576.2, 0.051], [63657.3, 30.896], [63930.4, 0.0], [64253.3, 0.567], [64504.9, 1.357], [64515.9, 0.268], [64524.9, 0.009], [64527.8, 0.039], [64545.5, 1.035], [64552.9, 0.693], [64563.1, 0.561], [64563.5, 0.002], [64569.1, 0.124], [64569.5, 0.001], [64570.0, 0.02], [64570.1, 0.715], [64570.4, 0.0], [64570.5, 0.185], [64570.6, 0.004], [64570.7, 0.076], [64572.1, 0.019], [64572.5, 0.085]], "asks": [[64576.3, 29.468], [64579.0, 0.035], [64579.8, 0.011], [64599.1, 2.012], [64606.5, 0.883], [64645.2, 0.16], [65222.1, 3.05], [65576.3, 0.024], [65743.7, 1.321], [65867.8, 1.531]]}
{"kind": "depth", "E": 1787088867347, "U": 11315947813698, "u": 11315947819639, "recv_ms": 1787088867293, "bids": [[1000.0, 35.76], [14076.2, 1.4], [14476.2, 2.8], [58118.5, 0.002], [61993.1, 0.003], [63769.0, 1.883], [63837.8, 4.696], [63930.4, 0.0], [64433.6, 0.03], [64433.7, 4.326], [64435.1, 0.94], [64538.6, 0.004], [64554.8, 0.0], [64555.7, 2.423], [64555.9, 0.001], [64556.9, 0.562], [64569.5, 0.003], [64570.1, 0.713], [64570.4, 0.0]], "asks": [[64576.8, 0.0], [64577.2, 0.007], [64577.7, 0.113], [64578.1, 0.0], [64579.8, 0.088], [64580.3, 0.936], [64580.6, 43.222], [64582.0, 0.083], [64583.2, 0.312], [64584.5, 0.003], [64716.1, 5.408], [65222.1, 3.05], [65685.5, 1.367], [65706.4, 1.216]]}
{"kind": "depth", "E": 1787088867449, "U": 11315947819782, "u": 11315947823980, "recv_ms": 1787088867396, "bids": [[14076.2, 1.05], [14476.2, 3.15], [58118.5, 0.002], [61347.4, 0.004], [61993.1, 0.0], [63576.2, 0.031], [63657.3, 29.798], [63930.4, 0.0], [64559.4, 0.019], [64569.5, 0.001], [64570.1, 0.715], [64570.3, 2.263], [64570.9, 0.089], [64571.1, 0.008]], "asks": [[64591.7, 1.114], [64591.8, 1.238], [64593.8, 0.046], [65576.3, 0.004], [65867.8, 1.528]]}
{"kind": "depth", "E": 1787088867551, "U": 11315947824021, "u": 11315947829079, "recv_ms": 1787088867498, "bids": [[1000.0, 35.76], [14076.2, 0.686], [14476.2, 3.514], [58118.5, 0.002], [61993.1, 0.003], [63639.8, 4.081], [63769.0, 2.234], [63930.4, 0.0], [64253.3, 0.567], [64433.7, 4.312], [64555.3, 0.116], [64555.7, 2.307], [64556.6, 0.674], [64556.9, 0.004], [64559.1, 0.001], [64559.4, 0.021], [64560.6, 0.554], [64563.1, 0.019], [64563.6, 0.012], [64565.2, 0.05], [64566.4, 0.881], [64569.5, 0.003], [64570.1, 0.713], [64570.2, 1.552], [64570.4, 0.077], [64570.6, 0.036], [64570.9, 0.086], [64571.9, 0.004], [64572.3, 0.314], [64573.0, 0.0], [64573.2, 0.089], [64573.4, 0.0], [64575.0, 0.02]], "asks": [[64577.2, 0.0], [64578.1, 0.007], [64579.8, 0.011], [64580.4, 2.397], [64583.2, 0.003], [64584.5, 0.312], [64591.6, 0.012], [64591.7, 0.495], [64591.8, 1.24], [64592.0, 0.8], [64592.7, 0.929], [64593.3, 0.014], [64593.7, 0.005], [64593.8, 0.665], [64595.7, 1.003], [64598.7, 0.07], [64599.8, 0.004], [64660.2, 0.003], [64660.3, 0.013], [64716.1, 5.408], [65222.1, 3.05], [65667.6, 0.609], [65725.8, 0.759]]}
{"kind": "depth", "E": 1787088867653, "U": 11315947829123, "u": 11315947833416, "recv_ms": 1787088867601, "bids": [[1000.0, 35.76], [14076.2, 0.392], [14376.2, 0.07], [14476.2, 3.738], [51661.0, 0.0], [58118.5, 0.002], [61347.3, 0.001], [63471.3, 1.574], [63576.2, 0.051], [63639.8, 5.18], [63761.9, 0.787], [63769.0, 2.585], [63773.3, 20.354], [63833.6, 2.816], [63930.4, 0.0], [63960.0, 0.255], [64518.0, 0.251], [64530.9, 0.136], [64559.1, 0.009], [64560.6, 0.546], [64560.7, 0.01], [64563.5, 0.087], [64565.2, 0.36], [64566.4, 0.571], [64569.5, 0.003], [64570.1, 0.713], [64570.4, 0.0], [64570.6, 0.02], [64571.1, 0.011], [64571.9, 0.001], [64572.1, 2.179], [64572.3, 0.004], [64573.2, 0.005]], "asks": [[64576.3, 29.468], [64579.0, 0.025], [64579.1, 0.094], [64579.8, 0.088], [64580.4, 2.32], [64580.7, 1.805], [64591.7, 1.114], [64592.0, 0.258], [64592.7, 0.002], [64593.0, 0.547], [64593.1, 0.969], [64593.8, 0.046], [64605.1, 0.313], [64605.2, 0.174], [64605.3, 0.026], [64608.1, 2.206], [64608.2, 5.299], [64608.3, 0.156], [64609.0, 0.019], [64609.1, 0.002], [64609.2, 0.002], [64611.1, 0.002], [64611.2, 0.022], [64611.3, 0.003], [64634.5, 1.476], [64653.8, 0.002], [64899.2, 0.309], [65180.3, 0.013], [65222.1, 3.05], [65576.3, 0.024], [66150.9, 1.941]]}
{"kind": "depth", "E": 1787088867755, "U": 11315947833493, "u": 11315947838024, "recv_ms": 1787088867701, "bids": [[14076.2, 0.252], [14376.2, 0.28], [14476.2, 3.668], [51661.0, 0.0], [58118.5, 0.002], [61993.1, 0.0], [63930.4, 0.0], [64533.2, 0.0], [64541.0, 0.701], [64560.6, 0.004], [64563.0, 2.863], [64563.5, 0.087], [64569.5, 0.003], [64570.1, 0.713], [64570.2, 0.004], [64570.3, 1.721], [64570.4, 0.542], [64570.6, 1.56], [64570.7, 0.084], [64572.1, 1.099], [64572.2, 0.009], [64572.3, 0.004], [64572.4, 0.008], [64572.9, 0.002]], "asks": [[65222.1, 3.05], [65383.5, 1.058]]}
{"kind": "depth", "E": 1787088867857, "U": 11315947838148, "u": 11315947843282, "recv_ms": 1787088867804, "bids": [[1000.0, 35.76], [14076.2, 0.126], [14376.2, 0.504], [14476.2, 3.57], [58118.5, 0.002], [61347.3, 0.001], [61993.1, 0.003], [63576.2, 0.031], [63644.2, 28.958], [63805.5, 29.164], [63812.1, 4.656], [63930.4, 0.001], [63949.8, 0.866], [64253.3, 0.568], [64257.6, 6.344], [64415.3, 0.013], [64416.0, 1.284], [64433.7, 0.0], [64572.1, 0.103], [64572.2, 0.009], [64572.3, 0.004], [64572.4, 0.008], [64572.5, 0.001]], "asks": [[64576.3, 29.468], [64593.1, 0.042], [64593.5, 0.927], [64716.1, 0.0], [64732.8, 0.0], [64732.9, 0.003], [64903.5, 4.308], [65097.2, 7.515], [65222.1, 3.052], [65576.3, 0.004], [65867.8, 1.525]]}
{"kind": "depth", "E": 1787088867959, "U": 11315947843312, "u": 11315947848424, "recv_ms": 1787088867906, "bids": [[1000.0, 35.76], [14076.2, 0.014], [14376.2, 0.756], [14476.2, 3.43], [58118.5, 0.002], [61993.1, 0.0], [63805.6, 44.661], [63930.4, 0.001], [64063.9, 9.039], [64234.3, 0.004], [64234.7, 0.496], [64416.8, 5.106], [64433.8, 4.314], [64460.1, 29.759], [64488.7, 0.0], [64560.5, 0.0], [64560.6, 0.012], [64560.7, 0.002], [64561.8, 0.927], [64563.5, 0.087], [64570.5, 0.185], [64572.1, 0.019], [64572.2, 0.009], [64572.3, 0.004], [64572.4, 1.088], [64572.7, 0.001], [64573.2, 0.005]], "asks": [[64579.8, 0.011], [64580.4, 2.397], [64580.7, 1.793], [64591.7, 0.495], [64593.5, 0.0], [64593.8, 0.665], [64594.2, 1.017], [64598.3, 1.237], [64599.1, 2.128], [64716.1, 5.408], [64733.0, 10.428], [65222.1, 3.05]]}
{"kind": "depth", "E": 1787088868061, "U": 11315947848526, "u": 11315947853871, "recv_ms": 1787088868008, "bids": [[14076.2, 0.0], [14376.2, 1.078], [14476.2, 3.122], [58118.5, 0.002], [61347.3, 0.001], [63576.2, 0.051], [63639.8, 6.278], [63807.7, 2.974], [63889.7, 6.987], [63930.4, 0.001], [64460.1, 0.01], [64460.2, 0.001], [64488.7, 29.334], [64488.8, 0.003], [64508.1, 4.655], [64560.9, 1.27], [64561.8, 0.0], [64564.6, 0.465], [64570.7, 0.084], [64570.8, 0.006], [64570.9, 0.086], [64571.0, 1.083], [64572.1, 0.103], [64572.4, 0.008], [64576.2, 6.385]], "asks": [[64581.5, 0.003], [64597.0, 0.001], [64597.9, 0.558], [65222.1, 3.05], [65388.0, 27.415], [65576.3, 0.024]]}
{"kind": "depth", "E": 1787088868163, "U": 11315947854059, "u": 11315947859163, "recv_ms": 1787088868110, "bids": [[1000.0, 35.76], [14376.2, 1.456], [14476.2, 2.744], [58118.5, 0.002], [61347.3, 0.002], [61993.1, 0.003], [63284.7, 0.016], [63801.3, 1.846], [63930.4, 0.001], [64059.6, 0.314], [64253.3, 0.724], [64435.1, 1.478], [64468.9, 29.356], [64488.1, 2.621], [64488.7, 0.0], [64504.9, 1.358], [64518.0, 0.254], [64520.9, 0.0], [64521.2, 0.024], [64521.5, 0.013], [64521.9, 0.002], [64522.2, 1.237], [64525.0, 0.221], [64527.9, 3.527], [64538.4, 3.331], [64538.7, 0.001], [64539.0, 0.001], [64539.3, 2.319], [64539.7, 0.019], [64547.9, 0.116], [64548.0, 0.421], [64548.1, 0.642], [64548.2, 3.157], [64548.3, 2.631], [64548.4, 0.109], [64548.5, 0.407], [64548.6, 0.464], [64548.7, 0.005], [64548.8, 0.001], [64549.6, 0.0], [64550.1, 0.0], [64564.7, 0.117], [64566.7, 0.002], [64566.8, 0.02], [64566.9, 0.022], [64567.0, 0.484], [64567.1, 0.013], [64567.3, 0.001], [64567.4, 0.005], [64567.5, 0.072], [64567.6, 0.028], [64567.9, 0.001], [64568.2, 0.001], [64568.5, 0.002], [64568.9, 0.0], [64569.2, 0.018], [64570.7, 1.164], [64571.0, 0.003], [64572.1, 0.103], [64572.2, 0.009], [64572.3, 0.004]], "asks": [[64576.3, 29.468], [64580.6, 43.22], [64583.8, 0.004], [64586.6, 0.0], [64586.9, 0.018], [64587.2, 0.119], [64587.5, 0.117], [64587.9, 0.019], [64588.1, 0.001], [64588.4, 0.02], [64588.5, 1.709], [64588.6, 0.014], [64588.7, 0.003], [64588.8, 0.021], [64588.9, 0.0], [64589.0, 1.394], [64589.1, 2.329], [64603.7, 0.001], [64604.0, 0.014], [64604.4, 0.003], [64604.7, 0.003], [64605.0, 0.001], [64605.9, 2.048], [64606.3, 0.66], [64606.5, 0.623], [64606.7, 0.0], [64606.9, 0.002], [64607.1, 0.002], [64607.2, 0.0], [64607.3, 0.002], [64607.4, 0.506], [64607.6, 0.0], [64607.8, 0.041], [64620.9, 0.042], [64621.2, 0.0], [64621.5, 0.0], [64621.8, 0.001], [64622.2, 0.0], [64653.8, 0.005], [64732.9, 2.597], [64899.2, 0.462], [65092.9, 1.537], [65222.1, 3.05], [65872.2, 0.0]]}
{"kind": "depth", "E": 1787088868265, "U": 11315947859261, "u": 11315947864439, "recv_ms": 1787088868212, "bids": [[1000.0, 35.76], [14376.2, 1.806], [14476.2, 2.394], [51661.0, 0.0], [58118.5, 0.002], [61347.3, 0.002], [61993.1, 0.0], [63576.2, 0.031], [63872.3, 1.448], [63930.4, 0.001], [64255.0, 0.207], [64259.3, 0.0], [64460.2, 3.872], [64462.8, 0.0], [64468.9, 0.022], [64504.4, 0.046], [64507.0, 0.095], [64533.4, 0.087], [64533.7, 4.512], [64534.0, 0.048], [64534.3, 1.872], [64542.8, 0.627], [64545.5, 0.416], [64550.2, 0.154], [64552.9, 0.074], [64559.6, 0.027], [64560.3, 0.106], [64560.6, 0.004], [64563.5, 0.087], [64567.0, 0.554], [64567.3, 0.071], [64567.5, 0.272], [64567.7, 0.105], [64567.8, 1.16], [64567.9, 0.101], [64568.3, 0.048], [64568.6, 0.034], [64568.7, 0.085], [64568.9, 0.032], [64569.3, 0.033], [64570.3, 0.008], [64570.7, 1.156], [64571.0, 0.006], [64571.1, 0.008], [64571.6, 0.085], [64571.7, 0.073], [64572.0, 0.304], [64572.1, 0.019], [64572.2, 0.009], [64572.3, 0.004], [64572.7, 0.001], [64572.8, 1.189], [64572.9, 0.01], [64576.2, 6.233]], "asks": [[64576.3, 29.34], [64579.0, 0.025], [64579.1, 0.084], [64579.8, 0.011], [64586.8, 0.113], [64587.1, 0.335], [64587.4, 0.296], [64587.7, 0.06], [64588.1, 0.251], [64588.2, 0.45], [64588.3, 0.241], [64588.5, 1.939], [64588.6, 0.274], [64588.8, 0.161], [64589.0, 1.527], [64592.1, 5.652], [64595.7, 1.127], [64599.1, 1.509], [64604.3, 0.496], [64604.6, 0.167], [64604.9, 0.064], [64605.2, 0.232], [64605.6, 0.295], [64606.0, 6.303], [64607.0, 2.461], [64607.1, 0.242], [64607.3, 0.232], [64607.6, 0.14], [64607.8, 0.174], [64646.5, 0.047], [64649.1, 0.0], [64710.6, 1.532], [64710.7, 6.195], [64715.2, 2.319], [64908.6, 0.108], [64911.6, 0.0], [65576.3, 0.004], [65867.8, 1.528]]}
{"kind": "depth", "E": 1787088868367, "U": 11315947864443, "u": 11315947868890, "recv_ms": 1787088868314, "bids": [[14376.2, 2.17], [14476.2, 2.03], [34000.0, 1.146], [51661.0, 0.0], [58118.5, 0.002], [61347.3, 0.001], [61347.4, 0.006], [61993.1, 0.003], [63198.5, 2.031], [63930.4, 0.001], [64059.6, 0.314], [64460.1, 29.344], [64488.7, 0.0], [64534.7, 0.051], [64567.1, 0.083], [64567.2, 0.288], [64567.4, 0.105], [64567.8, 1.26], [64569.6, 1.391], [64570.7, 0.076], [64570.8, 0.014], [64572.1, 0.019], [64572.2, 0.009], [64572.3, 1.084], [64572.8, 0.841], [64572.9, 0.002]], "asks": [[64576.3, 29.348], [64576.8, 0.007], [64578.1, 0.0], [64579.1, 0.084], [64579.8, 0.078], [64580.4, 2.32], [64580.6, 43.211], [64583.2, 0.312], [64584.5, 0.003], [64586.5, 2.415], [64586.9, 0.021], [64587.8, 0.002], [64588.3, 0.501], [64588.6, 0.534], [64588.9, 0.259], [64597.0, 0.558], [64597.9, 0.001], [64598.3, 1.353], [64599.1, 1.393], [64603.9, 0.208], [64607.0, 2.721], [64607.4, 0.766], [64607.7, 0.276], [65222.1, 3.05], [65349.2, 1.834], [65355.7, 47.508]]}
{"kind": "depth", "E": 1787088868469, "U": 11315947868977, "u": 11315947872959, "recv_ms": 1787088868416, "bids": [[1000.0, 35.76], [14376.2, 2.52], [14476.2, 1.68], [58118.5, 0.002], [61347.3, 0.001], [61993.1, 0.0], [63528.1, 2.567], [63576.2, 0.051], [63930.4, 0.001], [64253.3, 0.724], [64460.1, 0.01], [64488.7, 29.334], [64567.2, 0.358], [64568.0, 0.427], [64570.7, 0.076], [64572.1, 0.019], [64572.2, 1.089], [64572.3, 0.004]], "asks": [[64576.3, 29.349], [64579.8, 0.088], [64588.0, 0.544], [64588.8, 0.315], [64591.7, 1.114], [64593.8, 0.046], [64606.8, 0.291], [64607.6, 0.294], [65222.1, 3.05], [65358.4, 0.764], [65576.3, 0.024]]}
{"kind": "depth", "E": 1787088868571, "U": 11315947873131, "u": 11315947877482, "recv_ms": 1787088868518, "bids": [[1000.0, 35.76], [14376.2, 2.884], [14476.2, 1.316], [58118.5, 0.002], [61347.3, 0.001], [63478.4, 0.943], [63510.7, 1.809], [63547.2, 10.063], [63930.4, 0.001], [64416.8, 0.001], [64417.0, 5.139], [64433.8, 0.003], [64433.9, 4.319], [64460.1, 29.344], [64488.7, 0.0], [64515.4, 0.01], [64515.9, 0.3], [64516.2, 0.032], [64516.5, 0.032], [64516.9, 0.036], [64526.1, 0.065], [64559.4, 0.021], [64561.5, 0.035], [64562.7, 0.007], [64565.2, 0.05], [64566.4, 0.881], [64567.4, 0.175], [64567.6, 0.128], [64567.7, 0.175], [64568.7, 0.001], [64569.7, 0.0], [64570.1, 0.716], [64570.7, 1.156], [64571.0, 0.003], [64571.9, 0.004], [64572.2, 0.319], [64572.9, 0.086], [64573.0, 0.0], [64573.3, 0.091], [64574.0, 0.22]], "asks": [[64576.3, 29.507], [64576.8, 0.0], [64577.8, 0.002], [64578.1, 0.007], [64579.1, 0.084], [64579.8, 0.001], [64580.4, 2.397], [64583.2, 0.003], [64584.5, 0.312], [64588.4, 0.349], [64588.7, 0.136], [64591.7, 0.495], [64591.8, 1.24], [64593.8, 0.665], [64607.2, 0.329], [64607.5, 0.139], [64621.7, 0.939], [64622.0, 0.238], [64622.4, 0.066], [64622.7, 0.058], [64716.1, 5.408], [64733.0, 10.428], [65222.1, 3.05], [65344.8, 2.809], [71034.0, 0.0]]}
{"kind": "depth", "E": 1787088868673, "U": 11315947877590, "u": 11315947882108, "recv_ms": 1787088868622, "bids": [[14376.2, 3.234], [14476.2, 0.966], [58118.5, 0.002], [61351.5, 0.002], [61351.6, 2.447], [61993.1, 0.003], [63576.2, 0.031], [63858.7, 1.737], [63930.4, 0.001], [64460.1, 0.01], [64468.9, 0.022], [64486.5, 29.44], [64517.2, 1.463], [64548.2, 3.227], [64548.4, 0.179], [64548.5, 0.477], [64548.7, 0.105], [64548.9, 2.261], [64549.0, 1.776], [64550.0, 0.351], [64550.4, 0.638], [64555.0, 0.364], [64557.2, 0.465], [64561.5, 0.042], [64562.7, 0.0], [64565.2, 0.36], [64566.4, 0.571], [64570.1, 0.713], [64570.7, 0.076], [64570.8, 1.094], [64571.1, 0.011], [64571.9, 0.001], [64572.2, 0.009], [64572.3, 0.088], [64572.9, 0.002], [64573.3, 0.007], [64574.0, 0.053], [64574.1, 0.006]], "asks": [[64576.3, 29.507], [64577.6, 0.046], [64577.7, 0.135], [64579.8, 0.078], [64580.4, 2.32], [64580.7, 1.627], [64621.4, 0.222], [65222.1, 3.05], [65465.9, 2.44], [65576.3, 0.004], [66538.4, 1.932]]}
{"kind": "depth", "E": 1787088868775, "U": 11315947882156, "u": 11315947886178, "recv_ms": 1787088868722, "bids": [[1000.0, 35.76], [14376.2, 3.598], [14476.2, 0.602], [51661.0, 0.0], [58118.5, 0.002], [61347.3, 0.001], [61351.6, 2.445], [61993.1, 0.0], [63812.1, 3.717], [63930.4, 0.0], [64253.3, 0.713], [64548.3, 2.701], [64548.6, 0.564], [64549.0, 1.876], [64559.1, 0.001], [64560.3, 0.098], [64563.5, 0.636], [64563.6, 0.028], [64569.1, 0.04], [64569.4, 2.329], [64570.3, 0.004], [64570.4, 0.0], [64570.6, 0.004], [64570.7, 0.014], [64570.8, 0.006], [64570.9, 0.086], [64571.0, 1.903], [64571.1, 0.07], [64572.0, 0.307], [64572.9, 0.312], [64573.0, 0.0], [64573.1, 0.018], [64573.2, 0.005], [64573.3, 0.007], [64573.4, 1.548], [64573.5, 0.085], [64574.0, 0.008], [64574.5, 0.085], [64574.9, 0.011], [64575.1, 0.043], [64575.2, 0.536]], "asks": [[64576.3, 29.425], [64579.5, 0.001], [64579.6, 0.0], [64579.8, 0.001], [64580.2, 0.105], [64580.4, 2.397], [64580.8, 0.007], [64581.9, 2.547], [65222.1, 3.05], [65867.8, 1.531]]}
{"kind": "depth", "E": 1787088868877, "U": 11315947886270, "u": 11315947890735, "recv_ms": 1787088868824, "bids": [[1000.0, 35.76], [14276.2, 0.098], [14376.2, 3.766], [14476.2, 0.336], [58118.5, 0.004], [61347.3, 0.001], [61993.1, 0.003], [63543.0, 2.203], [63576.2, 0.051], [63930.4, 0.002], [64518.0, 0.251], [64530.9, 0.136], [64548.4, 0.249], [64549.2, 0.07], [64551.4, 2.423], [64551.5, 0.329], [64560.3, 0.106], [64563.5, 0.002], [64563.6, 0.012], [64569.3, 0.035], [64569.5, 0.001], [64569.7, 0.0], [64569.8, 0.293], [64570.2, 0.004], [64570.3, 0.097], [64570.9, 0.086], [64571.0, 0.003], [64571.1, 0.008], [64571.2, 0.127], [64571.3, 0.084], [64572.1, 0.019], [64572.2, 0.558], [64572.8, 0.841], [64573.0, 1.564], [64573.1, 0.002], [64573.4, 0.0], [64573.9, 0.352], [64574.5, 0.001], [64575.2, 0.179]], "asks": [[64576.3, 29.554], [64579.5, 0.001], [64597.0, 0.001], [64597.3, 0.577], [64598.3, 1.237], [64598.7, 0.179], [64599.5, 0.011], [64634.5, 1.476], [64653.8, 0.002], [64899.2, 0.463], [65222.1, 3.05], [65326.2, 0.886], [65448.1, 0.776], [65576.3, 0.024]]}
{"kind": "depth", "E": 1787088868979, "U": 11315947890747, "u": 11315947894295, "recv_ms": 1787088868925, "bids": [[14276.2, 0.336], [14376.2, 3.64], [14476.2, 0.224], [58118.5, 0.002], [61351.5, 0.0], [61351.6, 2.447], [63576.2, 0.031], [63930.4, 0.0], [64234.7, 0.003], [64235.4, 0.493], [64257.6, 6.189], [64468.9, 0.022], [64486.5, 0.106], [64488.7, 29.406], [64548.6, 0.634], [64548.8, 0.101], [64548.9, 2.331], [64550.4, 0.558], [64551.2, 0.168], [64557.2, 0.545], [64560.3, 0.106], [64563.5, 0.002], [64569.8, 0.231], [64570.2, 1.552], [64570.3, 0.646], [64570.4, 1.889], [64570.5, 0.823], [64572.1, 2.179], [64572.2, 0.009], [64572.8, 0.952], [64573.0, 0.016]], "asks": [[64576.3, 29.554], [65222.1, 3.05], [65576.3, 0.004]]}
{"kind": "depth", "E": 1787088869081, "U": 11315947894370, "u": 11315947898955, "recv_ms": 1787088869027, "bids": [[1000.0, 35.76], [14276.2, 0.56], [14376.2, 3.542], [14476.2, 0.098], [58118.5, 0.002], [61347.3, 0.001], [61993.1, 0.0], [63747.1, 5.481], [63807.7, 3.913], [63930.4, 0.0], [64253.3, 0.723], [64433.9, 0.0], [64435.1, 0.94], [64460.1, 0.01], [64486.5, 29.512], [64488.7, 0.0], [64556.4, 0.081], [64557.2, 0.465], [64560.3, 0.098], [64563.5, 0.644], [64563.6, 0.02], [64564.6, 0.465], [64569.3, 0.035], [64569.5, 0.001], [64570.1, 0.713], [64570.2, 0.004], [64570.3, 0.004], [64570.4, 0.0], [64570.5, 0.185], [64570.6, 1.63], [64572.1, 0.019], [64572.2, 0.009], [64572.4, 0.318], [64572.8, 0.611], [64572.9, 0.002], [64573.0, 0.0], [64573.1, 0.002], [64573.9, 0.352], [64575.2, 0.366]], "asks": [[64576.3, 29.563], [64577.6, 0.047], [64580.6, 43.202], [64595.7, 1.003], [64713.6, 1.517], [64716.1, 0.0], [65222.1, 3.05], [65298.1, 9.183]]}
{"kind": "depth", "E": 1787088869183, "U": 11315947899116, "u": 11315947903524, "recv_ms": 1787088869131, "bids": [[1000.0, 35.76], [14276.2, 0.826], [14376.2, 3.374], [14476.2, 0.0], [51661.0, 0.0], [58118.5, 0.002], [61993.1, 0.003], [63773.3, 20.12], [63930.4, 0.0], [64253.3, 0.877], [64417.0, 0.022], [64460.3, 1.327], [64488.1, 6.675], [64505.0, 0.839], [64560.3, 0.106], [64563.5, 0.002], [64563.6, 0.012], [64569.7, 0.0], [64570.2, 0.097], [64570.6, 1.568], [64570.7, 0.563], [64570.8, 0.068], [64572.8, 0.985], [64575.2, 0.133]], "asks": [[64576.3, 29.564], [64577.8, 0.034], [64579.0, 0.056], [64581.7, 0.001], [64582.0, 0.084], [64582.4, 0.008], [64582.8, 0.103], [64583.0, 0.006], [64583.8, 0.003], [64732.9, 0.003], [64733.0, 0.001], [64734.0, 1.024], [65222.1, 3.05], [65298.0, 8.897]]}
{"kind": "depth", "E": 1787088869285, "U": 11315947903657, "u": 11315947908649, "recv_ms": 1787088869232, "bids": [[14276.2, 1.19], [14376.2, 3.01], [58118.5, 0.002], [61347.3, 0.001], [61993.1, 0.0], [63366.6, 0.113], [63576.2, 0.051], [63930.4, 0.0], [64376.6, 0.002], [64377.2, 0.634], [64378.3, 4.871], [64417.1, 4.133], [64434.0, 3.798], [64435.1, 1.402], [64533.2, 0.004], [64541.0, 0.697], [64563.5, 0.095], [64570.2, 0.004], [64570.8, 0.006], [64570.9, 0.148], [64574.3, 0.085]], "asks": [[64576.3, 29.563], [64605.1, 0.311], [64605.2, 0.23], [64605.3, 0.024], [64608.1, 2.204], [64608.2, 5.297], [64608.3, 0.154], [64609.0, 0.017], [64609.1, 0.0], [64609.2, 0.0], [64611.1, 0.0], [64611.2, 0.02], [64611.3, 0.001], [64716.1, 5.408], [64733.1, 10.428], [64771.7, 3.698], [64771.8, 15.44], [64772.2, 0.004], [64774.6, 0.0], [64776.0, 0.003], [65222.1, 3.05], [65280.2, 1.151], [65484.8, 47.858], [65576.3, 0.024]]}
{"kind": "depth", "E": 1787088869387, "U": 11315947908663, "u": 11315947914010, "recv_ms": 1787088869335, "bids": [[1000.0, 35.76], [14276.2, 1.54], [14376.2, 2.66], [58118.5, 0.002], [61347.3, 0.001], [61347.4, 0.008], [61993.1, 0.003], [63284.7, 0.016], [63547.3, 0.44], [63930.4, 0.0], [63962.2, 0.781], [64253.3, 0.867], [64378.3, 0.0], [64378.4, 10.517], [64380.5, 4.0], [64468.9, 29.428], [64486.5, 0.106], [64488.1, 2.621], [64488.7, 0.0], [64512.8, 2.24], [64515.1, 1.691], [64515.6, 1.002], [64552.6, 0.627], [64560.3, 0.114], [64561.5, 0.042], [64562.7, 0.0], [64563.5, 0.087], [64565.1, 0.312], [64565.2, 0.05], [64566.4, 0.571], [64569.4, 2.413], [64570.2, 1.552], [64570.3, 0.543], [64570.6, 0.02], [64570.7, 0.021], [64570.8, 0.006], [64571.2, 0.13], [64571.9, 0.002], [64572.0, 0.304], [64572.4, 0.008], [64572.7, 0.084], [64572.8, 0.938], [64573.5, 0.001], [64573.9, 0.268], [64574.3, 0.001], [64575.2, 0.109], [64576.2, 6.221]], "asks": [[64576.3, 29.563], [64576.8, 0.007], [64577.2, 0.171], [64578.1, 0.0], [64579.8, 0.441], [64580.4, 2.32], [64582.0, 0.083], [64583.2, 0.312], [64584.5, 0.003], [64592.1, 5.652], [64593.1, 0.969], [64594.2, 0.09], [64598.9, 0.959], [64639.3, 2.863], [64643.5, 0.219], [64899.2, 0.464], [65222.1, 3.05], [65530.6, 10.066], [66132.7, 0.647]]}
{"kind": "depth", "E": 1787088869489, "U": 11315947914074, "u": 11315947918620, "recv_ms": 1787088869434, "bids": [[1000.0, 35.76], [14276.2, 1.89], [14376.2, 2.31], [58118.5, 0.002], [63576.2, 0.031], [63769.0, 2.936], [63930.4, 0.0], [64063.9, 8.104], [64460.1, 29.416], [64468.9, 0.022], [64488.7, 0.0], [64560.3, 0.114], [64561.0, 0.013], [64563.0, 2.863], [64563.5, 0.087], [64570.4, 0.0], [64571.0, 0.006], [64571.2, 0.127]], "asks": [[64592.0, 0.258], [64593.0, 0.547], [64692.2, 0.0], [65222.1, 3.05], [65280.2, 1.838], [65452.5, 15.041], [65465.9, 1.525], [65512.7, 1.221], [65576.3, 0.004]]}
{"kind": "depth", "E": 1787088869591, "U": 11315947918766, "u": 11315947923298, "recv_ms": 1787088869538, "bids": [[14276.2, 2.254], [14376.2, 1.946], [51661.0, 0.0], [58118.5, 0.002], [61993.1, 0.0], [63644.1, 11.572], [63930.4, 0.0], [64131.9, 0.0], [64253.3, 0.867], [64460.1, 0.01], [64468.9, 29.428], [64488.7, 0.0], [64551.8, 0.04], [64555.8, 1.206], [64559.1, 0.009], [64559.4, 0.021], [64560.3, 0.106], [64563.5, 0.087], [64569.3, 0.033], [64569.5, 0.003], [64569.9, 0.005], [64570.1, 0.713], [64570.4, 1.9], [64572.0, 0.614], [64572.1, 2.179], [64573.1, 0.086], [64573.9, 0.268]], "asks": [[64579.7, 0.079], [64579.8, 0.364], [64580.3, 0.936], [64583.2, 0.003], [64584.5, 0.312], [64591.8, 1.24], [65222.1, 3.05], [65530.6, 8.999]]}
{"kind": "depth", "E": 1787088869693, "U": 11315947923453, "u": 11315947927996, "recv_ms": 1787088869642, "bids": [[1000.0, 35.76], [14276.2, 2.618], [14376.2, 1.582], [51661.0, 0.0], [58118.5, 0.002], [61993.1, 0.003], [63543.0, 3.303], [63576.2, 0.051], [63801.3, 2.065], [63930.4, 0.0], [64468.9, 0.022], [64486.5, 29.512], [64488.7, 0.0], [64551.2, 0.168], [64558.2, 0.002], [64559.1, 0.001], [64559.2, 0.007], [64560.3, 0.098], [64563.5, 0.079], [64563.6, 0.02], [64569.4, 2.329], [64569.5, 0.003], [64570.0, 0.02], [64570.1, 0.713], [64570.2, 0.004], [64570.3, 0.001], [64570.4, 1.903], [64570.5, 1.733], [64570.6, 2.745], [64570.7, 0.014], [64570.9, 0.151], [64571.0, 0.003], [64571.9, 0.002], [64572.1, 0.019], [64572.2, 0.009], [64572.3, 0.088], [64572.9, 0.002], [64573.0, 0.0], [64573.1, 0.002], [64573.5, 0.085], [64573.9, 0.352], [64575.2, 0.109]], "asks": [[64576.8, 0.0], [64578.1, 0.007], [64579.0, 0.066], [64579.7, 0.089], [64580.4, 2.32], [64593.1, 0.042], [64593.5, 0.0], [64594.1, 1.173], [65222.1, 3.05], [65383.5, 1.286], [65448.1, 1.157], [65576.3, 0.024]]}
{"kind": "depth", "E": 1787088869795, "U": 11315947928035, "u": 11315947932607, "recv_ms": 1787088869741, "bids": [[1000.0, 35.76], [14276.2, 2.968], [14376.2, 1.232], [51661.0, 0.0], [58118.5, 0.002], [61347.3, 0.001], [61993.1, 0.0], [63930.4, 0.0], [64059.6, 1.249], [64434.0, 0.0], [64486.5, 0.106], [64488.7, 29.406], [64552.6, 0.008], [64560.3, 0.114], [64563.5, 0.087], [64563.6, 0.012], [64569.5, 0.003], [64570.3, 0.001], [64570.4, 0.0], [64570.6, 0.569], [64570.7, 2.174], [64573.5, 0.001], [64573.9, 0.268], [64576.2, 6.449]], "asks": [[64576.3, 29.559], [64579.0, 0.056], [64579.6, 0.154], [64579.7, 0.002], [64580.4, 2.397], [64598.9, 0.34], [64605.1, 0.313], [64605.2, 0.232], [64605.3, 0.026], [64606.5, 0.004], [64608.1, 2.206], [64608.2, 5.299], [64608.3, 0.156], [64609.0, 0.019], [64609.1, 0.002], [64609.2, 0.002], [64611.1, 0.002], [64611.2, 0.022], [64611.3, 0.003], [64716.1, 0.0], [65222.1, 3.05]]}
{"kind": "depth", "E": 1787088869897, "U": 11315947932655, "u": 11315947936544, "recv_ms": 1787088869844, "bids": [[14276.2, 3.318], [14376.2, 0.882], [58118.5, 0.0], [61993.1, 0.003], [63284.7, 0.01], [63576.2, 0.031], [63721.8, 2.663], [63930.4, 0.0], [64114.3, 0.249], [64253.3, 0.868], [64434.2, 4.434], [64435.1, 0.94], [64551.2, 0.168], [64570.7, 2.174]], "asks": [[64576.3, 29.562], [64716.2, 7.102], [64771.8, 0.001], [64771.9, 10.945], [64899.2, 0.463], [65222.1, 3.05], [65512.7, 2.288], [65576.3, 0.004], [65867.8, 1.534]]}
{"kind": "depth", "E": 1787088869999, "U": 11315947936546, "u": 11315947940158, "recv_ms": 1787088869946, "bids": [[1000.0, 35.76], [14276.2, 3.682], [14376.2, 0.518], [58118.5, 0.002], [63930.4, 0.0], [64235.4, 0.0], [64235.6, 0.493], [64570.7, 2.174]], "asks": [[64691.3, 0.088], [64880.5, 0.004], [65222.1, 3.05]]}
{"kind": "depth", "E": 1787088870101, "U": 11315947940265, "u": 11315947944771, "recv_ms": 1787088870047, "bids": [[1000.0, 35.76], [14176.2, 0.14], [14276.2, 3.752], [14376.2, 0.308], [58118.5, 0.002], [61993.1, 0.0], [63181.2, 0.684], [63576.2, 0.051], [63639.8, 7.376], [63930.4, 0.0], [64551.2, 0.168], [64564.6, 0.465], [64567.7, 0.329], [64568.4, 0.282], [64569.4, 2.413], [64570.0, 0.023], [64570.7, 0.014], [64572.0, 0.304], [64572.7, 0.084]], "asks": [[65222.1, 3.05], [65351.2, 5.225], [65576.3, 0.024], [66525.9, 0.004]]}
{"kind": "depth", "E": 1787088870203, "U": 11315947944960, "u": 11315947949284, "recv_ms": 1787088870149, "bids": [[14176.2, 0.392], [14276.2, 3.612], [14376.2, 0.196], [58118.5, 0.002], [61993.1, 0.003], [63930.4, 0.0], [64253.3, 0.868], [64434.2, 0.0], [64488.1, 0.002], [64488.8, 7.608], [64530.9, 0.136], [64570.7, 0.014]], "asks": [[64581.1, 0.017], [64634.5, 1.476], [64716.2, 1.694], [64733.0, 2.595], [64734.0, 0.001], [65222.1, 3.05], [65415.8, 3.053], [65588.0, 6.465], [66520.2, 0.643]]}
{"kind": "depth", "E": 1787088870305, "U": 11315947949539, "u": 11315947955461, "recv_ms": 1787088870252, "bids": [[1000.0, 35.76], [14176.2, 0.63], [14276.2, 3.5], [14376.2, 0.07], [51661.0, 0.0], [58118.5, 0.002], [61347.3, 0.001], [61993.1, 0.0], [63576.2, 0.031], [63736.7, 3.133], [63930.4, 0.0], [63995.0, 3.505], [64434.2, 4.434], [64483.6, 2.337], [64514.2, 0.036], [64518.0, 0.254], [64526.1, 0.004], [64527.0, 0.099], [64560.3, 0.114], [64563.5, 0.636], [64569.5, 0.001], [64570.4, 0.002], [64570.5, 0.185], [64570.6, 0.004], [64570.7, 0.014], [64570.9, 0.089], [64571.0, 1.903], [64571.1, 0.07], [64572.1, 0.019], [64572.2, 0.017], [64572.7, 0.0], [64572.9, 1.558], [64573.1, 0.002], [64573.7, 0.002], [64575.2, 0.159], [64575.4, 0.007]], "asks": [[64576.3, 29.576], [64577.6, 0.028], [64577.7, 0.113], [64629.5, 0.04], [64630.4, 0.067], [64653.8, 0.005], [64713.6, 2.118], [64716.2, 7.102], [64733.1, 6.92], [64771.9, 10.946], [65157.5, 6.388], [65222.1, 3.05], [65576.3, 0.004], [65763.8, 2.277], [66521.5, 2.177]]}
{"kind": "depth", "E": 1787088870407, "U": 11315947955513, "u": 11315947959896, "recv_ms": 1787088870353, "bids": [[1000.0, 35.76], [14176.2, 0.91], [14276.2, 3.29], [14376.2, 0.0], [58118.5, 0.002], [61347.3, 0.002], [63805.5, 28.538], [63930.4, 0.0], [64063.9, 7.792], [64253.3, 0.869], [64552.9, 0.693], [64560.3, 0.106], [64563.6, 0.02], [64569.5, 0.003], [64570.4, 0.0], [64571.1, 1.618], [64571.2, 0.143], [64572.2, 0.009], [64572.9, 0.002], [64573.2, 0.002], [64574.9, 0.014], [64575.2, 0.109]], "asks": [[64576.3, 29.576], [64576.8, 0.007], [64577.8, 0.053], [64578.1, 0.0], [64579.7, 0.079], [64580.4, 2.32], [64583.2, 0.312], [64584.5, 0.003], [64599.2, 0.646], [64606.5, 0.623], [64733.1, 10.428], [64899.2, 0.462], [65222.1, 3.05], [66195.2, 4.3]]}
{"kind": "depth", "E": 1787088870509, "U": 11315947960062, "u": 11315947963898, "recv_ms": 1787088870456, "bids": [[14176.2, 1.274], [14276.2, 2.926], [58118.5, 0.002], [61347.3, 0.001], [61347.4, 0.006], [61347.5, 0.002], [61993.1, 0.003], [63576.2, 0.051], [63754.2, 9.087], [63805.5, 28.068], [63930.4, 0.0], [64063.9, 7.48], [64253.3, 0.869], [64559.1, 0.009], [64560.3, 0.106], [64563.6, 0.012], [64570.0, 0.02], [64571.1, 0.008], [64571.2, 0.189], [64572.1, 0.019], [64572.2, 0.017], [64572.3, 1.636], [64572.9, 0.01]], "asks": [[64577.8, 0.075], [64589.9, 0.033], [64591.6, 0.004], [64650.1, 1.537], [64651.3, 0.004], [64659.8, 7.561], [64662.3, 46.831], [65222.1, 3.05], [65388.0, 27.155], [65576.3, 0.024]]}
{"kind": "depth", "E": 1787088870611, "U": 11315947963926, "u": 11315947968498, "recv_ms": 1787088870635, "bids": [[1000.0, 35.76], [14176.2, 1.624], [14276.2, 2.576], [58118.5, 0.002], [61993.1, 0.0], [63773.3, 19.886], [63930.4, 0.002], [64559.4, 0.021], [64560.3, 0.098], [64563.6, 0.012], [64571.1, 0.008], [64571.2, 0.127], [64571.3, 1.632], [64571.4, 0.062], [64572.1, 0.019], [64572.2, 0.009], [64572.3, 0.088], [64572.4, 0.008], [64572.5, 0.001], [64572.9, 0.002]], "asks": [[64591.8, 1.24], [64653.5, 47.19], [64659.8, 0.892], [64662.3, 0.0], [65222.1, 3.05], [66190.7, 0.075]]}
{"kind": "depth", "E": 1787088870713, "U": 11315947968536, "u": 11315947973221, "recv_ms": 1787088870661, "bids": [[1000.0, 35.76], [14176.2, 1.974], [14276.2, 2.226], [58118.5, 0.002], [61347.3, 0.001], [61993.1, 0.003], [63284.7, 0.013], [63576.2, 0.031], [63644.1, 10.474], [63663.6, 1.639], [63801.3, 2.691], [63930.4, 0.0], [64059.6, 1.873], [64559.1, 0.001], [64560.3, 0.106], [64563.5, 0.636], [64563.6, 0.02], [64565.1, 0.002], [64566.4, 0.881], [64569.3, 0.035], [64569.5, 0.001], [64569.7, 1.152], [64569.8, 0.293], [64570.2, 1.571], [64570.9, 0.086], [64571.0, 0.003], [64571.3, 0.084], [64571.4, 0.0], [64571.9, 0.005], [64572.1, 0.019], [64572.2, 0.009], [64572.8, 0.611], [64572.9, 2.162], [64573.1, 0.312], [64573.7, 0.086], [64574.1, 0.09], [64575.2, 0.399], [64576.2, 6.447]], "asks": [[64576.3, 29.582], [64576.8, 0.0], [64578.1, 0.007], [64579.7, 0.002], [64580.4, 2.397], [64580.6, 43.196], [64581.1, 0.016], [64583.2, 0.003], [64584.5, 0.312], [64589.9, 0.025], [64591.6, 0.012], [64771.9, 10.504], [65222.1, 3.05], [65576.3, 0.004], [71033.9, 0.008]]}
{"kind": "depth", "E": 1787088870815, "U": 11315947973288, "u": 11315947977668, "recv_ms": 1787088870835, "bids": [[14176.2, 2.338], [14276.2, 1.862], [51661.0, 0.0], [58118.5, 0.002], [61993.1, 0.0], [63736.7, 5.482], [63930.4, 0.0], [64253.3, 0.869], [64559.1, 0.001], [64560.3, 0.098], [64563.5, 0.002], [64563.6, 0.012], [64565.1, 0.312], [64566.4, 0.571], [64569.3, 0.033], [64569.7, 0.0], [64569.8, 0.231], [64569.9, 0.008], [64570.1, 0.715], [64570.2, 0.004], [64570.3, 0.001], [64570.4, 2.476], [64570.5, 0.247], [64570.6, 0.089], [64571.1, 0.008], [64571.9, 0.002], [64572.1, 0.332], [64572.2, 2.114], [64572.8, 1.283], [64572.9, 0.01], [64573.0, 0.002], [64573.1, 0.002], [64573.7, 0.002], [64573.8, 0.002], [64574.1, 0.006], [64575.2, 0.181]], "asks": [[64576.8, 0.0], [64578.0, 0.053], [64578.1, 0.0], [64579.7, 0.002], [64580.3, 1.013], [64580.4, 2.32], [64589.9, 0.025], [64591.6, 0.004], [64767.9, 0.0], [65222.1, 3.05], [65530.6, 7.932], [71033.9, 0.006]]}
{"kind": "depth", "E": 1787088870917, "U": 11315947977670, "u": 11315947981811, "recv_ms": 1787088870865, "bids": [[1000.0, 35.76], [14176.2, 2.688], [14276.2, 1.512], [58118.5, 0.002], [63349.2, 0.956], [63576.2, 0.051], [63729.6, 1.568], [63769.0, 3.17], [63930.4, 0.0], [64033.8, 0.099], [64235.6, 0.0], [64235.8, 0.493], [64253.3, 0.868], [64533.2, 0.0], [64541.0, 0.701], [64559.1, 0.009], [64560.3, 0.106], [64563.5, 0.087], [64569.1, 0.124], [64569.5, 0.001], [64569.9, 0.005], [64570.1, 0.713], [64570.3, 0.003], [64570.4, 1.9], [64570.5, 0.185], [64570.6, 0.553], [64570.7, 1.562], [64570.8, 0.022], [64570.9, 0.148], [64571.1, 0.011], [64572.1, 0.019], [64572.2, 0.009], [64572.3, 0.004], [64572.9, 0.002], [64573.0, 0.002], [64575.2, 0.122]], "asks": [[64578.3, 0.021], [64579.5, 0.011], [64589.9, 0.033], [64903.5, 4.154], [65054.0, 0.044], [65097.2, 7.208], [65207.5, 7.36], [65222.1, 3.05], [65362.0, 0.039], [65576.3, 0.024], [65638.0, 0.011], [65958.0, 0.108], [67809.6, 0.0]]}
{"kind": "depth", "E": 1787088871019, "U": 11315947981926, "u": 11315947987154, "recv_ms": 1787088871015, "bids": [[1000.0, 35.76], [14176.2, 3.052], [14276.2, 1.148], [58118.5, 0.002], [61347.3, 0.001], [61993.1, 0.003], [63639.8, 8.474], [63676.5, 51.586], [63689.6, 25.087], [63812.1, 2.778], [63930.4, 0.0], [64434.2, 0.0], [64434.3, 4.474], [64551.1, 0.156], [64551.2, 0.014], [64569.5, 0.001], [64570.3, 0.003], [64570.8, 0.022], [64572.0, 0.388]], "asks": [[64576.3, 29.582], [64578.3, 0.011], [64579.5, 0.001], [64713.6, 1.517], [64716.2, 7.102], [64771.9, 10.156], [64899.2, 0.463], [65222.1, 3.05], [65480.4, 3.476], [65512.7, 3.355]]}
{"kind": "depth", "E": 1787088871121, "U": 11315947987222, "u": 11315947993491, "recv_ms": 1787088871067, "bids": [[14176.2, 3.402], [14276.2, 0.798], [58118.5, 0.002], [61993.1, 0.0], [63576.2, 0.031], [63837.8, 3.757], [63930.4, 0.002], [64253.3, 0.868], [64473.1, 0.004], [64479.3, 3.106], [64479.4, 1.483], [64525.0, 0.22], [64564.6, 0.465], [64569.5, 0.003], [64570.3, 0.001], [64570.8, 0.022], [64575.7, 0.016]], "asks": [[64581.5, 0.004], [64768.6, 0.632], [64899.2, 0.617], [65092.9, 1.844], [65222.1, 3.05], [65452.5, 14.432], [65517.0, 17.021], [65576.3, 0.004]]}
{"kind": "depth", "E": 1787088871223, "U": 11315947993549, "u": 11315947998690, "recv_ms": 1787088871169, "bids": [[1000.0, 35.76], [14076.2, 0.028], [14176.2, 3.71], [14276.2, 0.462], [51661.0, 0.002], [58118.5, 0.002], [61347.3, 0.001], [61993.1, 0.003], [63672.1, 2.54], [63807.7, 4.852], [63930.4, 0.0], [64435.1, 1.503], [64460.2, 0.001], [64460.3, 4.62], [64471.6, 0.1], [64473.1, 4.358], [64504.4, 0.046], [64559.1, 0.001], [64560.3, 0.106], [64563.5, 0.095], [64569.5, 0.003], [64570.3, 0.004], [64570.5, 0.185], [64570.8, 2.182], [64572.5, 0.311], [64573.2, 0.086]], "asks": [[64576.3, 29.582], [64577.7, 0.179], [64579.0, 0.074], [64582.0, 0.017], [64583.6, 0.007], [64589.9, 0.025], [64591.6, 0.012], [64646.5, 0.001], [64646.6, 0.051], [64710.6, 1.078], [64710.7, 6.195], [64774.6, 0.803], [65189.8, 2.586], [65222.1, 3.05], [65448.1, 2.682], [65867.8, 1.531]]}
{"kind": "depth", "E": 1787088871325, "U": 11315947998828, "u": 11315948005206, "recv_ms": 1787088871271, "bids": [[14076.2, 0.21], [14176.2, 3.71], [14276.2, 0.28], [51661.0, 0.0], [58118.5, 0.002], [61993.1, 0.0], [63576.2, 0.051], [63930.4, 0.0], [64559.1, 0.009], [64560.3, 0.106], [64563.5, 0.087], [64566.9, 0.033], [64569.3, 0.035], [64569.5, 0.001], [64570.3, 0.001], [64570.4, 0.0], [64570.8, 2.182], [64572.0, 0.304], [64572.5, 0.001], [64572.8, 0.68], [64573.2, 0.002]], "asks": [[64589.9, 0.033], [64591.6, 0.004], [64733.1, 7.659], [65222.1, 3.05], [65576.3, 0.024]]}
{"kind": "depth", "E": 1787088871427, "U": 11315948005262, "u": 11315948010426, "recv_ms": 1787088871374, "bids": [[14076.2, 0.448], [14176.2, 3.584], [14276.2, 0.168], [51661.0, 0.0], [58118.5, 0.002], [63721.5, 3.526], [63779.7, 2.35], [63801.3, 3.161], [63833.6, 3.755], [63837.8, 2.818], [63930.4, 0.0], [63980.2, 6.532], [64033.8, 0.068], [64253.3, 0.867], [64257.6, 6.034], [64488.7, 0.0], [64488.8, 0.003], [64490.9, 30.0], [64492.5, 5.564], [64498.7, 0.004], [64505.3, 0.014], [64518.0, 0.251], [64527.9, 0.027], [64528.0, 1.23], [64530.9, 0.133], [64544.0, 0.045], [64560.3, 0.106], [64563.5, 0.087], [64569.3, 0.033], [64569.5, 0.003], [64570.0, 0.02], [64570.2, 1.552], [64570.3, 2.26], [64570.4, 2.16], [64570.6, 0.011], [64570.7, 0.014], [64570.8, 0.022], [64572.1, 0.103], [64572.8, 1.186]], "asks": [[64583.2, 0.312], [64584.5, 0.003], [64598.2, 0.352], [64611.9, 0.588], [64614.4, 0.024], [64634.5, 1.476], [64637.0, 0.037], [64651.3, 47.587], [64653.5, 0.0], [64653.8, 0.002], [65222.1, 3.05], [65512.7, 4.422]]}
{"kind": "depth", "E": 1787088871529, "U": 11315948010582, "u": 11315948015138, "recv_ms": 1787088871475, "bids": [[1000.0, 35.76], [14076.2, 0.672], [14176.2, 3.486], [14276.2, 0.042], [58118.5, 0.002], [61347.3, 0.001], [61347.4, 0.004], [61347.5, 0.004], [61993.1, 0.003], [63224.4, 2.37], [63528.1, 1.861], [63576.2, 0.031], [63704.4, 4.182], [63930.4, 0.0], [64434.3, 0.0], [64434.4, 4.495], [64468.9, 0.022], [64473.0, 0.017], [64473.1, 0.004], [64488.7, 29.75], [64490.9, 0.424], [64492.5, 1.173], [64514.2, 0.05], [64550.0, 0.97], [64552.9, 0.074], [64559.1, 0.001], [64560.3, 0.106], [64563.5, 0.002], [64565.1, 0.002], [64566.4, 0.881], [64569.5, 0.003], [64569.9, 0.008], [64570.1, 0.713], [64570.3, 2.836], [64570.4, 0.093], [64571.1, 0.008], [64571.9, 0.005], [64572.1, 2.263], [64572.5, 0.311], [64573.2, 0.086]], "asks": [[64576.3, 29.743], [64579.7, 0.002], [64583.2, 0.003], [64584.5, 0.312], [64589.9, 0.025], [64591.5, 0.009], [64668.8, 1.473], [64669.3, 0.05], [64716.2, 7.102], [64733.1, 10.428], [64771.9, 9.987], [64899.2, 0.618], [65222.1, 3.05], [65355.6, 20.424], [65388.0, 26.811], [65576.3, 0.004]]}
{"kind": "depth", "E": 1787088871631, "U": 11315948015287, "u": 11315948020703, "recv_ms": 1787088871578, "bids": [[14076.2, 0.994], [14176.2, 3.206], [14276.2, 0.0], [58118.5, 0.002], [61993.1, 0.0], [63576.2, 0.051], [63703.8, 1.963], [63833.6, 4.694], [63930.4, 0.002], [63962.7, 0.78], [64434.4, 0.0], [64505.2, 6.001], [64514.2, 0.036], [64527.8, 3.539], [64543.9, 0.999], [64559.4, 0.021], [64563.5, 0.544], [64563.6, 0.096], [64569.1, 0.04], [64569.4, 2.329], [64569.5, 0.001], [64570.1, 0.713], [64570.2, 0.006], [64570.3, 1.718], [64570.4, 1.58], [64570.6, 0.004], [64570.8, 0.006], [64572.1, 0.103], [64572.2, 0.009], [64572.8, 0.68], [64572.9, 0.002], [64573.0, 0.002], [64573.6, 0.086], [64574.0, 0.092], [64575.2, 0.38]], "asks": [[64576.3, 29.823], [64580.7, 1.493], [64591.8, 1.24], [64598.4, 0.994], [64614.5, 1.765], [64614.6, 3.5], [64615.6, 0.02], [64637.2, 6.0], [64716.2, 1.694], [65222.1, 3.052], [65576.3, 0.024], [65867.8, 1.534]]}
{"kind": "depth", "E": 1787088871733, "U": 11315948020717, "u": 11315948025510, "recv_ms": 1787088871681, "bids": [[14076.2, 1.358], [14176.2, 2.842], [58118.5, 0.002], [61347.3, 0.001], [61993.1, 0.003], [63773.3, 19.652], [63930.4, 0.0], [64253.3, 1.032], [64434.4, 3.999], [64472.9, 10.049], [64524.9, 0.01], [64559.1, 0.009], [64560.3, 0.106], [64563.5, 0.644], [64563.6, 0.012], [64565.1, 0.312], [64566.4, 0.571], [64569.5, 0.001], [64569.7, 0.002], [64569.9, 0.005], [64570.2, 0.004], [64570.4, 0.0], [64570.5, 0.185], [64570.6, 0.004], [64570.7, 1.562], [64571.1, 0.008], [64571.9, 0.002], [64572.1, 0.106], [64572.2, 0.009], [64572.7, 0.084], [64572.8, 0.68], [64572.9, 2.17], [64573.0, 0.002], [64573.2, 0.002], [64573.6, 0.002], [64573.9, 0.268], [64574.0, 0.008], [64575.2, 0.366]], "asks": [[64576.3, 29.823], [64579.0, 0.084], [64579.7, 0.012], [64589.9, 0.033], [64591.5, 0.001], [64671.0, 10.014], [64716.2, 7.102], [64733.1, 0.001], [64733.2, 7.648], [64771.9, 11.425], [65222.1, 3.05]]}
{"kind": "depth", "E": 1787088871835, "U": 11315948025572, "u": 11315948032201, "recv_ms": 1787088871781, "bids": [[1000.0, 35.76], [14076.2, 1.708], [14176.2, 2.492], [51661.0, 0.0], [58118.5, 0.002], [61347.3, 0.001], [63220.1, 0.316], [63510.7, 2.516], [63708.8, 19.042], [63930.4, 0.0], [64563.5, 0.087], [64570.8, 0.563], [64570.9, 2.254], [64571.0, 0.065], [64571.1, 0.011], [64572.1, 0.103], [64572.8, 1.245], [64572.9, 0.002], [64573.1, 0.086], [64575.2, 0.109], [64576.2, 6.449]], "asks": [[64581.5, 0.003], [64607.7, 0.276], [64608.3, 0.002], [65222.1, 3.05], [65351.2, 5.835], [65360.2, 2.609], [65388.0, 26.552]]}
{"kind": "depth", "E": 1787088871937, "U": 11315948032356, "u": 11315948037653, "recv_ms": 1787088871885, "bids": [[14076.2, 2.058], [14176.2, 2.142], [58118.5, 0.002], [61993.1, 0.0], [63576.2, 0.031], [63579.5, 4.397], [63644.1, 9.375], [63799.3, 21.856], [63837.8, 1.879], [63930.4, 0.0], [64235.8, 0.0], [64236.0, 0.616], [64555.3, 0.116], [64556.3, 0.013], [64556.6, 0.116], [64556.7, 0.563], [64557.6, 0.0], [64558.2, 0.009], [64559.1, 0.001], [64559.2, 0.0], [64560.3, 0.106], [64561.0, 0.013], [64563.0, 2.863], [64563.5, 0.095], [64570.9, 0.094], [64572.1, 2.263], [64573.9, 0.352]], "asks": [[64579.0, 0.074], [64579.7, 0.002], [64589.9, 0.025], [64591.5, 0.009], [64597.3, 0.02], [64597.9, 0.558], [64598.7, 0.063], [64599.1, 1.509], [64607.7, 0.43], [64607.8, 0.174], [64607.9, 0.0], [64733.2, 10.427], [65413.8, 0.0], [65576.3, 0.004]]}
{"kind": "depth", "E": 1787088872039, "U": 11315948037868, "u": 11315948043946, "recv_ms": 1787088871986, "bids": [[14076.2, 2.422], [14176.2, 1.778], [58118.5, 0.002], [61347.4, 0.006], [61993.1, 0.003], [63704.4, 4.808], [63773.3, 19.301], [63930.4, 0.0], [64253.3, 1.023], [64468.9, 29.772], [64488.7, 0.0], [64559.1, 0.009], [64560.3, 0.106], [64563.5, 0.002], [64563.6, 0.097], [64564.6, 0.47], [64569.4, 2.413], [64570.4, 0.007], [64570.5, 0.743], [64570.6, 1.552], [64570.7, 0.014], [64570.8, 0.006], [64570.9, 0.086], [64572.1, 0.103], [64572.5, 0.001], [64572.7, 0.0], [64572.8, 1.035], [64572.9, 0.002], [64573.0, 0.002], [64573.1, 0.002], [64573.9, 0.268], [64575.2, 0.109]], "asks": [[64589.9, 0.033], [64591.5, 0.001], [64607.7, 0.276], [64607.8, 0.328], [64899.2, 0.617], [65222.1, 3.05], [65351.3, 1.615], [65505.4, 5.286], [65745.8, 0.76]]}
{"kind": "depth", "E": 1787088872141, "U": 11315948044032, "u": 11315948049752, "recv_ms": 1787088872087, "bids": [[1000.0, 35.76], [14076.2, 2.772], [14176.2, 1.428], [51661.0, 0.0], [58118.5, 0.002], [61347.3, 0.001], [61993.1, 0.0], [63284.7, 0.01], [63463.5, 2.521], [63576.2, 0.051], [63801.3, 3.631], [63930.4, 0.0], [64468.9, 0.022], [64486.5, 29.953], [64528.9, 0.028], [64530.9, 0.136], [64541.8, 0.388], [64564.6, 0.465], [64570.7, 2.174], [64572.4, 0.092]], "asks": [[64576.3, 29.823], [64579.0, 0.084], [64579.7, 0.012], [64580.6, 43.195], [64581.6, 0.016], [64653.8, 0.005], [65222.1, 3.05], [65576.3, 0.024], [65867.8, 1.531]]}
{"kind": "depth", "E": 1787088872243, "U": 11315948049958, "u": 11315948055414, "recv_ms": 1787088872190, "bids": [[14076.2, 3.136], [14176.2, 1.064], [51661.0, 0.0], [58118.5, 0.002], [61347.3, 0.001], [61351.6, 2.445], [61993.1, 0.003], [63575.3, 1.755], [63639.8, 9.573], [63773.3, 18.949], [63833.6, 5.633], [63930.4, 0.0], [64419.1, 1.732], [64460.3, 4.113], [64460.4, 1.395], [64486.5, 0.106], [64487.3, 0.628], [64488.7, 29.847], [64506.4, 0.0], [64516.7, 0.014], [64559.1, 0.001], [64560.3, 0.106], [64563.5, 0.01], [64567.5, 0.249], [64570.3, 0.001], [64570.7, 0.014], [64571.0, 1.903], [64571.1, 0.073], [64572.1, 2.263], [64573.1, 0.312], [64573.3, 0.091], [64573.4, 0.0], [64575.2, 0.16]], "asks": [[64576.3, 29.826], [64589.9, 0.025], [64591.5, 0.009], [64650.1, 8.183], [64668.8, 3.155], [64713.6, 2.118], [65222.1, 3.05], [65383.5, 1.545]]}
{"kind": "depth", "E": 1787088872345, "U": 11315948055523, "u": 11315948061952, "recv_ms": 1787088872292, "bids": [[1000.0, 35.91], [14076.2, 3.486], [14176.2, 0.714], [51661.0, 0.0], [58118.5, 0.002], [61347.3, 0.001], [63446.1, 1.272], [63576.2, 0.031], [63769.0, 3.404], [63786.4, 4.701], [63812.0, 5.523], [63930.4, 0.0], [64033.8, 0.031], [64253.3, 1.033], [64511.6, 0.031], [64518.0, 0.254], [64537.4, 0.207], [64550.0, 0.351], [64559.1, 0.009], [64560.3, 0.106], [64563.5, 0.002], [64563.6, 0.097], [64569.3, 0.033], [64569.5, 0.003], [64569.7, 0.0], [64570.1, 0.713], [64570.2, 1.568], [64570.3, 2.45], [64570.4, 2.16], [64570.5, 0.185], [64570.6, 0.004], [64571.0, 0.003], [64572.1, 0.103], [64572.2, 0.009], [64572.8, 1.225], [64572.9, 0.002], [64573.1, 0.002], [64573.3, 0.007], [64575.2, 0.109]], "asks": [[64576.3, 29.679], [64579.0, 0.074], [64579.7, 0.012], [64589.9, 0.033], [64591.5, 0.001], [64599.2, 0.027], [64640.9, 0.005], [64686.1, 0.003], [65222.1, 3.05], [65388.0, 26.324], [65576.3, 0.004]]}
{"kind": "depth", "E": 1787088872447, "U": 11315948061990, "u": 11315948067347, "recv_ms": 1787088872392, "bids": [[1000.0, 35.76], [14076.2, 3.738], [14176.2, 0.406], [14476.2, 0.056], [58118.5, 0.002], [61347.3, 0.002], [61993.1, 0.0], [63659.2, 0.234], [63930.4, 0.002], [64569.5, 0.003], [64570.1, 0.713], [64570.4, 0.0]], "asks": [[64576.3, 29.832], [64579.7, 0.002], [64597.0, 0.558], [64597.9, 0.001], [64606.5, 0.004], [65222.1, 3.05]]}
{"kind": "depth", "E": 1787088872549, "U": 11315948067435, "u": 11315948072210, "recv_ms": 1787088872495, "bids": [[14076.2, 3.682], [14176.2, 0.252], [14476.2, 0.266], [58118.5, 0.002], [61347.3, 0.001], [61993.1, 0.003], [63576.2, 0.051], [63930.4, 0.0], [64560.0, 0.206], [64570.4, 2.16], [64572.2, 0.319], [64573.1, 0.002]], "asks": [[64899.2, 0.616], [65222.1, 3.05], [65388.0, 26.065], [65576.3, 0.024], [65867.8, 1.534]]}
{"kind": "depth", "E": 1787088872651, "U": 11315948072252, "u": 11315948076857, "recv_ms": 1787088872598, "bids": [[1000.0, 35.76], [14076.2, 3.556], [14176.2, 0.14], [14476.2, 0.504], [50000.0, 233.329], [58118.5, 0.002], [61347.4, 0.004], [61347.5, 0.006], [61993.1, 0.0], [63807.7, 5.791], [63930.4, 0.0], [64253.3, 1.024], [64506.4, 0.009], [64516.7, 0.028], [64533.2, 0.004], [64534.8, 0.018], [64541.0, 0.697], [64559.1, 0.001], [64559.4, 0.021], [64560.3, 0.106], [64563.6, 0.012], [64569.5, 0.001], [64569.9, 0.008], [64570.1, 0.715], [64570.4, 0.0], [64570.5, 0.278], [64571.1, 0.07], [64571.9, 0.005], [64573.6, 0.086]], "asks": [[64579.7, 0.012], [64580.6, 43.178], [64589.9, 0.025], [64591.5, 0.009], [64591.8, 1.24], [64771.9, 11.532], [65222.1, 3.05]]}
{"kind": "depth", "E": 1787088872753, "U": 11315948076924, "u": 11315948081772, "recv_ms": 1787088872700, "bids": [[1000.0, 35.76], [14076.2, 3.458], [14176.2, 0.014], [14476.2, 0.728], [58118.5, 0.002], [61347.3, 0.001], [61993.1, 0.003], [63576.2, 0.031], [63617.9, 1.57], [63672.1, 2.728], [63930.4, 0.0], [64451.2, 2.395], [64468.9, 29.869], [64488.7, 0.0], [64498.7, 0.004], [64518.0, 0.251], [64530.9, 0.133], [64552.9, 0.693], [64569.4, 2.329], [64569.7, 0.002], [64570.1, 0.713], [64570.2, 0.004], [64570.3, 2.45], [64570.4, 1.564], [64572.1, 2.263], [64572.3, 0.004], [64572.8, 0.68], [64572.9, 0.002], [64573.0, 0.002], [64574.0, 0.092], [64575.2, 0.359]], "asks": [[64576.3, 29.832], [64579.7, 0.002], [64580.7, 1.492], [64595.7, 1.127], [64599.2, 0.646], [64606.5, 0.623], [64607.7, 0.276], [64607.8, 0.328], [64634.5, 1.476], [64653.8, 0.002], [64686.1, 0.0], [64710.3, 0.021], [65097.2, 6.901], [65222.1, 3.05], [65576.3, 0.004], [65667.6, 1.216], [65685.5, 0.76]]}
{"kind": "depth", "E": 1787088872855, "U": 11315948081912, "u": 11315948086571, "recv_ms": 1787088872801, "bids": [[14076.2, 3.122], [14176.2, 0.0], [14476.2, 1.078], [51661.0, 0.0], [58118.5, 0.002], [63930.4, 0.0], [64447.0, 1.833], [64468.9, 0.022], [64486.5, 29.953], [64563.5, 0.628], [64570.3, 1.901], [64570.4, 3.74], [64570.5, 0.185], [64571.9, 0.004], [64572.1, 0.103], [64572.2, 0.319], [64572.3, 0.004], [64572.8, 0.68], [64572.9, 0.002], [64573.8, 0.003], [64575.2, 0.357]], "asks": [[64708.5, 1.272], [64768.4, 5.149], [64768.6, 0.002], [65222.1, 3.051], [65867.8, 1.537]]}
{"kind": "depth", "E": 1787088872957, "U": 11315948086640, "u": 11315948090360, "recv_ms": 1787088872903, "bids": [[1000.0, 35.76], [14076.2, 2.772], [14476.2, 1.428], [58118.5, 0.002], [61347.3, 0.001], [61993.1, 0.0], [63576.2, 0.051], [63773.3, 18.684], [63930.4, 0.0], [64033.8, 0.0], [64236.0, 0.123], [64236.1, 0.493], [64253.3, 1.034], [64378.4, 0.115], [64378.9, 4.966], [64417.1, 0.006], [64417.6, 3.396], [64434.4, 0.0], [64434.6, 3.643], [64512.8, 0.028], [64551.0, 0.19], [64551.1, 0.002], [64563.5, 0.002], [64569.7, 0.0], [64570.3, 0.003], [64570.4, 0.635], [64570.5, 0.185], [64570.6, 0.011], [64572.3, 0.004], [64572.7, 0.001], [64572.8, 1.286], [64572.9, 1.566], [64573.8, 0.002], [64575.2, 0.134]], "asks": [[64576.3, 29.832], [64639.3, 0.002], [64771.9, 0.0], [64772.0, 15.532], [65092.9, 2.765], [65097.2, 5.98], [65222.1, 3.051], [65576.3, 0.024]]}
{"kind": "depth", "E": 1787088873059, "U": 11315948090458, "u": 11315948094549, "recv_ms": 1787088873006, "bids": [[1000.0, 35.76], [14076.2, 2.408], [14476.2, 1.792], [58118.5, 0.0], [61347.3, 0.001], [61993.1, 0.003], [63930.4, 0.0], [64063.9, 7.168], [64253.3, 1.033], [64378.9, 10.794], [64417.6, 5.336], [64434.6, 4.967], [64486.5, 0.106], [64488.7, 29.763], [64513.0, 2.308], [64514.2, 0.036], [64533.2, 0.0], [64541.0, 0.701], [64558.0, 0.036], [64559.1, 0.001], [64560.3, 0.106], [64563.5, 0.087], [64563.6, 0.012], [64564.6, 0.465], [64569.3, 0.035], [64569.9, 0.005], [64570.2, 1.568], [64570.3, 1.908], [64570.4, 0.542], [64570.6, 0.004], [64571.1, 0.073], [64571.9, 0.001], [64572.3, 2.164], [64572.8, 0.938], [64572.9, 0.002], [64573.0, 0.002], [64573.6, 0.002], [64574.0, 0.008], [64575.2, 0.134]], "asks": [[64576.3, 29.833], [64589.9, 0.033], [64591.5, 0.001], [64639.4, 3.044], [64733.2, 10.427], [64772.0, 10.489], [64899.2, 0.617], [65092.9, 3.072], [65222.1, 3.051], [65498.2, 40.254], [65530.6, 6.865]]}
{"kind": "depth", "E": 1787088873161, "U": 11315948094551, "u": 11315948098770, "recv_ms": 1787088873108, "bids": [[14076.2, 2.058], [14476.2, 2.142], [51661.0, 0.0], [58118.5, 0.002], [61993.1, 0.0], [63576.2, 0.031], [63579.5, 3.298], [63762.1, 0.813], [63930.4, 0.0], [64468.9, 0.022], [64488.7, 29.763], [64497.8, 0.0], [64505.0, 0.837], [64560.3, 0.106], [64563.5, 0.087], [64563.6, 0.012], [64569.3, 0.033], [64569.4, 2.413], [64569.5, 0.001], [64570.1, 0.713], [64570.2, 0.006], [64570.3, 1.901], [64570.4, 2.105], [64570.5, 0.185], [64570.6, 0.012], [64572.2, 0.009], [64572.3, 0.004], [64572.4, 0.008], [64572.9, 0.002], [64575.2, 0.109]], "asks": [[64576.3, 29.833], [64579.0, 0.084], [64579.7, 0.012], [65222.1, 3.051], [65383.5, 1.889], [65576.3, 0.004], [65581.6, 7.569]]}
{"kind": "depth", "E": 1787088873263, "U": 11315948098834, "u": 11315948103804, "recv_ms": 1787088873209, "bids": [[1000.0, 35.76], [14076.2, 1.694], [14476.2, 2.506], [58118.5, 0.002], [63663.6, 1.405], [63811.6, 1.593], [63837.8, 0.941], [63930.4, 0.0], [63999.3, 19.422], [64059.6, 2.185], [64253.3, 1.033], [64488.8, 7.661], [64542.9, 0.0], [64543.5, 1.998], [64567.0, 0.555], [64569.5, 0.003], [64570.2, 0.004], [64570.5, 0.185], [64572.5, 0.085]], "asks": [[64710.6, 1.532], [64903.5, 4.0], [65222.1, 3.051], [65867.8, 1.534]]}
{"kind": "depth", "E": 1787088873365, "U": 11315948103826, "u": 11315948108301, "recv_ms": 1787088873311, "bids": [[1000.0, 35.76], [14076.2, 1.33], [14476.2, 2.87], [58118.5, 0.002], [61347.3, 0.001], [61993.1, 0.003], [63576.2, 0.051], [63586.1, 1.346], [63930.4, 0.0], [64059.6, 2.185], [64417.6, 0.204], [64417.7, 4.143], [64419.1, 1.262], [64434.6, 4.76], [64435.1, 0.94], [64526.8, 0.001], [64527.8, 3.541], [64542.8, 0.008], [64552.9, 0.074], [64569.5, 0.003], [64570.2, 0.004], [64570.5, 2.345], [64576.2, 6.229]], "asks": [[64576.3, 29.846], [64577.2, 0.0], [64579.0, 0.084], [64579.7, 0.012], [64579.8, 0.001], [64597.1, 0.315], [64597.6, 10.003], [64599.2, 0.027], [64606.5, 0.004], [64651.3, 0.004], [64662.3, 47.877], [64713.6, 1.517], [64716.2, 1.694], [64716.3, 5.408], [64733.0, 1.039], [64733.2, 10.427], [65222.1, 3.051], [65304.5, 3.976], [65512.7, 5.489], [65576.3, 0.024]]}
{"kind": "depth", "E": 1787088873467, "U": 11315948108382, "u": 11315948112577, "recv_ms": 1787088873414, "bids": [[14076.2, 0.98], [14476.2, 3.22], [58118.5, 0.002], [61347.4, 0.006], [61993.1, 0.0], [63514.9, 0.001], [63575.3, 2.855], [63644.1, 8.277], [63889.7, 6.284], [63930.4, 0.0], [63993.8, 1.171], [64533.2, 0.004], [64541.0, 0.697], [64569.5, 0.003], [64570.2, 0.004], [64570.5, 2.345]], "asks": [[64650.1, 1.537], [64653.5, 47.877], [64659.8, 0.892], [64662.3, 0.0], [64899.2, 0.771], [65222.1, 3.051], [65383.5, 2.148], [65388.0, 25.837], [65577.2, 2.132]]}
{"kind": "depth", "E": 1787088873569, "U": 11315948112698, "u": 11315948117309, "recv_ms": 1787088873517, "bids": [[1000.0, 35.76], [14076.2, 0.616], [14476.2, 3.584], [58118.5, 0.002], [61347.3, 0.001], [61993.1, 0.003], [63284.7, 0.007], [63576.2, 0.031], [63769.0, 3.638], [63833.6, 6.571], [63930.4, 0.0], [64253.3, 1.032], [64484.9, 0.023], [64485.0, 0.185], [64558.0, 0.028], [64560.3, 0.106], [64563.5, 0.002], [64569.4, 2.329], [64569.5, 0.001], [64570.1, 0.716], [64570.2, 0.006], [64570.4, 1.563], [64570.5, 0.278], [64571.0, 1.903], [64571.1, 0.612], [64571.9, 0.004], [64572.1, 2.263], [64572.4, 0.008], [64572.5, 0.001], [64572.8, 1.332], [64573.9, 0.352], [64574.4, 0.089], [64575.2, 0.185], [64576.2, 6.227]], "asks": [[64576.3, 29.714], [64581.6, 0.015], [64589.9, 0.025], [64591.5, 0.009], [65222.1, 3.051], [65401.3, 2.0], [65576.3, 0.004]]}
{"kind": "depth", "E": 1787088873671, "U": 11315948117326, "u": 11315948122062, "recv_ms": 1787088873618, "bids": [[1000.0, 35.76], [14076.2, 0.35], [14376.2, 0.084], [14476.2, 3.766], [51661.0, 0.0], [58118.5, 0.002], [61347.4, 0.004], [61347.5, 0.006], [61993.1, 0.0], [63773.3, 18.418], [63812.1, 1.839], [63872.3, 2.151], [63889.7, 5.581], [63930.4, 0.0], [64514.2, 0.036], [64551.0, 0.19], [64559.4, 0.021], [64560.3, 0.106], [64563.5, 0.002], [64563.6, 0.012], [64569.3, 0.033], [64570.1, 0.718], [64570.2, 0.004], [64570.3, 2.543], [64570.4, 0.0], [64570.5, 0.185], [64570.6, 0.004], [64570.9, 0.086], [64571.0, 0.003], [64571.1, 0.07], [64572.1, 0.103], [64572.2, 1.573], [64572.8, 1.738], [64572.9, 0.002], [64575.2, 0.193]], "asks": [[64576.3, 29.722], [64579.0, 0.074], [64579.7, 0.002], [64591.8, 1.24], [64651.3, 47.881], [64653.5, 0.0], [64899.2, 0.772], [65222.1, 3.051], [65388.0, 25.578], [65867.8, 1.537]]}
{"kind": "depth", "E": 1787088873773, "U": 11315948122131, "u": 11315948126711, "recv_ms": 1787088873727, "bids": [[14076.2, 0.224], [14376.2, 0.308], [14476.2, 3.668], [58118.5, 0.002], [61347.3, 0.001], [63510.7, 3.617], [63576.2, 0.051], [63639.8, 10.671], [63689.6, 21.168], [63721.8, 2.037], [63872.3, 2.854], [63930.4, 0.0], [64545.6, 0.621], [64552.9, 0.693], [64569.5, 0.001], [64569.7, 0.002], [64570.1, 0.716], [64570.4, 0.0], [64570.5, 0.185], [64570.6, 0.004], [64572.1, 0.103], [64572.2, 0.009], [64572.8, 1.704], [64572.9, 1.566], [64573.0, 0.002], [64573.1, 0.002], [64575.2, 0.133]], "asks": [[64576.3, 29.722], [64599.2, 0.646], [64605.1, 0.311], [64605.2, 0.23], [64605.3, 0.024], [64606.5, 0.623], [64608.1, 2.204], [64608.2, 5.297], [64608.3, 0.0], [64609.0, 0.017], [64609.1, 0.0], [64609.2, 0.0], [64611.1, 0.0], [64611.2, 0.02], [64611.3, 0.001], [64772.0, 10.335], [65222.1, 3.051], [65487.5, 0.765], [65576.3, 0.024], [65867.8, 1.534], [67805.1, 0.008], [71034.0, 0.0]]}
{"kind": "depth", "E": 1787088873875, "U": 11315948126716, "u": 11315948130571, "recv_ms": 1787088873821, "bids": [[1000.0, 35.76], [14076.2, 0.112], [14376.2, 0.56], [14476.2, 3.528], [51661.0, 0.0], [58118.5, 0.002], [61347.3, 0.001], [61351.6, 2.443], [61993.1, 0.003], [63769.0, 4.341], [63807.7, 6.73], [63811.7, 6.264], [63930.4, 0.0], [64253.3, 1.022], [64434.6, 0.78], [64434.7, 4.462], [64552.9, 0.074], [64570.4, 1.564], [64570.5, 0.761], [64571.1, 0.008], [64571.3, 0.146], [64572.1, 2.263], [64572.8, 1.099], [64572.9, 0.002], [64573.0, 0.002], [64573.1, 0.002], [64575.2, 0.133], [64576.2, 6.453]], "asks": [[64576.3, 29.85], [64595.7, 1.003], [64598.4, 0.029], [64599.2, 0.027], [64599.9, 1.629], [64606.5, 0.004], [64607.6, 0.448], [64607.8, 0.174], [64651.3, 0.004], [64662.3, 47.877], [64716.3, 5.408], [65222.1, 3.05], [65859.4, 0.607]]}
{"kind": "depth", "E": 1787088873977, "U": 11315948130656, "u": 11315948134229, "recv_ms": 1787088873925, "bids": [[1000.0, 35.76], [14076.2, 0.0], [14376.2, 0.812], [14476.2, 3.388], [58118.5, 0.002], [61993.1, 0.0], [63576.2, 0.031], [63741.0, 14.804], [63844.0, 0.88], [63930.4, 0.0], [64236.0, 0.616], [64236.1, 0.0], [64498.7, 0.001], [64530.9, 0.136], [64533.2, 0.0], [64541.0, 0.701], [64558.0, 0.036], [64559.1, 0.001], [64560.3, 0.106], [64561.8, 0.01], [64563.5, 0.087], [64563.9, 0.347], [64569.3, 0.035], [64569.7, 0.0], [64570.1, 0.713], [64570.3, 0.001], [64570.4, 1.548], [64570.5, 2.345], [64570.6, 0.569], [64571.1, 0.011], [64571.9, 0.001], [64572.1, 0.103], [64572.2, 0.319], [64572.8, 0.789], [64572.9, 0.002], [64573.9, 0.268], [64574.4, 0.005], [64575.2, 0.109], [64576.2, 6.442]], "asks": [[64589.9, 0.033], [64591.5, 0.001], [64592.1, 5.654], [64634.5, 1.476], [64651.3, 47.956], [64653.5, 0.0], [64660.1, 0.013], [64662.3, 0.0], [64772.0, 10.336], [65222.1, 3.05], [65360.2, 0.318], [65383.5, 2.376], [65576.3, 0.004]]}
{"kind": "depth", "E": 1787088874079, "U": 11315948134283, "u": 11315948140505, "recv_ms": 1787088874026, "bids": [[14376.2, 1.162], [14476.2, 3.038], [58118.5, 0.002], [61347.3, 0.001], [61993.1, 0.003], [63672.1, 6.648], [63704.4, 5.434], [63769.0, 4.498], [63812.1, 0.9], [63930.4, 0.0], [64253.3, 1.023], [64504.9, 1.359], [64527.9, 0.026], [64532.2, 0.024], [64564.6, 0.465], [64569.7, 0.0], [64570.5, 0.185], [64570.7, 0.014], [64572.8, 1.056]], "asks": [[64576.3, 29.85], [64579.1, 0.094], [64579.8, 0.011], [64592.1, 5.652], [64605.1, 0.313], [64605.2, 0.232], [64605.3, 0.026], [64608.1, 2.206], [64608.2, 5.299], [64608.3, 0.002], [64609.0, 0.019], [64609.1, 0.002], [64609.2, 0.002], [64611.1, 0.002], [64611.2, 0.022], [64611.3, 0.003], [64899.2, 0.771], [65222.1, 3.05], [65408.5, 0.763]]}
{"kind": "depth", "E": 1787088874181, "U": 11315948140616, "u": 11315948145169, "recv_ms": 1787088874127, "bids": [[1000.0, 35.76], [14376.2, 1.512], [14476.2, 2.688], [58118.5, 0.002], [61993.1, 0.0], [63289.1, 0.0], [63360.8, 0.004], [63432.6, 0.181], [63504.4, 0.02], [63576.1, 0.0], [63576.2, 0.051], [63647.9, 0.007], [63719.6, 0.005], [63735.9, 1.1], [63791.4, 0.0], [63863.1, 6.256], [63930.4, 0.0], [63934.9, 0.0], [64033.8, 0.004], [64050.0, 2.98], [64253.3, 1.033], [64497.7, 0.189], [64551.0, 0.036], [64551.1, 0.002], [64569.7, 0.0], [64570.7, 0.014]], "asks": [[64581.8, 0.001], [65222.1, 3.05], [65226.5, 7.501], [65298.3, 0.002], [65370.0, 2.033], [65383.5, 2.635], [65441.8, 0.005], [65513.5, 0.001], [65576.3, 0.024], [65585.3, 0.0], [65657.0, 0.006], [65728.8, 0.0], [65800.6, 0.0], [65872.3, 1.591]]}
{"kind": "depth", "E": 1787088874283, "U": 11315948145188, "u": 11315948149249, "recv_ms": 1787088874230, "bids": [[1000.0, 35.76], [14376.2, 1.876], [14476.2, 2.324], [51661.0, 0.0], [58118.5, 0.002], [61347.3, 0.001], [62635.6, 0.0], [63663.6, 1.171], [63889.7, 4.878], [63930.4, 0.0], [64434.7, 3.971], [64473.0, 4.368], [64545.6, 0.002], [64558.0, 0.036], [64559.1, 0.001], [64569.4, 2.413], [64570.7, 0.014], [64572.4, 0.092], [64572.8, 0.972], [64573.9, 0.273], [64574.2, 0.047], [64576.2, 6.399]], "asks": [[64576.3, 29.86], [64579.1, 0.094], [64579.8, 0.011], [64581.8, 0.0], [64592.1, 5.652], [64598.4, 0.029], [64607.6, 0.294], [64713.6, 2.118], [64716.3, 5.408], [64775.5, 0.024], [64775.6, 0.002], [65220.5, 2.094], [65222.1, 3.05], [65517.0, 15.954]]}
{"kind": "depth", "E": 1787088874385, "U": 11315948149349, "u": 11315948156705, "recv_ms": 1787088874335, "bids": [[14376.2, 2.226], [14476.2, 1.974], [51661.0, 0.0], [58118.5, 0.002], [61993.1, 0.003], [63576.2, 0.031], [63600.4, 1.572], [63605.6, 0.0], [63807.7, 7.669], [63872.3, 3.557], [63930.4, 0.0], [64434.7, 0.0], [64570.7, 2.174]], "asks": [[64577.2, 0.165], [64579.1, 0.084], [64579.8, 0.371], [64716.3, 0.0], [65222.1, 3.05], [65576.3, 0.004], [65867.8, 1.537], [66693.3, 0.0]]}
{"kind": "depth", "E": 1787088874487, "U": 11315948156778, "u": 11315948164232, "recv_ms": 1787088874433, "bids": [[1000.0, 35.76], [14376.2, 2.59], [14476.2, 1.61], [58118.5, 0.002], [61993.1, 0.0], [62631.0, 2.312], [63805.5, 27.598], [63930.4, 0.0], [64253.3, 1.023], [64434.7, 4.461], [64515.7, 0.0], [64524.1, 0.213], [64569.4, 2.329], [64570.7, 2.174], [64572.9, 0.086], [64573.3, 0.091]], "asks": [[64579.7, 0.012], [64604.2, 2.32], [64713.6, 1.517], [64716.3, 5.408], [64772.0, 10.337], [65222.1, 3.05], [65512.7, 6.556], [67805.1, 0.013]]}
{"kind": "depth", "E": 1787088874589, "U": 11315948164323, "u": 11315948170568, "recv_ms": 1787088874537, "bids": [[1000.0, 35.76], [14376.2, 2.94], [14476.2, 1.26], [49000.0, 523.775], [51661.0, 0.0], [58118.5, 0.002], [61347.3, 0.001], [61993.1, 0.003], [63576.2, 0.051], [63801.3, 4.101], [63930.4, 0.0], [64505.2, 0.001], [64515.9, 0.268], [64516.2, 0.0], [64516.5, 0.0], [64516.9, 0.004], [64517.2, 1.431], [64518.0, 0.254], [64524.5, 2.393], [64527.8, 0.041], [64533.4, 0.055], [64533.7, 4.48], [64534.0, 0.016], [64534.1, 0.228], [64534.3, 1.84], [64534.4, 0.032], [64534.7, 0.051], [64535.0, 0.52], [64543.9, 0.011], [64548.2, 3.157], [64548.3, 2.631], [64548.4, 0.109], [64548.5, 0.407], [64548.6, 0.464], [64548.7, 0.005], [64548.8, 0.001], [64548.9, 2.161], [64549.0, 1.706], [64549.2, 0.0], [64550.0, 0.251], [64550.4, 0.458], [64551.1, 0.156], [64551.2, 0.014], [64558.0, 0.028], [64560.3, 0.106], [64561.5, 0.035], [64562.7, 0.007], [64563.5, 0.095], [64565.1, 0.002], [64566.3, 0.312], [64567.0, 0.485], [64567.1, 0.013], [64567.2, 0.218], [64567.3, 0.001], [64567.4, 0.005], [64567.5, 0.049], [64567.6, 0.028], [64567.7, 0.229], [64567.8, 1.09], [64567.9, 0.001], [64568.0, 0.457], [64568.3, 0.016], [64568.6, 0.002], [64568.9, 0.0], [64569.0, 0.033], [64569.3, 0.033], [64569.5, 0.003], [64569.6, 1.359], [64569.7, 0.032], [64569.8, 0.147], [64570.0, 0.052], [64570.3, 0.001], [64570.4, 0.0], [64570.7, 0.014], [64570.8, 1.901], [64570.9, 0.086], [64571.0, 1.551], [64571.1, 0.008], [64571.9, 0.004], [64572.1, 2.263], [64574.1, 0.09], [64575.2, 0.138], [64576.2, 6.175]], "asks": [[64576.3, 29.969], [64579.0, 0.074], [64579.7, 0.002], [64586.2, 0.106], [64586.5, 2.415], [64586.8, 0.133], [64587.1, 0.325], [64587.4, 0.232], [64587.7, 0.002], [64588.0, 0.383], [64588.1, 0.001], [64588.2, 0.52], [64588.3, 0.001], [64588.4, 0.153], [64588.5, 1.709], [64588.6, 0.014], [64588.7, 0.003], [64588.8, 0.021], [64588.9, 0.0], [64589.0, 1.394], [64589.9, 0.025], [64591.5, 0.009], [64598.2, 0.468], [64599.1, 1.393], [64599.9, 0.628], [64603.6, 0.055], [64603.9, 0.154], [64604.0, 0.068], [64604.3, 2.401], [64604.6, 0.157], [64604.9, 0.0], [64605.2, 0.174], [64605.6, 0.045], [64606.0, 6.043], [64606.8, 0.13], [64607.0, 2.531], [64607.1, 0.002], [64607.2, 0.133], [64607.3, 0.002], [64607.4, 0.506], [64607.5, 0.006], [64607.6, 0.0], [64607.7, 0.171], [64607.8, 0.041], [64614.5, 1.243], [64614.6, 0.0], [64621.4, 0.168], [64621.7, 0.885], [64622.0, 0.164], [64622.4, 0.002], [64622.7, 0.0], [64622.8, 0.079], [64637.2, 0.0], [64649.1, 47.952], [64651.2, 0.003], [64651.3, 0.004], [64653.8, 0.005], [65222.1, 3.05], [65498.3, 31.255], [65576.3, 0.024], [68228.8, 0.0], [71034.0, 0.0]]}
{"kind": "depth", "E": 1787088874691, "U": 11315948170581, "u": 11315948175887, "recv_ms": 1787088874638, "bids": [[14376.2, 3.304], [14476.2, 0.896], [58118.5, 0.002], [61347.5, 0.004], [63284.7, 0.004], [63607.6, 0.478], [63769.0, 4.763], [63930.4, 0.0], [64468.9, 29.685], [64472.9, 0.049], [64473.0, 0.017], [64488.7, 0.0], [64488.8, 0.003], [64490.9, 0.424], [64492.5, 1.173], [64514.2, 0.05], [64532.2, 0.038], [64558.0, 0.036], [64559.4, 0.021], [64560.3, 0.106], [64561.5, 0.042], [64562.7, 0.0], [64563.5, 0.087], [64563.6, 0.012], [64564.7, 0.117], [64565.0, 0.312], [64566.3, 0.002], [64567.4, 0.075], [64567.6, 0.098], [64567.7, 0.299], [64567.9, 0.201], [64568.1, 0.108], [64568.2, 0.071], [64568.3, 0.116], [64569.5, 0.003], [64569.7, 2.732], [64569.8, 1.299], [64569.9, 0.067], [64570.0, 0.052], [64570.1, 0.629], [64570.2, 0.561], [64570.3, 3.902], [64570.6, 0.004], [64570.8, 0.006], [64571.0, 0.006], [64571.3, 0.084], [64571.9, 0.001], [64572.1, 0.103], [64572.3, 0.004], [64572.4, 0.092], [64572.8, 0.705], [64572.9, 0.086], [64573.0, 0.002], [64573.8, 0.086], [64574.1, 0.006], [64575.0, 0.02], [64575.2, 0.148]], "asks": [[64576.3, 29.969], [64576.8, 0.007], [64578.0, 0.046], [64578.3, 0.021], [64579.5, 0.011], [64579.7, 0.079], [64580.3, 0.936], [64580.7, 1.457], [64583.2, 0.312], [64584.5, 0.003], [64587.8, 0.252], [64587.9, 0.159], [64588.0, 0.623], [64588.2, 0.75], [64588.3, 0.261], [64588.5, 1.849], [64588.6, 0.14], [64588.7, 0.136], [64589.9, 0.033], [64591.5, 0.001], [64591.7, 1.114], [64591.8, 1.24], [64593.8, 0.046], [64605.3, 0.276], [64605.7, 0.27], [64606.7, 0.14], [64606.8, 0.37], [64607.0, 2.761], [64607.3, 0.142], [64607.4, 0.632], [64607.5, 0.293], [64607.7, 0.017], [64668.8, 1.473], [64671.0, 0.014], [64899.2, 0.77], [65180.0, 1.999], [65222.1, 3.05], [66680.7, 0.135]]}
{"kind": "depth", "E": 1787088874793, "U": 11315948175957, "u": 11315948181416, "recv_ms": 1787088874739, "bids": [[1000.0, 35.76], [14376.2, 3.654], [14476.2, 0.546], [51661.0, 0.0], [58118.5, 0.002], [61993.1, 0.0], [63576.2, 0.031], [63773.3, 18.067], [63844.0, 0.098], [64253.3, 1.033], [64468.9, 29.685], [64490.9, 0.424], [64514.2, 0.036], [64527.8, 3.541], [64543.9, 0.981], [64567.5, 0.119], [64567.8, 1.19], [64568.2, 0.171], [64569.7, 0.032], [64569.8, 0.147], [64569.9, 0.005], [64570.2, 0.553], [64570.3, 2.31], [64570.4, 1.556], [64570.5, 0.247], [64572.1, 0.103], [64572.3, 0.004], [64572.8, 1.309], [64572.9, 0.094], [64573.8, 0.002]], "asks": [[64580.6, 43.173], [64587.9, 0.419], [64588.3, 0.521], [64588.6, 0.273], [64598.3, 2.239], [64606.7, 0.4], [64607.1, 0.262], [64607.4, 0.765], [64607.5, 0.139], [64607.8, 0.195], [64614.4, 3.524], [65222.1, 3.05], [65388.0, 25.235], [65480.4, 6.526], [65576.3, 0.004], [68228.8, 0.076]]}
{"kind": "depth", "E": 1787088874895, "U": 11315948181677, "u": 11315948187115, "recv_ms": 1787088874842, "bids": [[1000.0, 35.76], [14276.2, 0.126], [14376.2, 3.752], [14476.2, 0.322], [51661.0, 0.0], [58118.5, 0.002], [61347.3, 0.001], [61993.1, 0.003], [63463.5, 1.262], [63930.4, 0.0], [64253.3, 1.034], [64417.7, 0.002], [64417.8, 4.166], [64434.7, 0.0], [64434.8, 3.985], [64468.9, 0.022], [64472.9, 10.049], [64488.7, 29.663], [64505.2, 6.001], [64516.6, 0.039], [64516.9, 0.036], [64517.2, 1.463], [64517.6, 0.034], [64533.8, 0.481], [64545.6, 0.621], [64552.9, 0.693], [64561.2, 0.313], [64563.5, 0.087], [64567.6, 0.168], [64568.1, 0.178], [64568.4, 0.352], [64568.7, 0.033], [64569.5, 0.001], [64570.2, 0.097], [64570.3, 1.734], [64570.4, 1.556], [64570.6, 2.164], [64570.7, 0.564], [64572.3, 0.004], [64572.4, 0.092], [64572.9, 0.086], [64573.3, 0.007]], "asks": [[64576.3, 29.969], [64587.4, 0.29], [64587.7, 0.163], [64588.1, 0.12], [64588.5, 2.003], [64599.2, 0.646], [64604.9, 0.058], [64606.5, 0.784], [64606.9, 0.121], [64607.3, 0.296], [64621.1, 0.055], [64621.4, 0.222], [64621.7, 0.959], [64622.1, 0.374], [64638.7, 6.005], [64671.0, 10.014], [64716.3, 5.408], [64733.2, 10.427], [64772.0, 11.631], [65222.1, 3.05]]}
{"kind": "depth", "E": 1787088874997, "U": 11315948187447, "u": 11315948192538, "recv_ms": 1787088874943, "bids": [[14276.2, 0.378], [14376.2, 3.626], [14476.2, 0.196], [58118.5, 0.002], [61993.1, 0.0], [63488.7, 3.197], [63576.2, 0.051], [63659.2, 0.468], [63930.4, 0.0], [64236.0, 0.123], [64236.2, 0.495], [64253.3, 1.034], [64513.0, 2.561], [64548.9, 2.231], [64549.2, 0.1], [64563.5, 0.636], [64569.5, 0.003], [64570.2, 0.088], [64570.4, 0.0], [64570.5, 0.185], [64570.6, 0.004], [64570.7, 0.076], [64570.8, 0.006], [64572.1, 0.103], [64572.3, 0.012], [64572.4, 1.64], [64572.9, 0.094], [64573.3, 0.091], [64573.9, 0.273]], "asks": [[64607.8, 0.041], [64639.4, 2.994], [64649.1, 0.0], [64660.1, 48.045], [65222.1, 3.05], [65349.6, 3.212], [65576.3, 0.024], [66047.3, 0.634], [68405.0, 0.0]]}
{"kind": "depth", "E": 1787088875099, "U": 11315948192588, "u": 11315948197246, "recv_ms": 1787088875046, "bids": [[1000.0, 35.76], [14276.2, 0.616], [14376.2, 3.5], [14476.2, 0.084], [51661.0, 0.0], [58118.5, 0.002], [61993.1, 0.003], [63446.1, 2.531], [63568.7, 0.709], [63794.0, 0.787], [63930.4, 0.0], [64253.3, 1.033], [64447.0, 1.835], [64504.9, 1.36], [64527.8, 3.542], [64548.6, 0.534], [64548.8, 0.071], [64548.9, 2.301], [64549.1, 0.106], [64549.3, 0.1], [64549.4, 0.07], [64550.4, 0.558], [64550.8, 0.124], [64551.8, 0.04], [64553.2, 0.003], [64554.1, 0.004], [64555.3, 0.0], [64555.8, 1.322], [64556.3, 0.013], [64556.7, 0.005], [64557.5, 2.877], [64557.6, 0.0], [64557.9, 0.011], [64558.0, 0.028], [64559.1, 0.009], [64560.3, 0.098], [64563.5, 0.644], [64563.6, 0.012], [64564.6, 0.465], [64569.5, 0.001], [64570.2, 0.09], [64570.4, 0.0], [64570.5, 0.185], [64570.6, 0.004], [64571.0, 0.003], [64571.8, 0.171], [64572.3, 0.004], [64572.4, 0.092], [64572.8, 0.705], [64572.9, 1.642], [64573.3, 0.007], [64574.1, 0.09], [64575.2, 0.675]], "asks": [[64576.8, 0.0], [64578.1, 0.007], [64579.7, 0.002], [64580.3, 1.013], [64583.2, 0.003], [64584.5, 0.312], [64589.9, 0.025], [64590.5, 0.04], [64590.6, 0.005], [64593.0, 0.549], [64593.8, 0.044], [64597.0, 0.001], [64597.7, 0.557], [64598.1, 0.135], [64598.2, 0.352], [64599.0, 2.297], [64599.5, 0.004], [64607.8, 0.041], [64607.9, 0.154], [64608.0, 0.215], [64651.3, 48.036], [64660.1, 0.013], [64708.4, 9.835], [64708.5, 0.0], [64768.3, 0.53], [64768.4, 4.604], [65222.1, 3.05], [65287.1, 0.857], [65331.8, 1.07], [66029.3, 0.606]]}
{"kind": "depth", "E": 1787088875201, "U": 11315948197313, "u": 11315948201883, "recv_ms": 1787088875148, "bids": [[1000.0, 35.76], [14276.2, 0.882], [14376.2, 3.318], [14476.2, 0.0], [51661.0, 0.0], [58118.5, 0.002], [61347.3, 0.001], [63576.2, 0.031], [63930.4, 0.0], [64516.3, 0.059], [64518.0, 0.251], [64530.9, 0.133], [64548.7, 0.075], [64549.0, 1.806], [64549.4, 0.17], [64555.0, 0.48], [64555.8, 1.206], [64555.9, 0.559], [64557.5, 2.319], [64557.9, 0.003], [64559.1, 0.001], [64560.0, 1.133], [64560.3, 0.656], [64560.9, 0.343], [64561.0, 0.013], [64563.0, 2.321], [64563.5, 0.01], [64563.6, 0.012], [64569.5, 0.001], [64570.2, 0.006], [64570.4, 1.202], [64570.6, 0.004], [64572.3, 0.004], [64572.8, 0.705], [64572.9, 0.102], [64573.0, 1.55], [64574.4, 0.089], [64574.8, 0.084], [64575.2, 0.661]], "asks": [[64576.3, 29.937], [64578.3, 0.011], [64579.5, 0.001], [64581.5, 0.004], [64591.6, 0.546], [64592.4, 0.001], [64592.9, 0.927], [64593.0, 0.007], [64594.1, 0.246], [64596.4, 0.561], [64597.7, 0.0], [64607.9, 0.0], [64608.1, 2.36], [64622.4, 0.06], [64634.5, 1.473], [64653.8, 0.002], [64899.2, 0.771], [65222.1, 3.05], [65383.5, 2.863], [65576.3, 0.004], [65867.8, 1.534]]}
{"kind": "depth", "E": 1787088875303, "U": 11315948201897, "u": 11315948206089, "recv_ms": 1787088875250, "bids": [[14276.2, 1.246], [14376.2, 2.954], [58118.5, 0.002], [61993.1, 0.0], [63579.5, 2.2], [63644.1, 7.18], [63930.4, 0.0], [64253.3, 1.033], [64365.0, 0.146], [64435.1, 1.43], [64488.8, 7.646], [64498.7, 0.004], [64548.8, 0.141], [64549.3, 0.17], [64549.6, 0.07], [64553.1, 0.005], [64554.1, 0.002], [64557.8, 0.033], [64559.1, 0.009], [64560.0, 0.206], [64560.3, 0.098], [64560.4, 0.93], [64560.5, 0.542], [64560.7, 0.002], [64561.2, 0.313], [64561.3, 0.428], [64563.3, 0.002], [64563.5, 0.095], [64569.5, 0.003], [64570.2, 0.004], [64570.4, 0.0], [64570.5, 0.75], [64570.6, 1.552], [64570.7, 0.014], [64570.8, 0.068], [64571.0, 0.006], [64571.8, 0.168], [64572.8, 0.999], [64572.9, 0.086], [64573.0, 0.002], [64573.4, 0.084], [64574.1, 0.006], [64574.4, 0.005], [64574.7, 0.084], [64574.8, 0.0], [64575.2, 0.159]], "asks": [[64576.3, 29.936], [64579.7, 0.002], [64580.3, 1.013], [64590.5, 0.032], [64591.2, 0.219], [64591.6, 0.004], [64591.8, 1.782], [64592.8, 0.003], [64592.9, 0.0], [64593.6, 0.933], [64595.7, 1.127], [64596.4, 0.004], [64597.5, 0.711], [64598.1, 0.128], [64598.6, 0.039], [64608.1, 2.206], [64634.5, 1.476], [64650.1, 8.25], [64668.8, 3.155], [64713.6, 2.118], [64733.0, 2.463], [65222.1, 3.05], [65383.5, 3.016], [67805.1, 0.018]]}
{"kind": "depth", "E": 1787088875405, "U": 11315948206306, "u": 11315948210843, "recv_ms": 1787088875351, "bids": [[1000.0, 35.76], [14276.2, 1.596], [14376.2, 2.604], [58118.5, 0.002], [61347.3, 0.001], [61993.1, 0.003], [63289.0, 2.834], [63360.7, 0.122], [63432.5, 0.059], [63504.3, 0.059], [63576.0, 0.059], [63576.2, 0.051], [63647.8, 0.059], [63719.5, 0.059], [63769.0, 5.028], [63791.3, 0.059], [63863.0, 1.168], [63930.4, 0.0], [63934.8, 5.481], [64550.4, 0.635], [64552.9, 0.074], [64559.1, 0.001], [64560.6, 0.012], [64560.7, 0.01], [64563.5, 0.087], [64565.0, 0.002], [64566.3, 0.312], [64569.5, 0.001], [64570.2, 0.006], [64570.5, 0.734], [64570.7, 0.014], [64571.0, 0.003], [64572.0, 0.307], [64572.3, 0.004], [64572.9, 0.102]], "asks": [[64576.3, 29.93], [64598.0, 0.138], [64599.0, 2.181], [64599.2, 0.027], [64650.1, 1.537], [64651.3, 0.004], [64662.3, 48.032], [65222.1, 3.05], [65226.4, 3.273], [65298.2, 2.354], [65369.9, 0.079], [65383.5, 3.275], [65576.3, 0.024]]}
{"kind": "depth", "E": 1787088875507, "U": 11315948210899, "u": 11315948216137, "recv_ms": 1787088875453, "bids": [[1000.0, 35.76], [14276.2, 1.96], [14376.2, 2.24], [58118.5, 0.002], [61993.1, 0.0], [63284.7, 0.007], [63575.3, 3.954], [63639.8, 11.768], [63930.4, 0.0], [64434.8, 0.0], [64434.9, 4.575], [64435.1, 0.94], [64555.0, 0.364], [64555.7, 2.423], [64555.9, 0.001], [64556.6, 0.674], [64558.0, 0.036], [64559.2, 0.0], [64560.3, 0.106], [64560.4, 0.003], [64560.5, 0.0], [64560.6, 0.004], [64560.7, 0.002], [64561.4, 0.931], [64561.5, 0.042], [64562.7, 0.0], [64563.5, 0.629], [64565.0, 0.312], [64566.3, 0.002], [64569.5, 0.001], [64569.7, 0.032], [64570.2, 0.006], [64570.6, 1.56], [64570.7, 0.014], [64571.1, 0.011], [64572.0, 0.304], [64572.1, 0.103], [64572.2, 0.319], [64572.3, 0.004], [64572.9, 0.094], [64574.7, 0.0], [64575.2, 0.401], [64576.2, 6.195]], "asks": [[64576.3, 29.932], [64576.8, 0.007], [64578.1, 0.0], [64579.7, 0.079], [64580.3, 0.936], [64581.5, 0.003], [64583.3, 0.31], [64584.5, 0.003], [64589.9, 0.033], [64591.2, 0.211], [64591.6, 0.004], [64591.7, 1.114], [64591.8, 1.24], [64593.3, 0.556], [64593.8, 0.044], [64596.7, 0.035], [64597.0, 0.558], [64597.5, 0.154], [64598.0, 0.022], [64598.4, 0.145], [64598.6, 0.032], [64599.1, 1.4], [64651.3, 48.036], [64662.3, 0.0], [64713.6, 1.517], [64716.3, 5.408], [64772.0, 10.516], [64774.3, 0.0], [65000.0, 117.432], [65222.1, 3.05], [65441.7, 0.083], [65513.4, 0.061], [65585.2, 0.067], [65656.9, 0.059], [65728.7, 0.061], [65800.5, 0.067], [65872.2, 0.059]]}
{"kind": "depth", "E": 1787088875609, "U": 11315948216352, "u": 11315948223135, "recv_ms": 1787088875555, "bids": [[14276.2, 2.31], [14376.2, 1.89], [58118.5, 0.002], [61347.3, 0.001], [63576.2, 0.031], [63773.3, 17.715], [63930.4, 0.0], [64253.3, 1.033], [64481.3, 0.012], [64487.0, 0.0], [64494.4, 0.033], [64500.6, 0.204], [64507.1, 0.0], [64513.5, 0.007], [64520.0, 9.457], [64526.5, 0.004], [64532.9, 0.002], [64539.4, 0.0], [64545.8, 0.0], [64552.3, 0.062], [64555.2, 0.15], [64555.7, 2.307], [64558.0, 0.028], [64558.7, 0.063], [64560.3, 0.098], [64560.5, 0.927], [64560.6, 0.012], [64561.4, 0.004], [64563.1, 0.561], [64563.5, 0.095], [64565.2, 0.047], [64569.5, 0.001], [64569.9, 0.008], [64570.2, 0.006], [64570.7, 0.022], [64571.1, 0.008], [64571.7, 0.07], [64571.9, 0.004], [64572.9, 0.086], [64573.8, 0.086], [64574.9, 0.098], [64575.2, 0.117], [64576.2, 6.422]], "asks": [[64576.3, 29.847], [64576.8, 0.0], [64578.1, 0.007], [64578.3, 0.011], [64579.5, 0.001], [64579.7, 0.002], [64580.3, 1.013], [64582.6, 0.468], [64583.3, 0.001], [64584.5, 0.312], [64585.9, 0.001], [64589.8, 0.001], [64589.9, 0.025], [64591.5, 0.009], [64591.7, 0.495], [64593.0, 0.005], [64593.8, 0.663], [64594.0, 0.03], [64594.1, 0.243], [64598.9, 0.337], [64602.4, 0.021], [64605.1, 0.311], [64605.2, 0.172], [64605.3, 0.274], [64605.9, 2.045], [64606.5, 0.165], [64607.8, 0.195], [64608.1, 2.204], [64608.2, 5.297], [64608.3, 0.0], [64609.0, 0.017], [64609.1, 0.0], [64609.2, 0.0], [64609.9, 0.085], [64611.1, 0.0], [64611.2, 0.02], [64611.3, 0.001], [64616.3, 0.006], [64622.8, 0.076], [64629.3, 0.0], [64635.7, 0.002], [64642.2, 2.46], [64648.6, 0.0], [64655.1, 0.042], [64677.0, 2.616], [64733.2, 0.0], [64733.3, 7.102], [65222.1, 3.05], [65351.2, 8.126], [65498.3, 28.968], [65576.3, 0.004], [65854.9, 0.607]]}
{"kind": "depth", "E": 1787088875711, "U": 11315948223235, "u": 11315948228911, "recv_ms": 1787088875657, "bids": [[1000.0, 35.76], [14276.2, 2.674], [14376.2, 1.526], [51661.0, 0.0], [58118.5, 0.002], [61347.3, 0.002], [61993.1, 0.003], [63794.1, 0.783], [63826.4, 0.782], [63930.4, 0.0], [64559.4, 0.019], [64563.5, 0.095], [64569.5, 0.003], [64569.7, 1.184], [64570.2, 0.004], [64570.5, 0.192], [64570.6, 0.546], [64570.7, 0.014], [64572.3, 0.004], [64572.9, 2.262], [64573.0, 1.55], [64574.4, 0.089], [64574.9, 0.014], [64575.2, 0.336], [64576.2, 6.423]], "asks": [[64576.3, 29.931], [64580.2, 0.097], [64580.3, 1.021], [64588.4, 0.153], [64589.9, 0.025], [64591.8, 1.238], [64607.8, 0.041], [64607.9, 0.154], [64733.3, 10.434], [65222.1, 3.05], [65349.6, 2.677], [65530.5, 8.846], [65679.1, 1.323], [65867.8, 1.537]]}
{"kind": "depth", "E": 1787088875813, "U": 11315948228975, "u": 11315948234250, "recv_ms": 1787088875759, "bids": [[1000.0, 35.76], [14276.2, 3.038], [14376.2, 1.162], [51661.0, 0.0], [58118.5, 0.002], [61347.3, 0.001], [61347.5, 0.002], [61993.1, 0.0], [63576.2, 0.051], [63930.4, 0.0], [64509.0, 1.342], [64514.2, 0.036], [64555.9, 0.559], [64556.6, 0.116], [64558.0, 0.036], [64559.4, 0.021], [64560.3, 0.098], [64560.6, 0.012], [64563.1, 0.561], [64563.5, 0.087], [64563.6, 0.012], [64569.3, 0.035], [64569.5, 0.001], [64569.7, 1.58], [64569.9, 0.005], [64570.2, 0.553], [64570.3, 1.917], [64570.4, 2.16], [64570.5, 0.101], [64570.6, 0.004], [64570.7, 0.014], [64570.8, 0.006], [64570.9, 0.148], [64571.1, 0.011], [64571.9, 0.001], [64572.8, 0.705], [64572.9, 0.086], [64573.0, 0.002], [64574.4, 0.005], [64574.9, 0.014], [64575.2, 0.106]], "asks": [[64576.3, 29.931], [64579.0, 0.074], [64579.7, 0.079], [64580.3, 0.944], [64589.9, 0.033], [64591.5, 0.001], [64591.7, 0.495], [64591.8, 1.24], [64592.6, 0.002], [64593.3, 0.556], [64593.5, 0.927], [64593.6, 0.006], [64607.9, 0.0], [64608.0, 0.369], [64733.3, 10.434], [65222.1, 3.05], [65331.8, 1.605], [65390.6, 1.261], [65433.7, 34.179], [65480.4, 8.814], [65576.3, 0.024]]}
{"kind": "depth", "E": 1787088875915, "U": 11315948234313, "u": 11315948238763, "recv_ms": 1787088875859, "bids": [[14276.2, 3.388], [14376.2, 0.812], [51000.0, 93.274], [51661.0, 0.0], [58118.5, 0.002], [61347.3, 0.001], [61993.1, 0.003], [63930.4, 0.0], [64253.3, 1.032], [64552.9, 0.693], [64558.0, 0.028], [64560.3, 0.106], [64560.6, 0.004], [64561.8, 0.0], [64563.5, 0.002], [64565.2, 0.057], [64570.4, 2.16], [64570.5, 0.194], [64572.8, 1.238], [64574.5, 0.085]], "asks": [[64576.3, 29.846], [64579.5, 0.001], [64579.7, 0.002], [64580.3, 1.021], [64589.9, 0.025], [64591.5, 0.009], [64599.2, 0.027], [64606.5, 0.784], [64651.2, 0.002], [65202.7, 0.846], [65222.1, 3.05], [65311.7, 4.445], [65936.9, 3.181]]}
{"kind": "depth", "E": 1787088876017, "U": 11315948238861, "u": 11315948242944, "recv_ms": 1787088875963, "bids": [[1000.0, 35.76], [14176.2, 0.028], [14276.2, 3.696], [14376.2, 0.476], [58118.5, 0.002], [61347.3, 0.001], [61993.1, 0.0], [63284.7, 0.004], [63576.2, 0.031], [63659.2, 0.702], [63695.9, 4.639], [63930.4, 0.0], [64434.9, 0.139], [64435.0, 5.981], [64564.9, 0.617], [64565.2, 0.047], [64569.3, 0.033], [64569.6, 1.361], [64570.0, 0.052], [64570.4, 0.0], [64574.9, 0.098]], "asks": [[64576.3, 29.845], [64695.6, 0.0], [64716.3, 5.408], [64772.0, 10.494], [64899.2, 0.772], [65222.1, 3.05], [65497.7, 1.824], [65576.3, 0.004]]}
{"kind": "depth", "E": 1787088876119, "U": 11315948242996, "u": 11315948247760, "recv_ms": 1787088876064, "bids": [[1000.0, 35.76], [14176.2, 0.196], [14276.2, 3.71], [14376.2, 0.294], [51661.0, 0.0], [58118.5, 0.002], [61347.3, 0.001], [63930.4, 0.0], [64003.7, 0.936], [64552.9, 0.074], [64558.0, 0.036], [64560.3, 0.098], [64560.6, 0.012], [64563.5, 0.087], [64564.6, 0.465], [64570.4, 0.0], [64570.5, 0.101], [64574.4, 0.005], [64574.5, 0.001], [64574.8, 0.0], [64574.9, 0.014]], "asks": [[64576.3, 29.93], [64579.0, 0.084], [64579.7, 0.089], [64580.3, 0.944], [64580.7, 1.458], [64589.9, 0.033], [64591.5, 0.001], [64608.0, 0.369], [64733.3, 7.07], [65222.1, 3.05], [71034.0, 0.0]]}
{"kind": "depth", "E": 1787088876221, "U": 11315948247903, "u": 11315948253514, "recv_ms": 1787088876168, "bids": [[14176.2, 0.42], [14276.2, 3.612], [14376.2, 0.168], [51661.0, 0.0], [58118.5, 0.0], [61993.1, 0.003], [63576.2, 0.051], [63678.6, 1.822], [63930.4, 0.0], [64253.3, 1.032], [64479.5, 0.02], [64486.0, 0.033], [64492.4, 0.004], [64498.9, 0.012], [64505.4, 4.552], [64511.8, 0.004], [64518.3, 0.016], [64524.7, 0.026], [64531.2, 0.016], [64537.6, 0.013], [64544.1, 0.018], [64550.6, 0.313], [64557.0, 0.022], [64558.0, 0.028], [64560.6, 0.012], [64563.5, 0.082], [64569.9, 0.008], [64570.4, 0.016]], "asks": [[64580.3, 0.928], [64582.3, 0.062], [64588.4, 0.161], [64588.8, 0.024], [64589.9, 0.033], [64591.7, 0.503], [64595.2, 0.172], [64601.7, 0.006], [64608.1, 2.207], [64613.2, 0.026], [64614.4, 3.526], [64614.6, 0.003], [64621.0, 0.016], [64627.5, 0.452], [64634.0, 0.213], [64640.4, 2.322], [64646.9, 0.003], [64653.3, 0.003], [64659.8, 0.895], [64666.3, 0.134], [64672.7, 0.003], [64679.2, 0.003], [64733.3, 10.434], [64899.2, 0.771], [65222.1, 3.05], [65576.3, 0.024], [65932.4, 0.303]]}
{"kind": "depth", "E": 1787088876323, "U": 11315948253528, "u": 11315948263238, "recv_ms": 1787088876273, "bids": [[1000.0, 35.76], [14176.2, 0.672], [14276.2, 3.472], [14376.2, 0.056], [51661.0, 0.0], [58118.5, 0.002], [61347.3, 0.001], [61993.1, 0.0], [63547.2, 8.963], [63576.2, 0.031], [63930.4, 0.004], [64150.1, 0.006], [64152.9, 0.0], [64156.8, 0.003], [64158.6, 0.0], [64162.7, 0.0], [64165.7, 0.005], [64169.6, 0.002], [64170.8, 0.086], [64175.3, 0.0], [64178.2, 0.007], [64181.7, 0.0], [64185.1, 0.0], [64188.1, 0.26], [64191.8, 0.005], [64194.1, 0.001], [64198.1, 0.002], [64200.1, 0.0], [64204.7, 0.001], [64206.8, 0.008], [64211.2, 0.0], [64214.0, 0.006], [64215.1, 0.071], [64220.0, 1.137], [64223.9, 0.0], [64226.2, 0.003], [64230.1, 0.552], [64233.1, 0.0], [64235.5, 0.0], [64239.8, 0.003], [64243.0, 0.011], [64245.2, 0.0], [64249.6, 0.0], [64250.1, 0.808], [64253.3, 1.033], [64254.4, 0.002], [64258.8, 0.105], [64260.5, 0.002], [64265.1, 0.032], [64268.1, 0.0], [64271.1, 0.002], [64275.1, 0.0], [64277.1, 0.01], [64281.1, 0.0], [64284.1, 0.0], [64287.1, 0.126], [64291.1, 0.034], [64294.1, 0.159], [64297.1, 0.0], [64300.1, 0.922], [64302.7, 0.0], [64306.0, 0.017], [64310.4, 0.0], [64313.0, 0.223], [64315.1, 0.001], [64320.0, 1.537], [64321.6, 0.0], [64325.2, 0.004], [64329.1, 0.002], [64332.1, 0.21], [64335.3, 0.283], [64339.1, 0.062], [64342.1, 0.134], [64345.1, 0.0], [64348.1, 0.002], [64350.7, 0.007], [64355.1, 0.0], [64358.1, 0.0], [64361.1, 0.012], [64363.1, 0.0], [64367.5, 0.001], [64370.1, 0.005], [64373.3, 0.002], [64377.2, 0.0], [64380.5, 0.0], [64382.7, 0.216], [64385.1, 0.005], [64390.1, 0.0], [64391.1, 0.002], [64396.8, 0.003], [64399.9, 0.159], [64400.4, 0.104], [64406.1, 1.618], [64409.5, 0.0], [64412.8, 0.944], [64416.0, 0.246], [64419.1, 0.029], [64420.1, 0.005], [64423.5, 0.029], [64428.3, 0.0], [64432.0, 0.065], [64435.1, 0.12], [64438.2, 0.005], [64441.5, 0.001], [64444.1, 0.411], [64447.6, 0.0], [64450.1, 0.0], [64454.2, 0.015], [64455.8, 0.271], [64460.4, 0.274], [64462.3, 0.0], [64467.2, 7.677], [64470.3, 3.359], [64475.7, 0.009], [64479.4, 0.013], [64482.4, 0.001], [64485.6, 0.001], [64488.8, 0.003], [64492.5, 0.061], [64495.4, 0.014], [64498.3, 0.016], [64500.1, 0.003], [64505.5, 0.312], [64508.6, 0.014], [64509.0, 1.356], [64510.7, 0.022], [64515.1, 0.0], [64517.3, 0.007], [64517.8, 0.013], [64517.9, 0.036], [64521.1, 0.098], [64524.0, 0.112], [64528.0, 0.116], [64529.7, 0.039], [64530.8, 0.0], [64534.3, 0.0], [64536.7, 0.0], [64540.6, 0.033], [64543.5, 0.31], [64545.6, 0.002], [64545.7, 0.001], [64549.7, 0.016], [64553.1, 0.003], [64553.3, 0.001], [64555.8, 0.319], [64556.4, 0.083], [64559.0, 0.006], [64560.5, 0.0], [64560.8, 0.931], [64560.9, 0.885], [64561.7, 0.019], [64561.8, 0.0], [64563.1, 0.576], [64563.2, 0.102], [64563.5, 0.013], [64566.4, 0.009], [64569.6, 0.012], [64569.7, 0.032], [64569.9, 0.011], [64570.2, 0.004], [64570.3, 0.001], [64570.4, 0.0], [64570.5, 0.101], [64570.9, 0.086], [64571.0, 1.903], [64571.1, 0.011], [64571.8, 0.478], [64572.3, 0.004], [64572.4, 1.656], [64572.5, 0.063], [64572.8, 0.01], [64574.8, 0.084], [64575.2, 0.0], [64576.2, 6.926]], "asks": [[64576.3, 29.825], [64576.4, 0.032], [64579.7, 0.012], [64580.0, 0.012], [64580.2, 0.174], [64580.5, 0.784], [64580.7, 1.455], [64582.6, 0.002], [64584.6, 0.075], [64585.6, 0.329], [64586.6, 0.002], [64588.4, 0.153], [64589.0, 0.013], [64589.9, 0.025], [64591.1, 0.008], [64591.7, 0.495], [64592.1, 0.002], [64592.7, 0.01], [64593.5, 0.0], [64594.0, 0.028], [64594.1, 1.17], [64595.2, 0.174], [64596.3, 0.0], [64597.6, 0.003], [64599.0, 0.107], [64602.8, 0.0], [64605.9, 0.026], [64606.5, 0.165], [64607.8, 0.041], [64608.0, 0.215], [64608.1, 0.065], [64611.9, 0.041], [64614.5, 0.315], [64617.7, 0.095], [64621.7, 0.075], [64625.5, 0.055], [64627.6, 0.0], [64628.9, 9.999], [64629.1, 0.042], [64631.0, 0.092], [64633.6, 0.165], [64637.3, 0.002], [64640.3, 0.001], [64643.9, 0.001], [64646.7, 0.001], [64650.1, 0.0], [64651.3, 0.004], [64652.4, 0.002], [64652.9, 0.002], [64656.8, 0.165], [64659.8, 0.003], [64662.3, 48.032], [64662.9, 0.0], [64666.3, 0.003], [64668.8, 0.026], [64673.3, 0.01], [64676.2, 0.0], [64678.6, 0.0], [64682.3, 1.097], [64684.8, 0.007], [64688.0, 0.362], [64691.7, 0.0], [64694.7, 0.018], [64698.6, 0.002], [64700.9, 0.0], [64704.1, 0.005], [64708.4, 4.278], [64710.6, 0.0], [64713.6, 0.04], [64717.5, 0.0], [64720.9, 0.0], [64725.9, 0.0], [64726.8, 0.0], [64729.7, 0.0], [64733.0, 0.001], [64733.3, 10.434], [64737.1, 0.0], [64740.8, 0.019], [64742.6, 0.079], [64747.4, 0.0], [64748.8, 0.091], [64752.0, 0.043], [64755.2, 0.005], [64758.4, 0.001], [64762.8, 0.0], [64765.5, 0.026], [64768.4, 0.005], [64771.7, 0.001], [64774.6, 0.0], [64778.0, 0.006], [64780.8, 0.008], [64784.0, 0.0], [64787.2, 0.1], [64790.4, 0.094], [64794.0, 0.091], [64799.9, 0.0], [64800.2, 0.006], [64803.7, 0.008], [64807.7, 0.041], [64809.9, 0.0], [64813.2, 0.0], [64819.9, 0.0], [64824.8, 0.0], [64827.9, 0.0], [64831.8, 0.411], [64832.5, 0.0], [64835.7, 0.004], [64839.1, 0.0], [64841.7, 0.0], [64845.2, 0.002], [64849.9, 0.002], [64851.3, 0.0], [64854.9, 0.032], [64857.7, 0.001], [64861.4, 0.0], [64864.9, 0.0], [64868.5, 0.125], [64871.2, 0.091], [64874.5, 0.0], [64877.1, 0.001], [64880.9, 0.0], [64883.4, 0.0], [64887.9, 1.39], [64889.9, 0.0], [64894.8, 0.0], [64897.9, 0.012], [64899.9, 0.059], [64903.4, 0.011], [64906.6, 0.001], [64909.7, 0.003], [64913.1, 0.014], [64916.7, 0.003], [64919.9, 0.008], [64922.4, 0.003], [64926.6, 0.094], [64929.1, 0.0], [64932.1, 0.817], [64935.1, 0.0], [64938.5, 0.0], [64941.5, 0.034], [64944.9, 0.0], [64947.9, 0.0], [64951.0, 0.082], [64954.5, 0.022], [64956.9, 0.932], [64961.9, 0.912], [64963.7, 0.0], [64967.9, 0.0], [64969.6, 2.633], [64973.0, 0.017], [64976.9, 0.0], [64979.9, 0.001], [64983.7, 0.0], [64988.4, 0.002], [64989.9, 0.0], [64993.6, 0.0], [64996.3, 2.004], [64999.9, 0.096], [65003.2, 0.0], [65005.9, 0.002], [65009.9, 0.183], [65011.9, 0.001], [65014.9, 0.002], [65018.5, 0.0], [65021.9, 0.0], [65024.9, 0.0], [65027.9, 0.067], [65031.9, 0.0], [65034.7, 0.0], [65037.9, 0.0], [65042.7, 0.118], [65222.1, 3.05], [65576.3, 0.004]]}
{"kind": "depth", "E": 1787088876425, "U": 11315948263274, "u": 11315948269379, "recv_ms": 1787088876373, "bids": [[1000.0, 35.76], [14176.2, 0.966], [14276.2, 3.234], [14376.2, 0.0], [58118.5, 0.002], [61347.3, 0.001], [61347.4, 0.006], [61993.1, 0.003], [63644.3, 10.47], [63657.3, 28.857], [63773.3, 17.481], [63930.4, 0.0], [64460.1, 29.592], [64488.7, 0.0], [64554.0, 0.218], [64555.9, 0.001], [64556.4, 0.081], [64556.9, 0.562], [64559.0, 0.014], [64560.3, 0.106], [64560.6, 0.004], [64560.9, 0.343], [64563.0, 2.863], [64563.1, 0.568], [64563.5, 0.021], [64565.1, 0.002], [64569.3, 0.035], [64569.6, 0.01], [64569.9, 0.008], [64570.2, 0.088], [64570.5, 0.185], [64570.9, 0.086], [64571.1, 0.011], [64571.2, 1.683], [64571.3, 2.244], [64571.8, 0.168], [64572.4, 0.092], [64573.4, 0.0], [64573.8, 0.002], [64574.4, 0.005], [64574.8, 0.0], [64576.2, 6.927]], "asks": [[64576.3, 29.93], [64576.8, 0.007], [64578.1, 0.0], [64579.0, 0.074], [64579.7, 0.002], [64580.2, 0.19], [64583.3, 0.31], [64584.5, 0.003], [64589.0, 0.005], [64590.6, 0.013], [64591.1, 0.0], [64592.7, 0.002], [64595.7, 1.003], [64600.5, 10.003], [64611.9, 0.016], [64618.9, 0.026], [64640.9, 0.003], [64651.3, 0.004], [64662.3, 48.112], [64708.3, 0.0], [64709.1, 0.038], [64733.3, 5.981], [64772.0, 10.312], [65222.1, 3.05], [65298.0, 8.21], [65724.4, 1.417], [104929.0, 0.0]]}
{"kind": "depth", "E": 1787088876527, "U": 11315948269511, "u": 11315948276096, "recv_ms": 1787088876472, "bids": [[14176.2, 1.33], [14276.2, 2.87], [58118.5, 0.002], [60782.9, 0.001], [61993.1, 0.0], [63284.7, 0.007], [63543.0, 4.403], [63626.9, 0.549], [63826.4, 1.564], [63930.4, 0.0], [64188.5, 0.001], [64253.3, 1.023], [64460.1, 0.01], [64468.9, 29.604], [64498.7, 0.001], [64530.9, 0.136], [64560.3, 0.098], [64561.5, 0.035], [64562.7, 0.007], [64563.1, 0.019], [64563.2, 0.11], [64563.5, 0.013], [64565.0, 0.002], [64566.3, 0.312], [64570.5, 0.188], [64571.1, 0.008], [64571.3, 0.084], [64571.4, 0.557], [64572.0, 0.307], [64572.9, 0.085], [64573.3, 0.091], [64574.4, 0.089]], "asks": [[64576.8, 0.0], [64578.1, 0.007], [64578.3, 0.021], [64579.5, 0.011], [64580.2, 0.174], [64583.3, 0.001], [64584.6, 0.384], [64588.4, 0.153], [64589.9, 0.025], [64590.6, 0.005], [64591.7, 0.503], [64592.7, 0.002], [64594.4, 0.002], [64595.2, 0.172], [64634.5, 1.476], [64638.3, 6.977], [64655.7, 2.322], [64657.9, 54.441], [64662.3, 0.0], [64664.5, 0.004], [64666.7, 0.002], [64733.3, 5.981], [65222.1, 3.05], [65383.5, 3.618]]}
{"kind": "depth", "E": 1787088876629, "U": 11315948276126, "u": 11315948281378, "recv_ms": 1787088876574, "bids": [[1000.0, 35.76], [14176.2, 1.68], [14276.2, 2.52], [51661.0, 0.0], [58118.5, 0.002], [63576.2, 0.051], [63639.8, 12.71], [63769.0, 5.379], [63930.4, 0.0], [64188.8, 0.003], [64563.1, 0.561], [64563.2, 0.117], [64564.3, 0.002], [64569.5, 0.001], [64571.1, 0.008], [64571.2, 0.127], [64571.4, 0.0], [64572.1, 0.103], [64572.2, 0.319], [64572.3, 0.005], [64572.4, 1.64], [64572.5, 0.079]], "asks": [[64577.8, 0.034], [64578.0, 0.003], [64578.1, 0.048], [64578.3, 0.011], [64579.5, 0.001], [64580.2, 0.097], [64580.4, 2.397], [64580.5, 0.8], [64588.4, 0.153], [64589.9, 0.025], [64691.3, 0.004], [64733.3, 5.981], [65222.1, 3.05], [65280.2, 2.526], [65452.5, 13.701], [65576.3, 0.024], [65706.4, 2.432]]}
{"kind": "depth", "E": 1787088876731, "U": 11315948281661, "u": 11315948286689, "recv_ms": 1787088876678, "bids": [[14176.2, 2.044], [14276.2, 2.156], [58118.5, 0.002], [61347.3, 0.001], [61993.1, 0.003], [63471.3, 2.361], [63805.5, 25.72], [63930.4, 0.0], [63980.2, 6.065], [64469.1, 2.401], [64518.0, 0.254], [64559.4, 0.019], [64560.3, 0.098], [64561.5, 0.042], [64562.7, 0.0], [64563.2, 0.117], [64564.3, 0.002], [64565.0, 0.312], [64566.3, 0.002], [64566.6, 0.244], [64569.5, 0.001], [64569.6, 1.247], [64569.7, 0.608], [64570.2, 0.004], [64570.5, 0.101], [64570.6, 0.007], [64571.1, 0.07], [64571.3, 0.394], [64571.4, 2.16], [64572.0, 0.307], [64572.4, 0.092], [64572.5, 0.009], [64572.6, 0.101], [64572.7, 0.009], [64572.8, 1.558], [64573.7, 0.086], [64574.4, 0.005], [64574.7, 0.084], [64575.1, 0.127]], "asks": [[64576.3, 29.764], [64589.9, 0.025], [64591.7, 0.503], [64591.8, 1.238], [64593.7, 0.002], [64595.7, 0.879], [64600.6, 0.002], [64607.9, 0.0], [64608.0, 0.215], [64608.2, 5.451], [64653.8, 0.005], [64655.7, 2.322], [64657.9, 6.329], [64664.5, 48.116], [64682.7, 2.325], [64684.6, 0.001], [64733.3, 10.434], [65222.1, 3.05], [65595.2, 7.006], [66047.3, 0.03], [68386.3, 1.315], [104929.0, 0.236]]}
{"kind": "depth", "E": 1787088876833, "U": 11315948286808, "u": 11315948292208, "recv_ms": 1787088876780, "bids": [[14176.2, 2.408], [14276.2, 1.792], [58118.5, 0.002], [61347.3, 0.001], [61347.4, 0.008], [61993.1, 0.0], [63576.2, 0.031], [63930.4, 0.0], [64253.3, 1.033], [64460.1, 0.01], [64468.9, 29.604], [64559.4, 0.021], [64561.0, 0.021], [64563.1, 0.568], [64563.2, 0.102], [64569.3, 0.033], [64569.5, 0.003], [64569.7, 0.032], [64570.9, 0.086], [64571.4, 0.0], [64571.5, 0.004], [64571.6, 1.649], [64571.7, 0.07], [64572.1, 2.263], [64572.5, 0.001], [64572.7, 0.001], [64572.8, 0.01], [64572.9, 0.085], [64575.1, 0.275], [64576.0, 0.003]], "asks": [[64576.3, 29.764], [64591.8, 1.24], [64657.9, 54.441], [64664.5, 0.004], [65222.1, 3.05], [65498.3, 26.681], [65576.3, 0.004]]}
{"kind": "depth", "E": 1787088876935, "U": 11315948292284, "u": 11315948297379, "recv_ms": 1787088876880, "bids": [[1000.0, 35.76], [14176.2, 2.744], [14276.2, 1.456], [51661.0, 0.0], [58118.5, 0.002], [61993.1, 0.003], [63930.4, 0.0], [64236.2, 0.002], [64236.3, 0.495], [64460.1, 29.314], [64468.9, 0.022], [64509.0, 1.356], [64511.6, 0.045], [64556.4, 5.081], [64561.0, 0.013], [64563.1, 0.019], [64563.2, 0.102], [64563.5, 0.005], [64569.5, 0.003], [64569.7, 0.032], [64570.2, 1.56], [64570.3, 2.458], [64570.4, 2.168], [64570.5, 0.163], [64570.6, 0.004], [64570.8, 0.006], [64571.0, 1.903], [64571.1, 0.011], [64571.3, 0.084], [64571.6, 0.085], [64572.0, 0.304], [64572.1, 0.103], [64574.7, 0.0], [64574.8, 0.084]], "asks": [[64576.3, 29.848], [64577.6, 0.027], [64579.0, 0.084], [64579.7, 0.012], [64589.9, 0.025], [64591.7, 0.495], [64600.0, 0.871], [65222.1, 3.05], [65448.1, 3.414], [65530.5, 8.694], [65577.2, 3.198], [66029.3, 1.21]]}
{"kind": "depth", "E": 1787088877037, "U": 11315948297392, "u": 11315948302158, "recv_ms": 1787088876983, "bids": [[14176.2, 3.108], [14276.2, 1.092], [58118.5, 0.002], [62074.7, 0.001], [63576.2, 0.051], [63801.3, 5.979], [63930.4, 0.0], [63962.7, 1.247], [64509.0, 1.342], [64561.0, 0.021], [64563.1, 0.104], [64563.2, 0.025], [64564.6, 0.47], [64570.3, 1.919], [64570.4, 0.0], [64571.1, 0.553], [64571.2, 0.127]], "asks": [[64579.0, 0.074], [64579.7, 0.002], [64591.5, 0.009], [64769.9, 0.002], [64899.2, 0.77], [65222.1, 3.05], [65504.7, 0.0], [65576.3, 0.024], [66079.7, 3.933]]}
{"kind": "depth", "E": 1787088877139, "U": 11315948302413, "u": 11315948307238, "recv_ms": 1787088877085, "bids": [[14176.2, 3.472], [14276.2, 0.728], [58118.5, 0.002], [61993.1, 0.0], [63930.4, 0.0], [64253.3, 1.034], [64460.1, 0.01], [64468.9, 29.326], [64498.7, 0.004], [64509.0, 1.37], [64561.0, 0.013], [64563.1, 0.019], [64564.6, 0.465], [64570.4, 0.093], [64571.2, 2.287]], "asks": [[64580.7, 1.456], [64589.3, 0.017], [64686.1, 0.003], [64691.4, 0.086], [65222.1, 3.05], [65388.0, 24.891], [65480.4, 11.101]]}
{"kind": "depth", "E": 1787088877241, "U": 11315948307483, "u": 11315948312814, "recv_ms": 1787088877188, "bids": [[1000.0, 35.76], [14076.2, 0.042], [14176.2, 3.738], [14276.2, 0.42], [51661.0, 0.0], [52000.0, 346.03], [58118.5, 0.002], [61347.3, 0.001], [61993.1, 0.003], [63576.2, 0.031], [63930.4, 0.0], [64253.3, 1.033], [64435.0, 1.54], [64435.1, 3.332], [64460.3, 0.242], [64460.4, 4.145], [64469.1, 0.078], [64469.2, 2.329], [64504.4, 0.0], [64504.6, 6.447], [64508.4, 0.081], [64509.0, 1.356], [64545.5, 1.035], [64550.4, 0.558], [64552.9, 0.693], [64556.4, 0.081], [64558.0, 0.028], [64559.0, 0.006], [64560.3, 0.106], [64561.0, 0.021], [64563.1, 0.104], [64570.2, 1.552], [64570.3, 0.009], [64570.4, 0.0], [64571.1, 2.178], [64571.2, 0.669], [64571.3, 0.092], [64573.3, 0.007], [64573.7, 0.002], [64573.8, 0.086], [64574.8, 0.0], [64576.2, 6.926]], "asks": [[64576.3, 29.845], [64580.7, 1.455], [64589.9, 0.025], [64591.5, 0.009], [64599.1, 2.019], [64606.5, 0.784], [64638.3, 6.968], [64646.6, 0.005], [64646.7, 0.047], [64682.7, 2.325], [64710.7, 2.324], [64710.9, 3.875], [64716.3, 0.0], [64716.4, 8.024], [64899.2, 0.771], [65222.1, 3.05], [65239.9, 3.446], [65498.3, 22.107], [65512.7, 6.708], [65576.3, 0.004], [65661.2, 1.224]]}
{"kind": "depth", "E": 1787088877343, "U": 11315948312875, "u": 11315948318872, "recv_ms": 1787088877289, "bids": [[14076.2, 0.252], [14176.2, 3.682], [14276.2, 0.266], [58118.5, 0.002], [61347.3, 0.001], [61351.6, 2.441], [61993.1, 0.0], [63811.7, 5.481], [63930.4, 0.0], [64542.6, 1.061], [64555.2, 0.034], [64556.4, 0.197], [64558.0, 0.036], [64560.3, 0.098], [64563.1, 0.653], [64569.8, 0.231], [64570.2, 1.636], [64570.5, 0.247], [64571.1, 2.171], [64571.2, 0.127], [64571.3, 0.092], [64572.9, 0.001], [64573.4, 0.0], [64573.8, 0.002]], "asks": [[64576.3, 29.848], [64579.7, 0.012], [64589.9, 0.033], [64591.5, 0.001], [64597.0, 0.001], [64597.9, 0.558], [64598.4, 0.029], [64599.1, 2.135], [64607.8, 0.195], [64608.2, 5.297], [64616.6, 0.0], [65207.5, 6.672], [65222.1, 3.05]]}
{"kind": "depth", "E": 1787088877445, "U": 11315948318989, "u": 11315948323374, "recv_ms": 1787088877392, "bids": [[14076.2, 0.476], [14176.2, 3.584], [14276.2, 0.14], [51661.0, 0.0], [58118.5, 0.002], [61347.3, 0.001], [61993.1, 0.003], [63576.2, 0.051], [63644.3, 9.215], [63769.0, 5.73], [63805.5, 24.939], [63930.4, 0.002], [64033.8, 0.008], [64253.3, 1.023], [64257.6, 5.879], [64511.6, 0.044], [64552.9, 0.074], [64555.5, 0.426], [64556.4, 0.081], [64558.0, 0.028], [64558.1, 0.241], [64560.3, 0.098], [64561.5, 0.035], [64562.7, 0.007], [64563.1, 0.646], [64565.0, 0.312], [64566.3, 0.002], [64570.2, 0.088], [64571.1, 0.011], [64571.2, 0.134], [64571.3, 0.092], [64571.4, 1.548], [64572.1, 0.103], [64572.7, 0.0], [64572.8, 0.094], [64573.5, 0.001], [64574.1, 0.007], [64576.2, 7.536]], "asks": [[64576.3, 29.848], [64577.2, 0.0], [64579.0, 0.074], [64579.7, 0.002], [64579.8, 0.001], [64583.3, 0.31], [64584.6, 0.075], [64589.9, 0.025], [64591.5, 0.009], [64595.7, 0.808], [64596.0, 5.692], [64597.0, 0.558], [64597.9, 0.001], [64598.3, 1.353], [64599.1, 1.4], [64606.5, 0.165], [64607.8, 0.041], [64607.9, 0.154], [64640.9, 0.002], [65222.1, 3.05], [65480.4, 13.389], [65576.3, 0.024], [65678.6, 9.855]]}
